File: data/instron/2021/1104/1mms_0.is_tcyclic_RawData/Specimen_RawData_1.csv
Time,Extension,Load
(s),(mm),(N)
"0.00000","162.43529","-2.19425"
"0.13000","162.52638","-0.93551"
"0.26000","162.65833","0.74178"
"0.39000","162.78870","2.31622"
"0.52000","162.91875","3.88490"
"0.65000","163.04846","5.37126"
"0.78000","163.17853","6.86071"
"0.91000","163.30876","8.31878"
"1.04000","163.43858","9.75971"
"1.17000","163.56844","11.18667"
"1.30000","163.69870","12.59187"
"1.43000","163.82880","14.00797"
"1.56000","163.95844","15.37256"
"1.69000","164.08870","16.75879"
"1.82000","164.21878","18.10148"
"1.95000","164.34840","19.43477"
"2.08000","164.47858","20.75323"
"2.21000","164.60876","22.06371"
"2.34000","164.73849","23.36810"
"2.47000","164.86847","24.63899"
"2.60000","164.99876","25.93136"
"2.73000","165.12863","27.18596"
"2.86000","165.25841","28.44385"
"2.99000","165.38870","29.69422"
"3.12000","165.51878","30.93177"
"3.25000","165.64838","32.16002"
"3.38000","165.77870","33.35804"
"3.51000","165.90877","34.56020"
"3.64000","166.03844","35.73171"
"3.77000","166.16856","36.91683"
"3.90000","166.29874","38.06761"
"4.03000","166.42854","39.22992"
"4.16000","166.55844","40.36536"
"4.29000","166.68877","41.49269"
"4.42000","166.81870","42.62442"
"4.55000","166.94846","43.73216"
"4.68000","167.07869","44.85785"
"4.81000","167.20876","45.95694"
"4.94000","167.33838","47.07027"
"5.07000","167.46866","48.16298"
"5.20000","167.59879","49.26820"
"5.33000","167.72845","50.36320"
"5.46000","167.85861","51.45047"
"5.59000","167.98875","52.54932"
"5.72000","168.11847","53.62350"
"5.85000","168.24846","54.71961"
"5.98000","168.37878","55.78878"
"6.11000","168.50871","56.86191"
"6.24000","168.63834","57.92297"
"6.37000","168.76866","58.99183"
"6.50000","168.89873","60.06619"
"6.63000","169.02843","61.11519"
"6.76000","169.15868","62.18599"
"6.89000","169.28867","63.22574"
"7.02000","169.41841","64.28233"
"7.15000","169.54854","65.29717"
"7.28000","169.67876","66.33811"
"7.41000","169.80855","67.35248"
"7.54000","169.93846","68.38490"
"7.67000","170.06880","69.41019"
"7.80000","170.19859","70.41513"
"7.93000","170.32843","71.43004"
"8.06000","170.45877","72.42461"
"8.19000","170.58878","73.44139"
"8.32000","170.71835","74.42830"
"8.45000","170.84865","75.42907"
"8.58000","170.97874","76.41376"
"8.71000","171.10841","77.39720"
"8.84000","171.23856","78.37708"
"8.97000","171.36870","79.35159"
"9.10000","171.49869","80.34486"
"9.23000","171.62839","81.30907"
"9.36000","171.75870","82.28553"
"9.49000","171.88873","83.25465"
"9.62000","172.01837","84.21070"
"9.75000","172.14868","85.17873"
"9.88000","172.27879","86.13808"
"10.01000","172.40842","87.10398"
"10.14000","172.53860","88.05068"
"10.27000","172.66875","89.00612"
"10.40000","172.79846","89.94887"
"10.53000","172.92848","90.89630"
"10.66000","173.05873","91.84383"
"10.79000","173.18866","92.79489"
"10.92000","173.31845","93.73211"
"11.05000","173.44865","94.66200"
"11.18000","173.57878","95.59801"
"11.31000","173.70842","96.51324"
"11.44000","173.83861","97.44640"
"11.57000","173.96880","98.36845"
"11.70000","174.09842","99.29758"
"11.83000","174.22862","100.22647"
"11.96000","174.35878","101.14660"
"12.09000","174.48851","102.06545"
"12.22000","174.61853","102.97703"
"12.35000","174.74869","103.89857"
"12.48000","174.87860","104.81330"
"12.61000","175.00845","105.72606"
"12.74000","175.13870","106.63981"
"12.87000","175.26869","107.55099"
"13.00000","175.39841","108.45769"
"13.13000","175.52872","109.36592"
"13.26000","175.65875","110.27675"
"13.39000","175.78835","111.16888"
"13.52000","175.91859","112.09046"
"13.65000","176.04877","112.98569"
"13.78000","176.17853","113.88157"
"13.91000","176.30844","114.77885"
"14.04000","176.43869","115.67934"
"14.17000","176.56866","116.58449"
"14.30000","176.69843","117.47677"
"14.43000","176.82874","118.37797"
"14.56000","176.95869","119.27203"
"14.69000","177.08830","120.16760"
"14.82000","177.21866","121.05533"
"14.95000","177.34877","121.95113"
"15.08000","177.47842","122.84254"
"15.21000","177.60863","123.73303"
"15.34000","177.73878","124.62815"
"15.47000","177.86845","125.50704"
"15.60000","177.99846","126.40057"
"15.73000","178.12878","127.28265"
"15.86000","178.25868","128.17035"
"15.99000","178.38840","129.04752"
"16.12000","178.51872","129.93571"
"16.25000","178.64879","130.82202"
"16.38000","178.77844","131.69604"
"16.51000","178.90866","132.57210"
"16.64000","179.03871","133.44923"
"16.77000","179.16847","134.32890"
"16.90000","179.29855","135.20502"
"17.03000","179.42871","136.08183"
"17.16000","179.55858","136.94759"
"17.29000","179.68848","137.81880"
"17.42000","179.81876","138.69110"
"17.55000","179.94870","139.55997"
"17.65400","180.02368","139.93690"
"17.78400","179.89400","138.66119"
"17.91400","179.76357","137.45964"
"18.04400","179.63365","136.29507"
"18.17400","179.50328","135.17267"
"18.30400","179.37344","134.05563"
"18.43400","179.24362","132.96838"
"18.56400","179.11336","131.88155"
"18.69400","178.98337","130.80730"
"18.82400","178.85367","129.73839"
"18.95400","178.72350","128.67276"
"19.08400","178.59328","127.61799"
"19.21400","178.46344","126.56856"
"19.34400","178.33360","125.53278"
"19.47400","178.20316","124.48708"
"19.60400","178.07343","123.45483"
"19.73400","177.94371","122.42717"
"19.86400","177.81348","121.39620"
"19.99400","177.68352","120.36829"
"20.12400","177.55356","119.34464"
"20.25400","177.42340","118.33105"
"20.38400","177.29332","117.30705"
"20.51400","177.16347","116.29472"
"20.64400","177.03351","115.27190"
"20.77400","176.90332","114.25529"
"20.90400","176.77345","113.24965"
"21.03400","176.64357","112.24391"
"21.16400","176.51321","111.23367"
"21.29400","176.38348","110.23075"
"21.42400","176.25372","109.22254"
"21.55400","176.12337","108.20751"
"21.68400","175.99333","107.20576"
"21.81400","175.86363","106.20780"
"21.94400","175.73343","105.19861"
"22.07400","175.60330","104.19345"
"22.20400","175.47351","103.18149"
"22.33400","175.34348","102.17531"
"22.46400","175.21326","101.16543"
"22.59400","175.08344","100.16194"
"22.72400","174.95361","99.16344"
"22.85400","174.82324","98.15964"
"22.98400","174.69351","97.16016"
"23.11400","174.56371","96.15503"
"23.24400","174.43330","95.15145"
"23.37400","174.30339","94.14473"
"23.50400","174.17363","93.14970"
"23.63400","174.04338","92.14121"
"23.76400","173.91322","91.14514"
"23.89400","173.78352","90.14682"
"24.02400","173.65361","89.14157"
"24.15400","173.52327","88.13824"
"24.28400","173.39351","87.13831"
"24.41400","173.26353","86.12628"
"24.54400","173.13324","85.12891"
"24.67400","173.00342","84.12792"
"24.80400","172.87367","83.12621"
"24.93400","172.74338","82.12975"
"25.06400","172.61337","81.12287"
"25.19400","172.48367","80.11885"
"25.32400","172.35353","79.11332"
"25.45400","172.22325","78.11127"
"25.58400","172.09351","77.10622"
"25.71400","171.96352","76.09891"
"25.84400","171.83319","75.10234"
"25.97400","171.70351","74.09862"
"26.10400","171.57364","73.10820"
"26.23400","171.44318","72.10311"
"26.36400","171.31343","71.11114"
"26.49400","171.18372","70.11085"
"26.62400","171.05344","69.09663"
"26.75400","170.92340","68.08684"
"26.88400","170.79356","67.07780"
"27.01400","170.66345","66.06703"
"27.14400","170.53325","65.04893"
"27.27400","170.40344","64.03550"
"27.40400","170.27359","63.01990"
"27.53400","170.14323","61.99624"
"27.66400","170.01343","60.98463"
"27.79400","169.88362","59.97206"
"27.92400","169.75330","58.94814"
"28.05400","169.62344","57.92664"
"28.18400","169.49359","56.89284"
"28.31400","169.36339","55.86658"
"28.44400","169.23343","54.83558"
"28.57400","169.10364","53.80962"
"28.70400","168.97346","52.77419"
"28.83400","168.84325","51.72831"
"28.96400","168.71355","50.69044"
"29.09400","168.58362","49.64675"
"29.22400","168.45325","48.59101"
"29.35400","168.32339","47.54751"
"29.48400","168.19370","46.49864"
"29.61400","168.06334","45.43907"
"29.74400","167.93346","44.37712"
"29.87400","167.80360","43.31755"
"30.00400","167.67337","42.24651"
"30.13400","167.54337","41.18128"
"30.26400","167.41356","40.10926"
"30.39400","167.28346","39.03902"
"30.52400","167.15320","37.96371"
"30.65400","167.02357","36.88741"
"30.78400","166.89368","35.79917"
"30.91400","166.76320","34.70199"
"31.04400","166.63341","33.60913"
"31.17400","166.50362","32.51412"
"31.30400","166.37328","31.41349"
"31.43400","166.24341","30.30699"
"31.56400","166.11363","29.19816"
"31.69400","165.98344","28.08203"
"31.82400","165.85338","26.95700"
"31.95400","165.72368","25.82417"
"32.08400","165.59348","24.68346"
"32.21400","165.46315","23.54452"
"32.34400","165.33340","22.40306"
"32.47400","165.20361","21.26579"
"32.60400","165.07329","20.11732"
"32.73400","164.94344","18.96202"
"32.86400","164.81374","17.78698"
"32.99400","164.68333","16.59858"
"33.12400","164.55344","15.40450"
"33.25400","164.42369","14.18236"
"33.38400","164.29340","12.93829"
"33.51400","164.16327","11.69491"
"33.64400","164.03358","10.44537"
"33.77400","163.90353","9.19075"
"33.90400","163.77321","7.91570"
"34.03400","163.64340","6.63907"
"34.16400","163.51363","5.34081"
"34.29400","163.38327","4.02761"
"34.42400","163.25342","2.71530"
"34.55400","163.12367","1.38857"
"34.68400","162.99339","0.05165"
"34.81400","162.86340","-1.31073"
"34.94400","162.73358","-2.68762"
"35.07400","162.60349","-4.08828"
"35.18000","162.52611","-4.76745"
"35.31000","162.65504","-2.91001"
"35.44000","162.78624","-1.17517"
"35.57000","162.91634","0.47182"
"35.70000","163.04602","2.06546"
"35.83000","163.17615","3.62771"
"35.96000","163.30634","5.15531"
"36.09000","163.43616","6.65833"
"36.22000","163.56599","8.13638"
"36.35000","163.69630","9.60329"
"36.48000","163.82637","11.04989"
"36.61000","163.95602","12.47205"
"36.74000","164.08632","13.88659"
"36.87000","164.21637","15.28325"
"37.00000","164.34596","16.65310"
"37.13000","164.47617","18.01377"
"37.26000","164.60637","19.35967"
"37.39000","164.73605","20.69123"
"37.52000","164.86613","22.01068"
"37.65000","164.99635","23.32307"
"37.78000","165.12616","24.61642"
"37.91000","165.25600","25.89944"
"38.04000","165.38632","27.18499"
"38.17000","165.51636","28.45021"
"38.30000","165.64598","29.70198"
"38.43000","165.77629","30.94142"
"38.56000","165.90636","32.17088"
"38.69000","166.03604","33.38406"
"38.82000","166.16620","34.58507"
"38.95000","166.29633","35.78877"
"39.08000","166.42610","36.96812"
"39.21000","166.55605","38.13692"
"39.34000","166.68636","39.30420"
"39.47000","166.81627","40.44596"
"39.60000","166.94604","41.58945"
"39.73000","167.07629","42.73165"
"39.86000","167.20630","43.86332"
"39.99000","167.33600","44.98088"
"40.12000","167.46625","46.09901"
"40.25000","167.59639","47.20359"
"40.38000","167.72603","48.30335"
"40.51000","167.85620","49.40630"
"40.64000","167.98633","50.51195"
"40.77000","168.11604","51.60659"
"40.90000","168.24608","52.71073"
"41.03000","168.37637","53.80016"
"41.16000","168.50629","54.88055"
"41.29000","168.63593","55.96045"
"41.42000","168.76630","57.04344"
"41.55000","168.89633","58.12712"
"41.68000","169.02602","59.20551"
"41.81000","169.15628","60.27081"
"41.94000","169.28627","61.33829"
"42.07000","169.41600","62.40010"
"42.20000","169.54614","63.44848"
"42.33000","169.67635","64.49335"
"42.46000","169.80609","65.53179"
"42.59000","169.93607","66.57330"
"42.72000","170.06638","67.61085"
"42.85000","170.19612","68.64212"
"42.98000","170.32605","69.66394"
"43.11000","170.45634","70.69128"
"43.24000","170.58632","71.70694"
"43.37000","170.71597","72.71765"
"43.50000","170.84627","73.72827"
"43.63000","170.97632","74.73568"
"43.76000","171.10600","75.72871"
"43.89000","171.23619","76.72050"
"44.02000","171.36630","77.71758"
"44.15000","171.49623","78.71274"
"44.28000","171.62602","79.70016"
"44.41000","171.75632","80.68549"
"44.54000","171.88631","81.66878"
"44.67000","172.01596","82.64619"
"44.80000","172.14627","83.62506"
"44.93000","172.27637","84.60529"
"45.06000","172.40598","85.57939"
"45.19000","172.53622","86.55653"
"45.32000","172.66635","87.52137"
"45.45000","172.79602","88.48108"
"45.58000","172.92610","89.44430"
"45.71000","173.05630","90.40411"
"45.84000","173.18619","91.36611"
"45.97000","173.31610","92.31855"
"46.10000","173.44627","93.27282"
"46.23000","173.57632","94.22118"
"46.36000","173.70601","95.15263"
"46.49000","173.83626","96.09899"
"46.62000","173.96634","97.03936"
"46.75000","174.09602","97.97532"
"46.88000","174.22621","98.91112"
"47.01000","174.35634","99.84795"
"47.14000","174.48608","100.77524"
"47.27000","174.61613","101.70579"
"47.40000","174.74631","102.63658"
"47.53000","174.87617","103.56673"
"47.66000","175.00604","104.48755"
"47.79000","175.13631","105.41492"
"47.92000","175.26628","106.34060"
"48.05000","175.39598","107.26216"
"48.18000","175.52632","108.18355"
"48.31000","175.65633","109.10130"
"48.44000","175.78590","110.01083"
"48.57000","175.91620","110.93004"
"48.70000","176.04637","111.84297"
"48.83000","176.17609","112.74757"
"48.96000","176.30602","113.65951"
"49.09000","176.43626","114.56782"
"49.22000","176.56621","115.47839"
"49.35000","176.69604","116.39322"
"49.48000","176.82632","117.29984"
"49.61000","176.95627","118.21437"
"49.74000","177.08589","119.11407"
"49.87000","177.21626","120.01450"
"50.00000","177.34636","120.91901"
"50.13000","177.47597","121.82138"
"50.26000","177.60623","122.72646"
"50.39000","177.73637","123.62491"
"50.52000","177.86603","124.51804"
"50.65000","177.99605","125.41460"
"50.78000","178.12637","126.31443"
"50.91000","178.25624","127.20940"
"51.04000","178.38599","128.10152"
"51.17000","178.51631","128.99339"
"51.30000","178.64641","129.88596"
"51.43000","178.77602","130.77072"
"51.56000","178.90627","131.66031"
"51.69000","179.03632","132.54454"
"51.82000","179.16605","133.43950"
"51.95000","179.29614","134.32106"
"52.08000","179.42628","135.20670"
"52.21000","179.55615","136.09317"
"52.34000","179.68608","136.97205"
"52.47000","179.81631","137.84924"
"52.60000","179.94627","138.72984"
"52.70600","180.02328","139.12814"
"52.83600","179.89360","137.86259"
"52.96600","179.76318","136.65979"
"53.09600","179.63326","135.51143"
"53.22600","179.50285","134.38474"
"53.35600","179.37306","133.27396"
"53.48600","179.24324","132.19138"
"53.61600","179.11296","131.10741"
"53.74600","178.98296","130.03793"
"53.87600","178.85329","128.97386"
"54.00600","178.72310","127.91585"
"54.13600","178.59288","126.86704"
"54.26600","178.46304","125.82339"
"54.39600","178.33321","124.78310"
"54.52600","178.20276","123.74378"
"54.65600","178.07301","122.71281"
"54.78600","177.94330","121.69162"
"54.91600","177.81308","120.66187"
"55.04600","177.68309","119.63770"
"55.17600","177.55319","118.62543"
"55.30600","177.42303","117.60607"
"55.43600","177.29289","116.58159"
"55.56600","177.16306","115.56837"
"55.69600","177.03311","114.55574"
"55.82600","176.90286","113.54400"
"55.95600","176.77309","112.53876"
"56.08600","176.64316","111.53519"
"56.21600","176.51280","110.53703"
"56.34600","176.38307","109.52768"
"56.47600","176.25333","108.52145"
"56.60600","176.12297","107.51262"
"56.73600","175.99295","106.51540"
"56.86600","175.86324","105.51765"
"56.99600","175.73302","104.51752"
"57.12600","175.60294","103.50838"
"57.25600","175.47311","102.49903"
"57.38600","175.34305","101.49591"
"57.51600","175.21286","100.48603"
"57.64600","175.08302","99.48598"
"57.77600","174.95314","98.48863"
"57.90600","174.82283","97.49003"
"58.03600","174.69313","96.48811"
"58.16600","174.56328","95.48700"
"58.29600","174.43291","94.48485"
"58.42600","174.30299","93.48183"
"58.55600","174.17323","92.48336"
"58.68600","174.04297","91.48480"
"58.81600","173.91286","90.47916"
"58.94600","173.78311","89.48934"
"59.07600","173.65312","88.48547"
"59.20600","173.52290","87.48030"
"59.33600","173.39314","86.48213"
"59.46600","173.26312","85.48026"
"59.59600","173.13284","84.47974"
"59.72600","173.00305","83.48590"
"59.85600","172.87326","82.48777"
"59.98600","172.74300","81.48067"
"60.11600","172.61298","80.47804"
"60.24600","172.48326","79.48065"
"60.37600","172.35309","78.47686"
"60.50600","172.22285","77.47044"
"60.63600","172.09311","76.47317"
"60.76600","171.96320","75.48024"
"60.89600","171.83275","74.47674"
"61.02600","171.70309","73.47112"
"61.15600","171.57324","72.48100"
"61.28600","171.44279","71.48154"
"61.41600","171.31302","70.48575"
"61.54600","171.18332","69.49166"
"61.67600","171.05305","68.47882"
"61.80600","170.92299","67.46932"
"61.93600","170.79317","66.46243"
"62.06600","170.66301","65.45243"
"62.19600","170.53287","64.44157"
"62.32600","170.40305","63.42657"
"62.45600","170.27315","62.41517"
"62.58600","170.14288","61.39757"
"62.71600","170.01302","60.38303"
"62.84600","169.88324","59.36991"
"62.97600","169.75290","58.35069"
"63.10600","169.62306","57.32819"
"63.23600","169.49318","56.30001"
"63.36600","169.36301","55.27721"
"63.49600","169.23303","54.24602"
"63.62600","169.10327","53.22127"
"63.75600","168.97305","52.18454"
"63.88600","168.84280","51.15006"
"64.01600","168.71312","50.10896"
"64.14600","168.58322","49.06594"
"64.27600","168.45287","48.01398"
"64.40600","168.32301","46.97286"
"64.53600","168.19328","45.92706"
"64.66600","168.06296","44.86891"
"64.79600","167.93306","43.81123"
"64.92600","167.80321","42.75394"
"65.05600","167.67297","41.67967"
"65.18600","167.54295","40.61573"
"65.31600","167.41316","39.54507"
"65.44600","167.28307","38.47639"
"65.57600","167.15279","37.40617"
"65.70600","167.02315","36.32938"
"65.83600","166.89328","35.24416"
"65.96600","166.76280","34.14922"
"66.09600","166.63300","33.05312"
"66.22600","166.50322","31.96026"
"66.35600","166.37285","30.86103"
"66.48600","166.24301","29.75408"
"66.61600","166.11324","28.64560"
"66.74600","165.98303","27.52941"
"66.87600","165.85300","26.40371"
"67.00600","165.72318","25.27662"
"67.13600","165.59308","24.14139"
"67.26600","165.46280","23.00429"
"67.39600","165.33302","21.87222"
"67.52600","165.20334","20.73988"
"67.65600","165.07286","19.58887"
"67.78600","164.94302","18.42876"
"67.91600","164.81332","17.25635"
"68.04600","164.68292","16.07153"
"68.17600","164.55301","14.86883"
"68.30600","164.42328","13.64663"
"68.43600","164.29300","12.40486"
"68.56600","164.16287","11.16084"
"68.69600","164.03319","9.91484"
"68.82600","163.90315","8.66924"
"68.95600","163.77281","7.39644"
"69.08600","163.64301","6.11907"
"69.21600","163.51324","4.82179"
"69.34600","163.38289","3.51943"
"69.47600","163.25301","2.20143"
"69.60600","163.12326","0.88623"
"69.73600","162.99300","-0.45367"
"69.86600","162.86299","-1.81043"
"69.99600","162.73320","-3.18040"
"70.12600","162.60309","-4.57247"
"70.23200","162.52568","-5.25734"
"70.36200","162.65466","-3.40676"
"70.49200","162.78583","-1.66794"
"70.62200","162.91595","-0.02402"
"70.75200","163.04562","1.57472"
"70.88200","163.17577","3.13118"
"71.01200","163.30592","4.66945"
"71.14200","163.43578","6.16249"
"71.27200","163.56564","7.63876"
"71.40200","163.69592","9.10757"
"71.53200","163.82599","10.55515"
"71.66200","163.95564","11.98971"
"71.79200","164.08594","13.39219"
"71.92200","164.21596","14.79152"
"72.05200","164.34558","16.15575"
"72.18200","164.47578","17.51939"
"72.31200","164.60594","18.86843"
"72.44200","164.73564","20.19370"
"72.57200","164.86581","21.51707"
"72.70200","164.99599","22.82373"
"72.83200","165.12576","24.12408"
"72.96200","165.25563","25.40610"
"73.09200","165.38588","26.69386"
"73.22200","165.51604","27.96117"
"73.35200","165.64555","29.20177"
"73.48200","165.77589","30.45594"
"73.61200","165.90598","31.68140"
"73.74200","166.03563","32.89840"
"73.87200","166.16580","34.10102"
"74.00200","166.29594","35.29919"
"74.13200","166.42572","36.48124"
"74.26200","166.55565","37.65797"
"74.39200","166.68596","38.82114"
"74.52200","166.81584","39.97400"
"74.65200","166.94566","41.11179"
"74.78200","167.07590","42.25652"
"74.91200","167.20593","43.39141"
"75.04200","167.33560","44.50458"
"75.17200","167.46587","45.62363"
"75.30200","167.59601","46.72823"
"75.43200","167.72562","47.83529"
"75.56200","167.85582","48.93791"
"75.69200","167.98596","50.03696"
"75.82200","168.11566","51.13250"
"75.95200","168.24567","52.23029"
"76.08200","168.37598","53.32951"
"76.21200","168.50591","54.40845"
"76.34200","168.63554","55.48853"
"76.47200","168.76585","56.56672"
"76.60200","168.89592","57.64884"
"76.73200","169.02563","58.73312"
"76.86200","169.15590","59.80161"
"76.99200","169.28587","60.86506"
"77.12200","169.41560","61.92529"
"77.25200","169.54578","62.97753"
"77.38200","169.67595","64.02366"
"77.51200","169.80569","65.06683"
"77.64200","169.93568","66.10759"
"77.77200","170.06598","67.14503"
"77.90200","170.19579","68.17928"
"78.03200","170.32564","69.19947"
"78.16200","170.45598","70.22732"
"78.29200","170.58595","71.24416"
"78.42200","170.71559","72.25353"
"78.55200","170.84590","73.26605"
"78.68200","170.97595","74.27431"
"78.81200","171.10559","75.27264"
"78.94200","171.23576","76.26438"
"79.07200","171.36592","77.26196"
"79.20200","171.49582","78.26166"
"79.33200","171.62560","79.25240"
"79.46200","171.75591","80.23719"
"79.59200","171.88582","81.22044"
"79.72200","172.01564","82.19786"
"79.85200","172.14589","83.18440"
"79.98200","172.27599","84.16539"
"80.11200","172.40559","85.14130"
"80.24200","172.53584","86.11425"
"80.37200","172.66595","87.08746"
"80.50200","172.79564","88.04379"
"80.63200","172.92570","89.00867"
"80.76200","173.05594","89.97864"
"80.89200","173.18584","90.93026"
"81.02200","173.31558","91.88958"
"81.15200","173.44589","92.83355"
"81.28200","173.57594","93.79747"
"81.41200","173.70555","94.72449"
"81.54200","173.83592","95.67448"
"81.67200","173.96593","96.60944"
"81.80200","174.09564","97.55201"
"81.93200","174.22581","98.49385"
"82.06200","174.35600","99.42088"
"82.19200","174.48569","100.35941"
"82.32200","174.61574","101.28342"
"82.45200","174.74590","102.22593"
"82.58200","174.87578","103.15108"
"82.71200","175.00565","104.08049"
"82.84200","175.13591","105.00940"
"82.97200","175.26591","105.93124"
"83.10200","175.39561","106.85156"
"83.23200","175.52592","107.77570"
"83.36200","175.65594","108.70065"
"83.49200","175.78552","109.60756"
"83.62200","175.91580","110.53957"
"83.75200","176.04601","111.44881"
"83.88200","176.17572","112.35388"
"84.01200","176.30562","113.26326"
"84.14200","176.43588","114.17660"
"84.27200","176.56586","115.09341"
"84.40200","176.69563","115.99960"
"84.53200","176.82594","116.91903"
"84.66200","176.95586","117.82185"
"84.79200","177.08553","118.73647"
"84.92200","177.21588","119.63516"
"85.05200","177.34598","120.53933"
"85.18200","177.47559","121.44600"
"85.31200","177.60582","122.34732"
"85.44200","177.73596","123.26576"
"85.57200","177.86565","124.13657"
"85.70200","177.99568","125.06227"
"85.83200","178.12599","125.93513"
"85.96200","178.25584","126.84739"
"86.09200","178.38560","127.73687"
"86.22200","178.51596","128.63429"
"86.35200","178.64600","129.54073"
"86.48200","178.77563","130.41180"
"86.61200","178.90585","131.32047"
"86.74200","179.03593","132.19293"
"86.87200","179.16566","133.10490"
"87.00200","179.29576","133.97624"
"87.13200","179.42589","134.87061"
"87.26200","179.55576","135.75482"
"87.39200","179.68567","136.62975"
"87.52200","179.81596","137.52615"
"87.65200","179.94589","138.39264"
"87.75900","180.02405","138.81606"
"87.88900","179.89426","137.54108"
"88.01900","179.76381","136.35280"
"88.14900","179.63388","135.18643"
"88.27900","179.50351","134.07616"
"88.40900","179.37369","132.95259"
"88.53900","179.24388","131.87915"
"88.66900","179.11359","130.79852"
"88.79900","178.98363","129.71751"
"88.92900","178.85393","128.66765"
"89.05900","178.72375","127.60097"
"89.18900","178.59348","126.56132"
"89.31900","178.46368","125.50378"
"89.44900","178.33383","124.47302"
"89.57900","178.20337","123.42967"
"89.70900","178.07365","122.40203"
"89.83900","177.94394","121.38066"
"89.96900","177.81372","120.34698"
"90.09900","177.68370","119.33884"
"90.22900","177.55380","118.30633"
"90.35900","177.42366","117.30140"
"90.48900","177.29352","116.27519"
"90.61900","177.16370","115.27217"
"90.74900","177.03375","114.25491"
"90.87900","176.90350","113.23602"
"91.00900","176.77373","112.23837"
"91.13900","176.64383","111.22780"
"91.26900","176.51344","110.23388"
"91.39900","176.38370","109.22501"
"91.52900","176.25397","108.22118"
"91.65900","176.12360","107.21188"
"91.78900","175.99358","106.21326"
"91.91900","175.86385","105.22051"
"92.04900","175.73367","104.21265"
"92.17900","175.60355","103.20991"
"92.30900","175.47377","102.20488"
"92.43900","175.34370","101.19336"
"92.56900","175.21344","100.18980"
"92.69900","175.08366","99.18708"
"92.82900","174.95381","98.19450"
"92.95900","174.82347","97.19182"
"93.08900","174.69377","96.19309"
"93.21900","174.56392","95.19080"
"93.34900","174.43352","94.18597"
"93.47900","174.30365","93.18750"
"93.60900","174.17387","92.18619"
"93.73900","174.04359","91.18873"
"93.86900","173.91348","90.18943"
"93.99900","173.78377","89.19512"
"94.12900","173.65376","88.19270"
"94.25900","173.52351","87.18993"
"94.38900","173.39375","86.18948"
"94.51900","173.26378","85.18888"
"94.64900","173.13347","84.19308"
"94.77900","173.00368","83.18798"
"94.90900","172.87390","82.19576"
"95.03900","172.74362","81.18676"
"95.16900","172.61360","80.19166"
"95.29900","172.48392","79.19161"
"95.42900","172.35368","78.18832"
"95.55900","172.22348","77.18523"
"95.68900","172.09375","76.18322"
"95.81900","171.96373","75.19034"
"95.94900","171.83342","74.18839"
"96.07900","171.70374","73.19058"
"96.20900","171.57388","72.19822"
"96.33900","171.44342","71.19608"
"96.46900","171.31366","70.20122"
"96.59900","171.18396","69.19767"
"96.72900","171.05367","68.18840"
"96.85900","170.92363","67.17889"
"96.98900","170.79379","66.17358"
"97.11900","170.66370","65.16741"
"97.24900","170.53349","64.14956"
"97.37900","170.40370","63.14262"
"97.50900","170.27380","62.12395"
"97.63900","170.14345","61.10516"
"97.76900","170.01364","60.09129"
"97.89900","169.88387","59.08292"
"98.02900","169.75352","58.06173"
"98.15900","169.62367","57.03731"
"98.28900","169.49382","56.01393"
"98.41900","169.36363","54.98738"
"98.54900","169.23367","53.96156"
"98.67900","169.10388","52.93162"
"98.80900","168.97371","51.90588"
"98.93900","168.84346","50.86063"
"99.06900","168.71375","49.82843"
"99.19900","168.58383","48.78071"
"99.32900","168.45349","47.72951"
"99.45900","168.32365","46.69214"
"99.58900","168.19392","45.64467"
"99.71900","168.06361","44.58453"
"99.84900","167.93370","43.52874"
"99.97900","167.80382","42.47305"
"100.10900","167.67360","41.40284"
"100.23900","167.54358","40.33692"
"100.36900","167.41380","39.27023"
"100.49900","167.28371","38.20198"
"100.62900","167.15344","37.13110"
"100.75900","167.02376","36.05530"
"100.88900","166.89392","34.97321"
"101.01900","166.76344","33.87574"
"101.14900","166.63364","32.78450"
"101.27900","166.50386","31.68839"
"101.40900","166.37354","30.58817"
"101.53900","166.24362","29.48372"
"101.66900","166.11386","28.37395"
"101.79900","165.98369","27.26192"
"101.92900","165.85364","26.13542"
"102.05900","165.72385","25.00563"
"102.18900","165.59369","23.87106"
"102.31900","165.46344","22.73769"
"102.44900","165.33365","21.60479"
"102.57900","165.20387","20.47516"
"102.70900","165.07350","19.32263"
"102.83900","164.94373","18.16302"
"102.96900","164.81395","16.99211"
"103.09900","164.68355","15.80643"
"103.22900","164.55367","14.60698"
"103.35900","164.42392","13.38352"
"103.48900","164.29361","12.14669"
"103.61900","164.16351","10.89651"
"103.74900","164.03383","9.64982"
"103.87900","163.90375","8.40076"
"104.00900","163.77350","7.13692"
"104.13900","163.64362","5.85563"
"104.26900","163.51384","4.56109"
"104.39900","163.38353","3.25635"
"104.52900","163.25363","1.94932"
"104.65900","163.12387","0.62873"
"104.78900","162.99361","-0.71215"
"104.91900","162.86365","-2.06238"
"105.04900","162.73380","-3.43415"
"105.17900","162.60371","-4.82730"
"105.28500","162.52635","-5.50607"
"105.41500","162.65533","-3.64783"
"105.54500","162.78648","-1.91799"
"105.67500","162.91660","-0.27424"
"105.80500","163.04628","1.31921"
"105.93500","163.17642","2.87881"
"106.06500","163.30661","4.40823"
"106.19500","163.43643","5.90902"
"106.32500","163.56627","7.38433"
"106.45500","163.69653","8.85465"
"106.58500","163.82666","10.30405"
"106.71500","163.95627","11.72444"
"106.84500","164.08658","13.13555"
"106.97500","164.21663","14.52979"
"107.10500","164.34625","15.89715"
"107.23500","164.47644","17.25891"
"107.36500","164.60663","18.60873"
"107.49500","164.73631","19.93454"
"107.62500","164.86641","21.25467"
"107.75500","164.99664","22.56849"
"107.88500","165.12643","23.85777"
"108.01500","165.25632","25.14670"
"108.14500","165.38652","26.43073"
"108.27500","165.51678","27.70133"
"108.40500","165.64619","28.94744"
"108.53500","165.77658","30.18769"
"108.66500","165.90663","31.42370"
"108.79500","166.03629","32.63707"
"108.92500","166.16643","33.84485"
"109.05500","166.29659","35.04401"
"109.18500","166.42639","36.22678"
"109.31500","166.55630","37.39885"
"109.44500","166.68663","38.56379"
"109.57500","166.81654","39.71299"
"109.70500","166.94629","40.85218"
"109.83500","167.07654","41.99705"
"109.96500","167.20662","43.13488"
"110.09500","167.33626","44.25037"
"110.22500","167.46651","45.36617"
"110.35500","167.59665","46.47911"
"110.48500","167.72629","47.57602"
"110.61500","167.85648","48.67456"
"110.74500","167.98662","49.77050"
"110.87500","168.11633","50.86741"
"111.00500","168.24629","51.96458"
"111.13500","168.37662","53.05873"
"111.26500","168.50658","54.14478"
"111.39500","168.63617","55.21774"
"111.52500","168.76653","56.30881"
"111.65500","168.89661","57.39251"
"111.78500","169.02628","58.46494"
"111.91500","169.15654","59.53966"
"112.04500","169.28651","60.60706"
"112.17500","169.41626","61.66165"
"112.30500","169.54640","62.70769"
"112.43500","169.67661","63.75779"
"112.56500","169.80637","64.79707"
"112.69500","169.93634","65.84397"
"112.82500","170.06664","66.88374"
"112.95500","170.19644","67.91295"
"113.08500","170.32628","68.93778"
"113.21500","170.45662","69.96956"
"113.34500","170.58659","70.98413"
"113.47500","170.71622","71.99930"
"113.60500","170.84656","73.00831"
"113.73500","170.97661","74.02010"
"113.86500","171.10628","75.01894"
"113.99500","171.23642","76.01102"
"114.12500","171.36658","77.01042"
"114.25500","171.49649","78.00505"
"114.38500","171.62625","78.99352"
"114.51500","171.75658","79.98334"
"114.64500","171.88658","80.96334"
"114.77500","172.01624","81.94617"
"114.90500","172.14653","82.93204"
"115.03500","172.27669","83.91238"
"115.16500","172.40625","84.89010"
"115.29500","172.53651","85.86369"
"115.42500","172.66661","86.83215"
"115.55500","172.79631","87.79937"
"115.68500","172.92635","88.76587"
"115.81500","173.05659","89.73383"
"115.94500","173.18648","90.68881"
"116.07500","173.31631","91.64243"
"116.20500","173.44653","92.60004"
"116.33500","173.57657","93.54515"
"116.46500","173.70627","94.48885"
"116.59500","173.83652","95.43353"
"116.72500","173.96658","96.37590"
"116.85500","174.09628","97.31102"
"116.98500","174.22647","98.25301"
"117.11500","174.35664","99.19444"
"117.24500","174.48634","100.12003"
"117.37500","174.61639","101.05098"
"117.50500","174.74655","101.99121"
"117.63500","174.87645","102.92113"
"117.76500","175.00630","103.85179"
"117.89500","175.13658","104.77432"
"118.02500","175.26657","105.70090"
"118.15500","175.39627","106.62529"
"118.28500","175.52660","107.54489"
"118.41500","175.65660","108.46839"
"118.54500","175.78618","109.38246"
"118.67500","175.91646","110.30531"
"118.80500","176.04666","111.21516"
"118.93500","176.17638","112.12373"
"119.06500","176.30629","113.04184"
"119.19500","176.43652","113.95253"
"119.32500","176.56650","114.87309"
"119.45500","176.69630","115.78880"
"119.58500","176.82660","116.69819"
"119.71500","176.95653","117.60693"
"119.84500","177.08620","118.51447"
"119.97500","177.21652","119.41790"
"120.10500","177.34663","120.32691"
"120.23500","177.47627","121.23297"
"120.36500","177.60648","122.14037"
"120.49500","177.73662","123.03985"
"120.62500","177.86630","123.93799"
"120.75500","177.99632","124.83848"
"120.88500","178.12665","125.73716"
"121.01500","178.25652","126.63673"
"121.14500","178.38626","127.53403"
"121.27500","178.51662","128.43491"
"121.40500","178.64667","129.32950"
"121.53500","178.77626","130.21275"
"121.66500","178.90652","131.11060"
"121.79500","179.03661","132.00323"
"121.92500","179.16632","132.89676"
"122.05500","179.29639","133.78386"
"122.18500","179.42654","134.67039"
"122.31500","179.55643","135.55891"
"122.44500","179.68636","136.44952"
"122.57500","179.81660","137.33369"
"122.70500","179.94655","138.20750"
"122.81100","180.02370","138.61484"
"122.94100","179.89391","137.35155"
"123.07100","179.76347","136.14560"
"123.20100","179.63351","134.98830"
"123.33100","179.50317","133.86012"
"123.46100","179.37332","132.74960"
"123.59100","179.24352","131.66533"
"123.72100","179.11327","130.59038"
"123.85100","178.98326","129.52086"
"123.98100","178.85358","128.45303"
"124.11100","178.72339","127.39946"
"124.24100","178.59317","126.35101"
"124.37100","178.46332","125.30930"
"124.50100","178.33351","124.26540"
"124.63100","178.20305","123.23063"
"124.76100","178.07332","122.20320"
"124.89100","177.94360","121.17554"
"125.02100","177.81337","120.15160"
"125.15100","177.68336","119.13245"
"125.28100","177.55347","118.11168"
"125.41100","177.42331","117.09547"
"125.54100","177.29318","116.08186"
"125.67100","177.16335","115.06535"
"125.80100","177.03340","114.05532"
"125.93100","176.90315","113.03889"
"126.06100","176.77339","112.03378"
"126.19100","176.64346","111.03446"
"126.32100","176.51309","110.02561"
"126.45100","176.38338","109.02691"
"126.58100","176.25360","108.02097"
"126.71100","176.12326","107.01061"
"126.84100","175.99324","106.01398"
"126.97100","175.86353","105.01987"
"127.10100","175.73329","104.01796"
"127.23100","175.60324","103.00935"
"127.36100","175.47339","102.00471"
"127.49100","175.34334","100.99542"
"127.62100","175.21318","99.99045"
"127.75100","175.08334","98.99348"
"127.88100","174.95349","97.99198"
"128.01100","174.82310","96.98978"
"128.14100","174.69342","95.99226"
"128.27100","174.56357","94.98958"
"128.40100","174.43318","93.98705"
"128.53100","174.30330","92.98794"
"128.66100","174.17352","91.99448"
"128.79100","174.04326","90.99382"
"128.92100","173.91312","89.99462"
"129.05100","173.78343","88.99875"
"129.18100","173.65343","87.99966"
"129.31100","173.52318","86.99336"
"129.44100","173.39343","85.99608"
"129.57100","173.26343","84.99406"
"129.70100","173.13310","83.99120"
"129.83100","173.00333","82.99852"
"129.96100","172.87357","82.00339"
"130.09100","172.74326","81.00170"
"130.22100","172.61325","79.99529"
"130.35100","172.48357","78.99312"
"130.48100","172.35336","77.99930"
"130.61100","172.22314","76.99092"
"130.74100","172.09340","75.99205"
"130.87100","171.96339","74.99904"
"131.00100","171.83313","73.99540"
"131.13100","171.70340","72.99747"
"131.26100","171.57353","72.00085"
"131.39100","171.44307","71.00696"
"131.52100","171.31331","70.00432"
"131.65100","171.18359","68.99981"
"131.78100","171.05330","67.99484"
"131.91100","170.92328","66.98533"
"132.04100","170.79344","65.97616"
"132.17100","170.66335","64.96595"
"132.30100","170.53325","63.95796"
"132.43100","170.40341","62.94463"
"132.56100","170.27336","61.92704"
"132.69100","170.14319","60.91620"
"132.82100","170.01329","59.90260"
"132.95100","169.88351","58.89058"
"133.08100","169.75319","57.87068"
"133.21100","169.62335","56.85004"
"133.34100","169.49350","55.82847"
"133.47100","169.36328","54.80132"
"133.60100","169.23334","53.76844"
"133.73100","169.10353","52.73864"
"133.86100","168.97334","51.71761"
"133.99100","168.84312","50.67498"
"134.12100","168.71341","49.63578"
"134.25100","168.58350","48.58351"
"134.38100","168.45316","47.53675"
"134.51100","168.32330","46.48956"
"134.64100","168.19356","45.45230"
"134.77100","168.06326","44.39397"
"134.90100","167.93336","43.33975"
"135.03100","167.80348","42.28060"
"135.16100","167.67326","41.21107"
"135.29100","167.54324","40.14902"
"135.42100","167.41345","39.08142"
"135.55100","167.28337","38.01538"
"135.68100","167.15308","36.93314"
"135.81100","167.02342","35.86185"
"135.94100","166.89357","34.78083"
"136.07100","166.76309","33.68928"
"136.20100","166.63329","32.59765"
"136.33100","166.50352","31.50633"
"136.46100","166.37318","30.40272"
"136.59100","166.24332","29.29748"
"136.72100","166.11349","28.18895"
"136.85100","165.98334","27.07515"
"136.98100","165.85327","25.94982"
"137.11100","165.72348","24.81796"
"137.24100","165.59335","23.68559"
"137.37100","165.46307","22.54462"
"137.50100","165.33330","21.42420"
"137.63100","165.20352","20.29192"
"137.76100","165.07318","19.14261"
"137.89100","164.94330","17.98307"
"138.02100","164.81363","16.81039"
"138.15100","164.68323","15.61888"
"138.28100","164.55333","14.41659"
"138.41100","164.42357","13.19150"
"138.54100","164.29329","11.95792"
"138.67100","164.16318","10.71358"
"138.80100","164.03348","9.47064"
"138.93100","163.90341","8.21687"
"139.06100","163.77310","6.94980"
"139.19100","163.64330","5.67047"
"139.32100","163.51352","4.38095"
"139.45100","163.38318","3.07640"
"139.58100","163.25331","1.77326"
"139.71100","163.12357","0.44923"
"139.84100","162.99329","-0.88502"
"139.97100","162.86331","-2.23830"
"140.10100","162.73349","-3.60672"
"140.23100","162.60338","-4.98813"
"140.33700","162.52597","-5.66604"
"140.46700","162.65494","-3.81500"
"140.59700","162.78612","-2.08795"
"140.72700","162.91623","-0.44702"
"140.85700","163.04591","1.13948"
"140.98700","163.17603","2.70426"
"141.11700","163.30621","4.23503"
"141.24700","163.43600","5.73237"
"141.37700","163.56587","7.20936"
"141.50700","163.69620","8.67588"
"141.63700","163.82625","10.12173"
"141.76700","163.95592","11.54182"
"141.89700","164.08623","12.95543"
"142.02700","164.21622","14.34837"
"142.15700","164.34586","15.71283"
"142.28700","164.47607","17.07343"
"142.41700","164.60623","18.42245"
"142.54700","164.73595","19.74647"
"142.67700","164.86600","21.06841"
"142.80700","164.99623","22.38239"
"142.93700","165.12607","23.67673"
"143.06700","165.25589","24.95823"
"143.19700","165.38626","26.24633"
"143.32700","165.51627","27.51617"
"143.45700","165.64581","28.76255"
"143.58700","165.77621","30.00873"
"143.71700","165.90622","31.23438"
"143.84700","166.03592","32.45383"
"143.97700","166.16608","33.65784"
"144.10700","166.29620","34.85199"
"144.23700","166.42601","36.03807"
"144.36700","166.55591","37.21094"
"144.49700","166.68625","38.38350"
"144.62700","166.81615","39.53141"
"144.75700","166.94594","40.67400"
"144.88700","167.07616","41.80881"
"145.01700","167.20619","42.94693"
"145.14700","167.33585","44.06364"
"145.27700","167.46614","45.17787"
"145.40700","167.59627","46.28506"
"145.53700","167.72589","47.38817"
"145.66700","167.85609","48.48841"
"145.79700","167.98624","49.59155"
"145.92700","168.11594","50.68830"
"146.05700","168.24593","51.77579"
"146.18700","168.37627","52.87087"
"146.31700","168.50616","53.95307"
"146.44700","168.63583","55.03326"
"146.57700","168.76613","56.11764"
"146.70700","168.89619","57.20522"
"146.83700","169.02586","58.27930"
"146.96700","169.15616","59.35140"
"147.09700","169.28615","60.41682"
"147.22700","169.41588","61.47651"
"147.35700","169.54604","62.52602"
"147.48700","169.67621","63.57385"
"147.61700","169.80597","64.62128"
"147.74700","169.93593","65.66363"
"147.87700","170.06625","66.69939"
"148.00700","170.19606","67.73022"
"148.13700","170.32590","68.75348"
"148.26700","170.45624","69.78577"
"148.39700","170.58620","70.80349"
"148.52700","170.71584","71.81462"
"148.65700","170.84616","72.83164"
"148.78700","170.97624","73.83925"
"148.91700","171.10588","74.83339"
"149.04700","171.23604","75.83078"
"149.17700","171.36620","76.82455"
"149.30700","171.49611","77.82576"
"149.43700","171.62589","78.81506"
"149.56700","171.75621","79.80178"
"149.69700","171.88617","80.78337"
"149.82700","172.01582","81.76893"
"149.95700","172.14619","82.75368"
"150.08700","172.27626","83.73091"
"150.21700","172.40587","84.70937"
"150.34700","172.53610","85.68429"
"150.47700","172.66623","86.65201"
"150.60700","172.79591","87.61481"
"150.73700","172.92598","88.58781"
"150.86700","173.05620","89.55254"
"150.99700","173.18610","90.51190"
"151.12700","173.31595","91.46517"
"151.25700","173.44615","92.42010"
"151.38700","173.57617","93.36445"
"151.51700","173.70586","94.30563"
"151.64700","173.83612","95.24750"
"151.77700","173.96623","96.19605"
"151.90700","174.09590","97.13106"
"152.03700","174.22606","98.07035"
"152.16700","174.35625","99.00846"
"152.29700","174.48596","99.94186"
"152.42700","174.61600","100.87251"
"152.55700","174.74617","101.80669"
"152.68700","174.87605","102.74025"
"152.81700","175.00592","103.66840"
"152.94700","175.13618","104.59477"
"153.07700","175.26617","105.52386"
"153.20700","175.39587","106.44550"
"153.33700","175.52618","107.36867"
"153.46700","175.65623","108.29002"
"153.59700","175.78583","109.20315"
"153.72700","175.91608","110.12385"
"153.85700","176.04625","111.03429"
"153.98700","176.17596","111.94247"
"154.11700","176.30589","112.85924"
"154.24700","176.43614","113.77097"
"154.37700","176.56613","114.68362"
"154.50700","176.69589","115.59885"
"154.63700","176.82620","116.51520"
"154.76700","176.95612","117.43052"
"154.89700","177.08580","118.33292"
"155.02700","177.21614","119.24011"
"155.15700","177.34622","120.14898"
"155.28700","177.47586","121.05800"
"155.41700","177.60611","121.95825"
"155.54700","177.73622","122.86545"
"155.67700","177.86591","123.76355"
"155.80700","177.99597","124.66215"
"155.93700","178.12624","125.56471"
"156.06700","178.25615","126.46535"
"156.19700","178.38588","127.36337"
"156.32700","178.51622","128.26353"
"156.45700","178.64626","129.15851"
"156.58700","178.77588","130.04950"
"156.71700","178.90613","130.93944"
"156.84700","179.03619","131.83554"
"156.97700","179.16594","132.72887"
"157.10700","179.29601","133.62035"
"157.23700","179.42618","134.50784"
"157.36700","179.55603","135.38852"
"157.49700","179.68593","136.28064"
"157.62700","179.81618","137.16051"
"157.75700","179.94617","138.04755"
"157.86300","180.02335","138.45413"
"157.99300","179.89355","137.18571"
"158.12300","179.76311","135.98634"
"158.25300","179.63315","134.83376"
"158.38300","179.50279","133.71199"
"158.51300","179.37297","132.60248"
"158.64300","179.24316","131.51949"
"158.77300","179.11290","130.44193"
"158.90300","178.98289","129.37126"
"159.03300","178.85321","128.31235"
"159.16300","178.72304","127.25536"
"159.29300","178.59279","126.20428"
"159.42300","178.46297","125.16034"
"159.55300","178.33313","124.12292"
"159.68300","178.20270","123.08634"
"159.81300","178.07294","122.05871"
"159.94300","177.94324","121.02737"
"160.07300","177.81299","120.00222"
"160.20300","177.68298","118.98538"
"160.33300","177.55310","117.96767"
"160.46300","177.42293","116.94984"
"160.59300","177.29282","115.93314"
"160.72300","177.16309","114.92273"
"160.85300","177.03308","113.91009"
"160.98300","176.90269","112.89423"
"161.11300","176.77301","111.89034"
"161.24300","176.64311","110.88651"
"161.37300","176.51273","109.88083"
"161.50300","176.38301","108.87920"
"161.63300","176.25325","107.87416"
"161.76300","176.12291","106.87127"
"161.89300","175.99287","105.87586"
"162.02300","175.86314","104.87713"
"162.15300","175.73296","103.87489"
"162.28300","175.60284","102.86671"
"162.41300","175.47301","101.86117"
"162.54300","175.34311","100.85848"
"162.67300","175.21278","99.85164"
"162.80300","175.08289","98.84904"
"162.93300","174.95314","97.85347"
"163.06300","174.82277","96.85738"
"163.19300","174.69304","95.85651"
"163.32300","174.56322","94.85393"
"163.45300","174.43282","93.85076"
"163.58300","174.30292","92.84928"
"163.71300","174.17314","91.85255"
"163.84300","174.04289","90.85065"
"163.97300","173.91275","89.85473"
"164.10300","173.78307","88.85745"
"164.23300","173.65308","87.85386"
"164.36300","173.52281","86.85837"
"164.49300","173.39305","85.85394"
"164.62300","173.26306","84.85490"
"164.75300","173.13277","83.85638"
"164.88300","173.00294","82.85764"
"165.01300","172.87320","81.86302"
"165.14300","172.74292","80.86487"
"165.27300","172.61288","79.85675"
"165.40300","172.48318","78.85672"
"165.53300","172.35303","77.85591"
"165.66300","172.22279","76.85173"
"165.79300","172.09305","75.84914"
"165.92300","171.96304","74.85456"
"166.05300","171.83272","73.85175"
"166.18300","171.70302","72.85893"
"166.31300","171.57317","71.86575"
"166.44300","171.44273","70.87218"
"166.57300","171.31296","69.87527"
"166.70300","171.18323","68.87061"
"166.83300","171.05296","67.85801"
"166.96300","170.92291","66.84723"
"167.09300","170.79311","65.84219"
"167.22300","170.66301","64.83301"
"167.35300","170.53278","63.81557"
"167.48300","170.40295","62.80473"
"167.61300","170.27310","61.79224"
"167.74300","170.14282","60.77627"
"167.87300","170.01292","59.76067"
"168.00300","169.88315","58.75127"
"168.13300","169.75282","57.72895"
"168.26300","169.62296","56.70410"
"168.39300","169.49310","55.68348"
"168.52300","169.36293","54.65382"
"168.65300","169.23297","53.62209"
"168.78300","169.10315","52.59662"
"168.91300","168.97298","51.56771"
"169.04300","168.84276","50.52954"
"169.17300","168.71303","49.49234"
"169.30300","168.58313","48.44711"
"169.43300","168.45279","47.39381"
"169.56300","168.32294","46.35264"
"169.69300","168.19321","45.30482"
"169.82300","168.06290","44.25064"
"169.95300","167.93298","43.19339"
"170.08300","167.80313","42.13266"
"170.21300","167.67290","41.06677"
"170.34300","167.54286","40.00378"
"170.47300","167.41310","38.93559"
"170.60300","167.28302","37.86524"
"170.73300","167.15274","36.79204"
"170.86300","167.02304","35.71646"
"170.99300","166.89319","34.63284"
"171.12300","166.76274","33.53577"
"171.25300","166.63295","32.45021"
"171.38300","166.50314","31.35429"
"171.51300","166.37280","30.25456"
"171.64300","166.24294","29.15215"
"171.77300","166.11314","28.04162"
"171.90300","165.98299","26.92321"
"172.03300","165.85294","25.80124"
"172.16300","165.72311","24.67331"
"172.29300","165.59297","23.54193"
"172.42300","165.46271","22.40611"
"172.55300","165.33301","21.28314"
"172.68300","165.20314","20.14851"
"172.81300","165.07280","19.00265"
"172.94300","164.94295","17.83752"
"173.07300","164.81323","16.66997"
"173.20300","164.68286","15.48077"
"173.33300","164.55296","14.27670"
"173.46300","164.42320","13.05469"
"173.59300","164.29292","11.81387"
"173.72300","164.16278","10.57360"
"173.85300","164.03311","9.32649"
"173.98300","163.90309","8.07866"
"174.11300","163.77275","6.81489"
"174.24300","163.64293","5.53605"
"174.37300","163.51315","4.24600"
"174.50300","163.38281","2.93978"
"174.63300","163.25294","1.63660"
"174.76300","163.12318","0.31751"
"174.89300","162.99290","-1.01972"
"175.02300","162.86293","-2.37006"
"175.15300","162.73309","-3.73677"
"175.28300","162.60303","-5.12391"
"175.33700","162.54912","-5.70168"