File: 1mms_0_1.is_tcyclic_RawData/Specimen_RawData_1.csv
Time,Extension,Load
(s),(mm),(N)
"0.00000","162.52650","-1.75156"
"0.13000","162.61731","-0.47959"
"0.26000","162.74974","1.16107"
"0.39000","162.87984","2.74701"
"0.52000","163.00960","4.25686"
"0.65000","163.13994","5.76603"
"0.78000","163.26984","7.22809"
"0.91000","163.39957","8.67471"
"1.04000","163.52980","10.11281"
"1.17000","163.65993","11.53011"
"1.30000","163.78954","12.94441"
"1.43000","163.91968","14.32240"
"1.56000","164.04993","15.71157"
"1.69000","164.17964","17.05461"
"1.82000","164.30960","18.38656"
"1.95000","164.43988","19.71287"
"2.08000","164.56984","21.02467"
"2.21000","164.69955","22.32402"
"2.34000","164.82990","23.60519"
"2.47000","164.95992","24.89633"
"2.60000","165.08946","26.15160"
"2.73000","165.21985","27.41712"
"2.86000","165.34990","28.66778"
"2.99000","165.47963","29.91178"
"3.12000","165.60966","31.13999"
"3.25000","165.73984","32.35004"
"3.38000","165.86972","33.55942"
"3.51000","165.99962","34.73325"
"3.64000","166.12987","35.91954"
"3.77000","166.25987","37.08528"
"3.90000","166.38956","38.24328"
"4.03000","166.51993","39.39177"
"4.16000","166.64992","40.51874"
"4.29000","166.77956","41.64464"
"4.42000","166.90982","42.76530"
"4.55000","167.03987","43.88785"
"4.68000","167.16959","44.99340"
"4.81000","167.29968","46.10394"
"4.94000","167.42993","47.20005"
"5.07000","167.55969","48.29564"
"5.20000","167.68962","49.38574"
"5.33000","167.81993","50.47930"
"5.46000","167.94992","51.57176"
"5.59000","168.07959","52.64196"
"5.72000","168.20990","53.73628"
"5.85000","168.33997","54.80866"
"5.98000","168.46959","55.88605"
"6.11000","168.59970","56.95602"
"6.24000","168.72981","58.02916"
"6.37000","168.85963","59.09735"
"6.50000","168.98972","60.16209"
"6.63000","169.11990","61.21756"
"6.76000","169.24974","62.25600"
"6.89000","169.37961","63.30848"
"7.02000","169.50996","64.34260"
"7.15000","169.63991","65.37426"
"7.28000","169.76953","66.40028"
"7.41000","169.89990","67.42778"
"7.54000","170.02988","68.45188"
"7.67000","170.15955","69.45705"
"7.80000","170.28976","70.47859"
"7.93000","170.41992","71.48356"
"8.06000","170.54956","72.48850"
"8.19000","170.67967","73.48899"
"8.32000","170.80991","74.48750"
"8.45000","170.93976","75.48586"
"8.58000","171.06961","76.46279"
"8.71000","171.19992","77.44743"
"8.84000","171.32991","78.41768"
"8.97000","171.45953","79.40432"
"9.10000","171.58994","80.38242"
"9.23000","171.71992","81.35893"
"9.36000","171.84952","82.32580"
"9.49000","171.97958","83.29623"
"9.62000","172.10995","84.26375"
"9.75000","172.23970","85.22140"
"9.88000","172.36969","86.19294"
"10.01000","172.49994","87.14714"
"10.14000","172.62981","88.09629"
"10.27000","172.75960","89.04704"
"10.40000","172.88989","90.00143"
"10.53000","173.01991","90.95372"
"10.66000","173.14961","91.89288"
"10.79000","173.27982","92.83466"
"10.92000","173.40988","93.76138"
"11.05000","173.53958","94.69425"
"11.18000","173.66971","95.62476"
"11.31000","173.79990","96.56013"
"11.44000","173.92967","97.49028"
"11.57000","174.05962","98.42253"
"11.70000","174.18991","99.35275"
"11.83000","174.31987","100.27357"
"11.96000","174.44960","101.19606"
"12.09000","174.57990","102.11668"
"12.22000","174.70993","103.03479"
"12.35000","174.83945","103.95184"
"12.48000","174.96985","104.87659"
"12.61000","175.09996","105.78611"
"12.74000","175.22957","106.70135"
"12.87000","175.35974","107.61797"
"13.00000","175.48993","108.52539"
"13.13000","175.61966","109.43819"
"13.26000","175.74957","110.33805"
"13.39000","175.87988","111.25573"
"13.52000","176.00993","112.15720"
"13.65000","176.13960","113.05620"
"13.78000","176.26984","113.96055"
"13.91000","176.39986","114.86022"
"14.04000","176.52959","115.76468"
"14.17000","176.65984","116.66798"
"14.30000","176.78992","117.56880"
"14.43000","176.91960","118.46124"
"14.56000","177.04962","119.36468"
"14.69000","177.17995","120.25832"
"14.82000","177.30975","121.15098"
"14.95000","177.43961","122.04939"
"15.08000","177.56992","122.94199"
"15.21000","177.69986","123.83366"
"15.34000","177.82956","124.71915"
"15.47000","177.95988","125.61709"
"15.60000","178.08994","126.50396"
"15.73000","178.21950","127.38828"
"15.86000","178.34984","128.27951"
"15.99000","178.47987","129.17282"
"16.12000","178.60962","130.05515"
"16.25000","178.73964","130.93730"
"16.38000","178.86995","131.81908"
"16.51000","178.99980","132.69844"
"16.64000","179.12961","133.58664"
"16.77000","179.25993","134.46704"
"16.90000","179.38985","135.34190"
"17.03000","179.51953","136.21500"
"17.16000","179.64983","137.08994"
"17.29000","179.77992","137.96785"
"17.42000","179.90959","138.83778"
"17.52300","180.01289","139.52368"
"17.65300","179.93506","138.60448"
"17.78300","179.80399","137.37947"
"17.91300","179.67354","136.20705"
"18.04300","179.54352","135.06725"
"18.17300","179.41373","133.95477"
"18.30300","179.28360","132.85344"
"18.43300","179.15344","131.77313"
"18.56300","179.02371","130.69727"
"18.69300","178.89383","129.62669"
"18.82300","178.76349","128.56284"
"18.95300","178.63367","127.50657"
"19.08300","178.50375","126.45268"
"19.21300","178.37344","125.40537"
"19.34300","178.24359","124.37160"
"19.47300","178.11378","123.33524"
"19.60300","177.98360","122.30648"
"19.73300","177.85358","121.27724"
"19.86300","177.72374","120.25452"
"19.99300","177.59369","119.23386"
"20.12300","177.46333","118.20950"
"20.25300","177.33363","117.18883"
"20.38300","177.20383","116.16800"
"20.51300","177.07341","115.15713"
"20.64300","176.94360","114.14050"
"20.77300","176.81386","113.13069"
"20.90300","176.68344","112.12379"
"21.03300","176.55353","111.11850"
"21.16300","176.42377","110.11996"
"21.29300","176.29370","109.11360"
"21.42300","176.16354","108.09760"
"21.55300","176.03362","107.09359"
"21.68300","175.90369","106.09834"
"21.81300","175.77341","105.09071"
"21.94300","175.64359","104.08340"
"22.07300","175.51382","103.08215"
"22.20300","175.38330","102.06906"
"22.33300","175.25360","101.06012"
"22.46300","175.12379","100.05756"
"22.59300","174.99345","99.05535"
"22.72300","174.86359","98.05009"
"22.85300","174.73380","97.04891"
"22.98300","174.60364","96.04120"
"23.11300","174.47348","95.03867"
"23.24300","174.34369","94.03539"
"23.37300","174.21370","93.03855"
"23.50300","174.08340","92.03407"
"23.63300","173.95360","91.03456"
"23.76300","173.82379","90.03624"
"23.89300","173.69347","89.03082"
"24.02300","173.56372","88.02484"
"24.15300","173.43378","87.02715"
"24.28300","173.30354","86.02443"
"24.41300","173.17352","85.01886"
"24.54300","173.04367","84.01346"
"24.67300","172.91359","83.01939"
"24.80300","172.78345","82.01982"
"24.93300","172.65366","81.01815"
"25.06300","172.52380","80.01513"
"25.19300","172.39337","79.00742"
"25.32300","172.26357","78.00656"
"25.45300","172.13379","77.00047"
"25.58300","172.00340","75.99503"
"25.71300","171.87358","74.99441"
"25.84300","171.74379","73.99147"
"25.97300","171.61351","72.99576"
"26.10300","171.48351","71.99637"
"26.23300","171.35374","71.00573"
"26.36300","171.22369","70.00407"
"26.49300","171.09344","68.99638"
"26.62300","170.96362","67.98943"
"26.75300","170.83374","66.97761"
"26.88300","170.70335","65.96429"
"27.01300","170.57362","64.94717"
"27.14300","170.44382","63.93198"
"27.27300","170.31355","62.91712"
"27.40300","170.18356","61.89991"
"27.53300","170.05380","60.88160"
"27.66300","169.92355","59.86456"
"27.79300","169.79347","58.84758"
"27.92300","169.66371","57.82604"
"28.05300","169.53374","56.79957"
"28.18300","169.40340","55.76999"
"28.31300","169.27361","54.74387"
"28.44300","169.14381","53.70668"
"28.57300","169.01337","52.67510"
"28.70300","168.88358","51.64035"
"28.83300","168.75375","50.59553"
"28.96300","168.62357","49.54963"
"29.09300","168.49367","48.50119"
"29.22300","168.36375","47.45249"
"29.35300","168.23355","46.40755"
"29.48300","168.10352","45.35073"
"29.61300","167.97366","44.29849"
"29.74300","167.84366","43.23722"
"29.87300","167.71338","42.16788"
"30.00300","167.58369","41.10786"
"30.13300","167.45383","40.04406"
"30.26300","167.32341","38.97025"
"30.39300","167.19359","37.90281"
"30.52300","167.06384","36.82597"
"30.65300","166.93350","35.74192"
"30.78300","166.80362","34.65441"
"30.91300","166.67380","33.56403"
"31.04300","166.54359","32.46782"
"31.17300","166.41345","31.36592"
"31.30300","166.28368","30.26581"
"31.43300","166.15372","29.15603"
"31.56300","166.02347","28.04086"
"31.69300","165.89368","26.92299"
"31.82300","165.76376","25.79217"
"31.95300","165.63339","24.65202"
"32.08300","165.50356","23.51717"
"32.21300","165.37376","22.38844"
"32.34300","165.24355","21.25217"
"32.47300","165.11353","20.11177"
"32.60300","164.98367","18.95725"
"32.73300","164.85365","17.79137"
"32.86300","164.72340","16.60865"
"32.99300","164.59367","15.41647"
"33.12300","164.46370","14.19384"
"33.25300","164.33337","12.95487"
"33.38300","164.20360","11.71042"
"33.51300","164.07379","10.46570"
"33.64300","163.94341","9.20820"
"33.77300","163.81366","7.94249"
"33.90300","163.68382","6.67864"
"34.03300","163.55354","5.37985"
"34.16300","163.42354","4.07948"
"34.29300","163.29372","2.77284"
"34.42300","163.16362","1.46193"
"34.55300","163.03345","0.12642"
"34.68300","162.90369","-1.21744"
"34.81300","162.77374","-2.58216"
"34.94300","162.64342","-3.96872"
"35.04900","162.53772","-5.10281"
"35.17900","162.61421","-3.78968"
"35.30900","162.74638","-2.02347"
"35.43900","162.87640","-0.35566"
"35.56900","163.00626","1.24538"
"35.69900","163.13654","2.81596"
"35.82900","163.26646","4.35178"
"35.95900","163.39615","5.85179"
"36.08900","163.52650","7.33313"
"36.21900","163.65656","8.80113"
"36.34900","163.78616","10.25170"
"36.47900","163.91638","11.68034"
"36.60900","164.04655","13.09832"
"36.73900","164.17630","14.49061"
"36.86900","164.30624","15.86308"
"36.99900","164.43654","17.22451"
"37.12900","164.56645","18.56956"
"37.25900","164.69620","19.90631"
"37.38900","164.82655","21.22622"
"37.51900","164.95654","22.53879"
"37.64900","165.08617","23.83124"
"37.77900","165.21642","25.11704"
"37.90900","165.34653","26.40248"
"38.03900","165.47621","27.66693"
"38.16900","165.60634","28.91759"
"38.29900","165.73650","30.16709"
"38.42900","165.86629","31.39422"
"38.55900","165.99628","32.60764"
"38.68900","166.12651","33.81187"
"38.81900","166.25652","35.00805"
"38.94900","166.38622","36.18819"
"39.07900","166.51656","37.36474"
"39.20900","166.64655","38.52937"
"39.33900","166.77618","39.67141"
"39.46900","166.90648","40.81065"
"39.59900","167.03656","41.95475"
"39.72900","167.16618","43.08835"
"39.85900","167.29634","44.20751"
"39.98900","167.42659","45.32664"
"40.11900","167.55627","46.42799"
"40.24900","167.68625","47.53154"
"40.37900","167.81657","48.63747"
"40.50900","167.94650","49.73520"
"40.63900","168.07626","50.82846"
"40.76900","168.20653","51.92681"
"40.89900","168.33661","53.02831"
"41.02900","168.46625","54.10563"
"41.15900","168.59637","55.18501"
"41.28900","168.72646","56.27224"
"41.41900","168.85625","57.35660"
"41.54900","168.98636","58.44006"
"41.67900","169.11655","59.50846"
"41.80900","169.24635","60.56944"
"41.93900","169.37630","61.62803"
"42.06900","169.50661","62.68594"
"42.19900","169.63654","63.73221"
"42.32900","169.76619","64.77294"
"42.45900","169.89655","65.81298"
"42.58900","170.02650","66.85722"
"42.71900","170.15617","67.87350"
"42.84900","170.28642","68.90252"
"42.97900","170.41655","69.92681"
"43.10900","170.54619","70.94385"
"43.23900","170.67633","71.95813"
"43.36900","170.80655","72.97047"
"43.49900","170.93636","73.97626"
"43.62900","171.06625","74.97191"
"43.75900","171.19652","75.96777"
"43.88900","171.32658","76.95673"
"44.01900","171.45618","77.94917"
"44.14900","171.58659","78.94845"
"44.27900","171.71657","79.93433"
"44.40900","171.84615","80.91757"
"44.53900","171.97638","81.89640"
"44.66900","172.10654","82.87129"
"44.79900","172.23633","83.84548"
"44.92900","172.36635","84.82292"
"45.05900","172.49655","85.79972"
"45.18900","172.62643","86.76615"
"45.31900","172.75624","87.72770"
"45.44900","172.88652","88.69449"
"45.57900","173.01654","89.65506"
"45.70900","173.14626","90.61478"
"45.83900","173.27650","91.57127"
"45.96900","173.40652","92.52267"
"46.09900","173.53621","93.46169"
"46.22900","173.66638","94.40094"
"46.35900","173.79660","95.35018"
"46.48900","173.92628","96.28972"
"46.61900","174.05629","97.22511"
"46.74900","174.18652","98.16264"
"46.87900","174.31644","99.10459"
"47.00900","174.44626","100.03236"
"47.13900","174.57654","100.96719"
"47.26900","174.70654","101.89927"
"47.39900","174.83614","102.82663"
"47.52900","174.96649","103.75716"
"47.65900","175.09662","104.68383"
"47.78900","175.22618","105.60335"
"47.91900","175.35641","106.52729"
"48.04900","175.48654","107.45171"
"48.17900","175.61629","108.37208"
"48.30900","175.74625","109.27810"
"48.43900","175.87651","110.20329"
"48.56900","176.00656","111.12127"
"48.69900","176.13629","112.02820"
"48.82900","176.26648","112.93590"
"48.95900","176.39647","113.85397"
"49.08900","176.52621","114.76595"
"49.21900","176.65649","115.68015"
"49.34900","176.78658","116.59056"
"49.47900","176.91620","117.49427"
"49.60900","177.04633","118.40870"
"49.73900","177.17661","119.30891"
"49.86900","177.30635","120.21288"
"49.99900","177.43623","121.11862"
"50.12900","177.56653","122.02361"
"50.25900","177.69649","122.92392"
"50.38900","177.82623","123.81279"
"50.51900","177.95657","124.71973"
"50.64900","178.08656","125.61620"
"50.77900","178.21614","126.51023"
"50.90900","178.34651","127.41499"
"51.03900","178.47655","128.31145"
"51.16900","178.60617","129.20456"
"51.29900","178.73625","130.09969"
"51.42900","178.86659","130.98680"
"51.55900","178.99641","131.87540"
"51.68900","179.12624","132.77095"
"51.81900","179.25658","133.66185"
"51.94900","179.38647","134.54475"
"52.07900","179.51617","135.42912"
"52.20900","179.64648","136.31985"
"52.33900","179.77657","137.19473"
"52.46900","179.90619","138.07903"
"52.57500","180.01254","138.78307"
"52.70500","179.93471","137.88046"
"52.83500","179.80362","136.65366"
"52.96500","179.67319","135.48460"
"53.09500","179.54314","134.35141"
"53.22500","179.41338","133.24255"
"53.35500","179.28328","132.14796"
"53.48500","179.15308","131.06538"
"53.61500","179.02338","129.99573"
"53.74500","178.89348","128.93697"
"53.87500","178.76308","127.87183"
"54.00500","178.63330","126.82040"
"54.13500","178.50342","125.77321"
"54.26500","178.37306","124.73029"
"54.39500","178.24326","123.69676"
"54.52500","178.11343","122.66239"
"54.65500","177.98325","121.63404"
"54.78500","177.85323","120.60806"
"54.91500","177.72337","119.59257"
"55.04500","177.59331","118.57213"
"55.17500","177.46298","117.55316"
"55.30500","177.33328","116.53735"
"55.43500","177.20349","115.52216"
"55.56500","177.07304","114.50646"
"55.69500","176.94324","113.49565"
"55.82500","176.81348","112.48748"
"55.95500","176.68311","111.48286"
"56.08500","176.55318","110.48534"
"56.21500","176.42340","109.48045"
"56.34500","176.29337","108.47720"
"56.47500","176.16321","107.46691"
"56.60500","176.03326","106.46715"
"56.73500","175.90334","105.47093"
"56.86500","175.77306","104.46660"
"56.99500","175.64325","103.46537"
"57.12500","175.51335","102.45931"
"57.25500","175.38304","101.45159"
"57.38500","175.25323","100.44398"
"57.51500","175.12340","99.44205"
"57.64500","174.99312","98.44088"
"57.77500","174.86322","97.44248"
"57.90500","174.73343","96.44541"
"58.03500","174.60329","95.44061"
"58.16500","174.47311","94.43302"
"58.29500","174.34334","93.43691"
"58.42500","174.21333","92.43788"
"58.55500","174.08307","91.43255"
"58.68500","173.95323","90.44059"
"58.81500","173.82344","89.44403"
"58.94500","173.69313","88.44176"
"59.07500","173.56334","87.44430"
"59.20500","173.43343","86.44749"
"59.33500","173.30319","85.44122"
"59.46500","173.17316","84.44303"
"59.59500","173.04332","83.44248"
"59.72500","172.91324","82.44373"
"59.85500","172.78311","81.44353"
"59.98500","172.65329","80.44101"
"60.11500","172.52339","79.44061"
"60.24500","172.39304","78.43193"
"60.37500","172.26324","77.43284"
"60.50500","172.13345","76.42989"
"60.63500","172.00305","75.42722"
"60.76500","171.87323","74.42855"
"60.89500","171.74341","73.42963"
"61.02500","171.61314","72.43052"
"61.15500","171.48315","71.43291"
"61.28500","171.35338","70.44398"
"61.41500","171.22331","69.44037"
"61.54500","171.09309","68.43210"
"61.67500","170.96327","67.42556"
"61.80500","170.83339","66.41941"
"61.93500","170.70300","65.40654"
"62.06500","170.57327","64.39579"
"62.19500","170.44348","63.38367"
"62.32500","170.31319","62.36710"
"62.45500","170.18324","61.35401"
"62.58500","170.05345","60.34370"
"62.71500","169.92316","59.32553"
"62.84500","169.79312","58.30594"
"62.97500","169.66338","57.28145"
"63.10500","169.53337","56.26260"
"63.23500","169.40305","55.23372"
"63.36500","169.27327","54.20851"
"63.49500","169.14345","53.17905"
"63.62500","169.01302","52.14645"
"63.75500","168.88322","51.11089"
"63.88500","168.75342","50.07419"
"64.01500","168.62321","49.02666"
"64.14500","168.49332","47.97768"
"64.27500","168.36333","46.93690"
"64.40500","168.23325","45.89299"
"64.53500","168.10316","44.83767"
"64.66500","167.97331","43.78576"
"64.79500","167.84329","42.73462"
"64.92500","167.71303","41.66087"
"65.05500","167.58336","40.60859"
"65.18500","167.45346","39.54126"
"65.31500","167.32306","38.46847"
"65.44500","167.19322","37.40094"
"65.57500","167.06348","36.32394"
"65.70500","166.93314","35.24150"
"65.83500","166.80324","34.15173"
"65.96500","166.67343","33.06453"
"66.09500","166.54321","31.96420"
"66.22500","166.41309","30.86794"
"66.35500","166.28333","29.76716"
"66.48500","166.15337","28.66079"
"66.61500","166.02310","27.54626"
"66.74500","165.89333","26.43243"
"66.87500","165.76340","25.30151"
"67.00500","165.63306","24.16270"
"67.13500","165.50323","23.03428"
"67.26500","165.37338","21.91245"
"67.39500","165.24318","20.77685"
"67.52500","165.11320","19.64035"
"67.65500","164.98340","18.48705"
"67.78500","164.85329","17.31531"
"67.91500","164.72308","16.13865"
"68.04500","164.59331","14.94350"
"68.17500","164.46335","13.72222"
"68.30500","164.33302","12.48421"
"68.43500","164.20328","11.24755"
"68.56500","164.07346","9.99683"
"68.69500","163.94304","8.74698"
"68.82500","163.81337","7.48194"
"68.95500","163.68350","6.21796"
"69.08500","163.55316","4.92334"
"69.21500","163.42317","3.62450"
"69.34500","163.29338","2.32444"
"69.47500","163.16327","1.00747"
"69.60500","163.03308","-0.32508"
"69.73500","162.90331","-1.66414"
"69.86500","162.77341","-3.02647"
"69.99500","162.64308","-4.41594"
"70.10100","162.53737","-5.54273"
"70.23100","162.61383","-4.22847"
"70.36100","162.74600","-2.46288"
"70.49100","162.87602","-0.79282"
"70.62100","163.00589","0.81012"
"70.75100","163.13620","2.38011"
"70.88100","163.26611","3.91380"
"71.01100","163.39581","5.41496"
"71.14100","163.52615","6.90368"
"71.27100","163.65616","8.36554"
"71.40100","163.78580","9.81520"
"71.53100","163.91595","11.25363"
"71.66100","164.04620","12.66124"
"71.79100","164.17590","14.06134"
"71.92100","164.30588","15.42923"
"72.05100","164.43614","16.79546"
"72.18100","164.56606","18.13814"
"72.31100","164.69585","19.46920"
"72.44100","164.82617","20.79243"
"72.57100","164.95616","22.10159"
"72.70100","165.08578","23.40063"
"72.83100","165.21606","24.68843"
"72.96100","165.34618","25.97612"
"73.09100","165.47588","27.24133"
"73.22100","165.60597","28.49658"
"73.35100","165.73615","29.73999"
"73.48100","165.86591","30.97227"
"73.61100","165.99591","32.19229"
"73.74100","166.12614","33.39463"
"73.87100","166.25613","34.59245"
"74.00100","166.38583","35.77388"
"74.13100","166.51616","36.94891"
"74.26100","166.64616","38.11870"
"74.39100","166.77579","39.26775"
"74.52100","166.90610","40.40936"
"74.65100","167.03621","41.54461"
"74.78100","167.16580","42.68681"
"74.91100","167.29597","43.80541"
"75.04100","167.42619","44.92632"
"75.17100","167.55591","46.02806"
"75.30100","167.68590","47.13005"
"75.43100","167.81619","48.23572"
"75.56100","167.94612","49.33041"
"75.69100","168.07587","50.42574"
"75.82100","168.20616","51.51693"
"75.95100","168.33624","52.61375"
"76.08100","168.46587","53.68720"
"76.21100","168.59599","54.77567"
"76.34100","168.72607","55.86044"
"76.47100","168.85590","56.94302"
"76.60100","168.98602","58.02368"
"76.73100","169.11618","59.09615"
"76.86100","169.24599","60.16428"
"76.99100","169.37589","61.22066"
"77.12100","169.50624","62.28336"
"77.25100","169.63615","63.32520"
"77.38100","169.76579","64.36549"
"77.51100","169.89616","65.41199"
"77.64100","170.02614","66.45203"
"77.77100","170.15581","67.47791"
"77.90100","170.28607","68.50478"
"78.03100","170.41620","69.53223"
"78.16100","170.54581","70.54075"
"78.29100","170.67598","71.56102"
"78.42100","170.80617","72.57246"
"78.55100","170.93599","73.58253"
"78.68100","171.06589","74.58100"
"78.81100","171.19618","75.56944"
"78.94100","171.32620","76.57192"
"79.07100","171.45580","77.55874"
"79.20100","171.58623","78.56352"
"79.33100","171.71620","79.54150"
"79.46100","171.84578","80.52892"
"79.59100","171.97598","81.50865"
"79.72100","172.10619","82.48785"
"79.85100","172.23592","83.46877"
"79.98100","172.36600","84.44761"
"80.11100","172.49620","85.42559"
"80.24100","172.62605","86.39126"
"80.37100","172.75586","87.35502"
"80.50100","172.88615","88.32211"
"80.63100","173.01616","89.29162"
"80.76100","173.14587","90.25018"
"80.89100","173.27609","91.20964"
"81.02100","173.40619","92.16552"
"81.15100","173.53586","93.10140"
"81.28100","173.66600","94.05142"
"81.41100","173.79616","94.98495"
"81.54100","173.92592","95.93054"
"81.67100","174.05589","96.87520"
"81.80100","174.18617","97.81916"
"81.93100","174.31607","98.75303"
"82.06100","174.44591","99.68617"
"82.19100","174.57616","100.62361"
"82.32100","174.70619","101.54991"
"82.45100","174.83574","102.48533"
"82.58100","174.96613","103.41187"
"82.71100","175.09621","104.34224"
"82.84100","175.22581","105.26302"
"82.97100","175.35608","106.19236"
"83.10100","175.48618","107.11552"
"83.23100","175.61591","108.03369"
"83.36100","175.74590","108.94995"
"83.49100","175.87613","109.86752"
"83.62100","176.00618","110.78921"
"83.75100","176.13588","111.69041"
"83.88100","176.26608","112.61230"
"84.01100","176.39612","113.52324"
"84.14100","176.52585","114.43547"
"84.27100","176.65613","115.35765"
"84.40100","176.78619","116.26849"
"84.53100","176.91583","117.18098"
"84.66100","177.04594","118.07555"
"84.79100","177.17622","118.99355"
"84.92100","177.30597","119.89503"
"85.05100","177.43588","120.80562"
"85.18100","177.56616","121.71255"
"85.31100","177.69609","122.61176"
"85.44100","177.82584","123.51027"
"85.57100","177.95619","124.41291"
"85.70100","178.08615","125.31387"
"85.83100","178.21579","126.20715"
"85.96100","178.34615","127.11243"
"86.09100","178.47615","128.01147"
"86.22100","178.60580","128.90356"
"86.35100","178.73595","129.80026"
"86.48100","178.86621","130.68918"
"86.61100","178.99603","131.58287"
"86.74100","179.12585","132.47318"
"86.87100","179.25618","133.37006"
"87.00100","179.38611","134.25264"
"87.13100","179.51579","135.14113"
"87.26100","179.64610","136.02907"
"87.39100","179.77618","136.91287"
"87.52100","179.90584","137.79443"
"87.62700","180.01218","138.50887"
"87.75700","179.93431","137.59795"
"87.88700","179.80325","136.37823"
"88.01700","179.67278","135.20610"
"88.14700","179.54277","134.07558"
"88.27700","179.41299","132.97015"
"88.40700","179.28287","131.87497"
"88.53700","179.15268","130.79291"
"88.66700","179.02296","129.72285"
"88.79700","178.89310","128.65756"
"88.92700","178.76265","127.59592"
"89.05700","178.63292","126.54662"
"89.18700","178.50307","125.50445"
"89.31700","178.37270","124.45574"
"89.44700","178.24284","123.42500"
"89.57700","178.11305","122.39620"
"89.70700","177.98285","121.36689"
"89.83700","177.85281","120.34241"
"89.96700","177.72301","119.31838"
"90.09700","177.59293","118.30764"
"90.22700","177.46259","117.28395"
"90.35700","177.33289","116.27282"
"90.48700","177.20308","115.25304"
"90.61700","177.07266","114.23780"
"90.74700","176.94284","113.22601"
"90.87700","176.81314","112.22559"
"91.00700","176.68268","111.21957"
"91.13700","176.55276","110.21503"
"91.26700","176.42303","109.21475"
"91.39700","176.29295","108.21358"
"91.52700","176.16280","107.19952"
"91.65700","176.03287","106.19971"
"91.78700","175.90295","105.20766"
"91.91700","175.77266","104.20187"
"92.04700","175.64288","103.20295"
"92.17700","175.51302","102.19954"
"92.30700","175.38257","101.18657"
"92.43700","175.25285","100.18310"
"92.56700","175.12303","99.18692"
"92.69700","174.99275","98.18288"
"92.82700","174.86285","97.18282"
"92.95700","174.73305","96.18711"
"93.08700","174.60291","95.18258"
"93.21700","174.47269","94.17936"
"93.34700","174.34293","93.18250"
"93.47700","174.21297","92.18189"
"93.60700","174.08269","91.18212"
"93.73700","173.95285","90.18774"
"93.86700","173.82303","89.18718"
"93.99700","173.69270","88.19064"
"94.12700","173.56296","87.18565"
"94.25700","173.43300","86.19157"
"94.38700","173.30281","85.18385"
"94.51700","173.17276","84.18263"
"94.64700","173.04292","83.18976"
"94.77700","172.91287","82.19125"
"94.90700","172.78270","81.19510"
"95.03700","172.65288","80.19010"
"95.16700","172.52306","79.18668"
"95.29700","172.39262","78.18307"
"95.42700","172.26283","77.18371"
"95.55700","172.13324","76.18768"
"95.68700","172.00262","75.17871"
"95.81700","171.87276","74.17998"
"95.94700","171.74304","73.18106"
"96.07700","171.61276","72.18127"
"96.20700","171.48276","71.18613"
"96.33700","171.35298","70.19485"
"96.46700","171.22295","69.19456"
"96.59700","171.09270","68.18695"
"96.72700","170.96289","67.18113"
"96.85700","170.83302","66.17319"
"96.98700","170.70261","65.15956"
"97.11700","170.57289","64.15182"
"97.24700","170.44307","63.14111"
"97.37700","170.31277","62.11934"
"97.50700","170.18285","61.11439"
"97.63700","170.05310","60.10287"
"97.76700","169.92279","59.08490"
"97.89700","169.79272","58.06770"
"98.02700","169.66296","57.04869"
"98.15700","169.53302","56.01944"
"98.28700","169.40265","54.99655"
"98.41700","169.27289","53.97379"
"98.54700","169.14308","52.94088"
"98.67700","169.01262","51.90978"
"98.80700","168.88281","50.87333"
"98.93700","168.75304","49.83558"
"99.06700","168.62282","48.79268"
"99.19700","168.49292","47.73990"
"99.32700","168.36299","46.69668"
"99.45700","168.23286","45.65329"
"99.58700","168.10274","44.59730"
"99.71700","167.97290","43.54958"
"99.84700","167.84293","42.49112"
"99.97700","167.71263","41.42313"
"100.10700","167.58293","40.36430"
"100.23700","167.45309","39.29977"
"100.36700","167.32269","38.22897"
"100.49700","167.19278","37.15287"
"100.62700","167.06310","36.08380"
"100.75700","166.93277","35.00076"
"100.88700","166.80287","33.91692"
"101.01700","166.67302","32.82598"
"101.14700","166.54283","31.73558"
"101.27700","166.41267","30.63603"
"101.40700","166.28293","29.53659"
"101.53700","166.15298","28.42878"
"101.66700","166.02272","27.31330"
"101.79700","165.89291","26.19188"
"101.92700","165.76303","25.07020"
"102.05700","165.63266","23.93188"
"102.18700","165.50278","22.80491"
"102.31700","165.37302","21.68089"
"102.44700","165.24283","20.55204"
"102.57700","165.11284","19.41049"
"102.70700","164.98299","18.25920"
"102.83700","164.85292","17.08485"
"102.96700","164.72269","15.90135"
"103.09700","164.59291","14.70396"
"103.22700","164.46298","13.48689"
"103.35700","164.33263","12.24865"
"103.48700","164.20287","11.00781"
"103.61700","164.07306","9.76686"
"103.74700","163.94266","8.51789"
"103.87700","163.81291","7.25831"
"104.00700","163.68307","5.98654"
"104.13700","163.55286","4.69946"
"104.26700","163.42274","3.39783"
"104.39700","163.29298","2.10241"
"104.52700","163.16287","0.78607"
"104.65700","163.03270","-0.54683"
"104.78700","162.90294","-1.88640"
"104.91700","162.77298","-3.24734"
"105.04700","162.64268","-4.63238"
"105.15300","162.53699","-5.75835"
"105.28300","162.61342","-4.44298"
"105.41300","162.74561","-2.67290"
"105.54300","162.87563","-1.01839"
"105.67300","163.00549","0.58742"
"105.80300","163.13580","2.15998"
"105.93300","163.26567","3.69871"
"106.06300","163.39542","5.19371"
"106.19300","163.52574","6.67885"
"106.32300","163.65570","8.14370"
"106.45300","163.78529","9.58833"
"106.58300","163.91568","11.02476"
"106.71300","164.04579","12.43591"
"106.84300","164.17549","13.83234"
"106.97300","164.30548","15.20093"
"107.10300","164.43575","16.56544"
"107.23300","164.56566","17.91130"
"107.36300","164.69543","19.24237"
"107.49300","164.82576","20.56984"
"107.62300","164.95576","21.87518"
"107.75300","165.08537","23.17039"
"107.88300","165.21564","24.45338"
"108.01300","165.34579","25.74275"
"108.14300","165.47543","27.01094"
"108.27300","165.60559","28.26422"
"108.40300","165.73572","29.50868"
"108.53300","165.86552","30.73957"
"108.66300","165.99550","31.95728"
"108.79300","166.12575","33.16993"
"108.92300","166.25574","34.36060"
"109.05300","166.38542","35.53976"
"109.18300","166.51579","36.72958"
"109.31300","166.64575","37.89098"
"109.44300","166.77541","39.04004"
"109.57300","166.90570","40.18248"
"109.70300","167.03580","41.32429"
"109.83300","167.16542","42.45769"
"109.96300","167.29558","43.57958"
"110.09300","167.42580","44.70080"
"110.22300","167.55551","45.80415"
"110.35300","167.68547","46.91100"
"110.48300","167.81580","48.01046"
"110.61300","167.94572","49.10284"
"110.74300","168.07547","50.19157"
"110.87300","168.20575","51.29652"
"111.00300","168.33578","52.39111"
"111.13300","168.46547","53.46558"
"111.26300","168.59558","54.55257"
"111.39300","168.72568","55.63361"
"111.52300","168.85547","56.71768"
"111.65300","168.98560","57.79752"
"111.78300","169.11577","58.87450"
"111.91300","169.24559","59.93970"
"112.04300","169.37550","60.99929"
"112.17300","169.50583","62.05959"
"112.30300","169.63574","63.10247"
"112.43300","169.76540","64.14664"
"112.56300","169.89575","65.19255"
"112.69300","170.02574","66.23042"
"112.82300","170.15543","67.26302"
"112.95300","170.28569","68.28609"
"113.08300","170.41577","69.31236"
"113.21300","170.54535","70.32735"
"113.34300","170.67558","71.34711"
"113.47300","170.80576","72.35773"
"113.60300","170.93558","73.37156"
"113.73300","171.06549","74.36662"
"113.86300","171.19576","75.35934"
"113.99300","171.32578","76.35107"
"114.12300","171.45541","77.35020"
"114.25300","171.58583","78.34814"
"114.38300","171.71579","79.33257"
"114.51300","171.84538","80.31922"
"114.64300","171.97559","81.30231"
"114.77300","172.10576","82.28699"
"114.90300","172.23555","83.26600"
"115.03300","172.36557","84.24585"
"115.16300","172.49580","85.21902"
"115.29300","172.62566","86.18947"
"115.42300","172.75546","87.15314"
"115.55300","172.88573","88.11741"
"115.68300","173.01576","89.08693"
"115.81300","173.14549","90.04248"
"115.94300","173.27571","91.00222"
"116.07300","173.40575","91.95103"
"116.20300","173.53546","92.90436"
"116.33300","173.66560","93.84416"
"116.46300","173.79576","94.78592"
"116.59300","173.92551","95.72865"
"116.72300","174.05550","96.66991"
"116.85300","174.18576","97.61550"
"116.98300","174.31564","98.55441"
"117.11300","174.44548","99.48529"
"117.24300","174.57576","100.41719"
"117.37300","174.70576","101.35174"
"117.50300","174.83534","102.28077"
"117.63300","174.96573","103.20980"
"117.76300","175.09581","104.14336"
"117.89300","175.22542","105.06583"
"118.02300","175.35564","105.99211"
"118.15300","175.48576","106.91634"
"118.28300","175.61554","107.83603"
"118.41300","175.74548","108.75583"
"118.54300","175.87573","109.67828"
"118.67300","176.00578","110.59254"
"118.80300","176.13548","111.50469"
"118.93300","176.26570","112.41682"
"119.06300","176.39571","113.33267"
"119.19300","176.52544","114.24355"
"119.32300","176.65573","115.16524"
"119.45300","176.78581","116.07264"
"119.58300","176.91541","116.98524"
"119.71300","177.04552","117.89268"
"119.84300","177.17581","118.80979"
"119.97300","177.30557","119.70705"
"120.10300","177.43546","120.62270"
"120.23300","177.56577","121.52951"
"120.36300","177.69568","122.42690"
"120.49300","177.82545","123.32963"
"120.62300","177.95581","124.22666"
"120.75300","178.08578","125.13262"
"120.88300","178.21535","126.02894"
"121.01300","178.34572","126.93214"
"121.14300","178.47574","127.83183"
"121.27300","178.60541","128.72929"
"121.40300","178.73547","129.62207"
"121.53300","178.86580","130.51630"
"121.66300","178.99562","131.40918"
"121.79300","179.12546","132.30261"
"121.92300","179.25581","133.19748"
"122.05300","179.38571","134.08701"
"122.18300","179.51540","134.97290"
"122.31300","179.64572","135.86139"
"122.44300","179.77577","136.74777"
"122.57300","179.90541","137.63228"
"122.68000","180.01273","138.34814"
"122.81000","179.93495","137.44156"
"122.94000","179.80388","136.22182"
"123.07000","179.67345","135.05489"
"123.20000","179.54340","133.92351"
"123.33000","179.41365","132.81187"
"123.46000","179.28351","131.71570"
"123.59000","179.15329","130.64117"
"123.72000","179.02361","129.57141"
"123.85000","178.89372","128.50716"
"123.98000","178.76334","127.44860"
"124.11000","178.63347","126.38775"
"124.24000","178.50369","125.34698"
"124.37000","178.37332","124.30209"
"124.50000","178.24347","123.27087"
"124.63000","178.11369","122.23605"
"124.76000","177.98349","121.20909"
"124.89000","177.85350","120.18519"
"125.02000","177.72362","119.16828"
"125.15000","177.59355","118.15397"
"125.28000","177.46323","117.10613"
"125.41000","177.33353","116.10454"
"125.54000","177.20375","115.07851"
"125.67000","177.07329","114.12334"
"125.80000","176.94348","113.05394"
"125.93000","176.81375","112.11716"
"126.06000","176.68333","111.05510"
"126.19000","176.55341","110.06647"
"126.32000","176.42368","109.05685"
"126.45000","176.29358","108.04226"
"126.58000","176.16347","107.05621"
"126.71000","176.03352","106.03098"
"126.84000","175.90358","105.07254"
"126.97000","175.77330","104.02421"
"127.10000","175.64351","103.05829"
"127.23000","175.51370","102.03803"
"127.36000","175.38329","101.03568"
"127.49000","175.25349","100.03533"
"127.62000","175.12367","99.01666"
"127.75000","174.99338","98.04127"
"127.88000","174.86349","97.01577"
"128.01000","174.73367","96.04947"
"128.14000","174.60353","95.01809"
"128.27000","174.47337","94.03176"
"128.40000","174.34355","93.02940"
"128.53000","174.21361","92.02283"
"128.66000","174.08333","91.04449"
"128.79000","173.95348","90.02056"
"128.92000","173.82368","89.05000"
"129.05000","173.69336","88.01929"
"129.18000","173.56358","87.04555"
"129.31000","173.43365","86.03063"
"129.44000","173.30345","85.03668"
"129.57000","173.17337","84.03592"
"129.70000","173.04355","83.02679"
"129.83000","172.91351","82.05086"
"129.96000","172.78336","81.02508"
"130.09000","172.65352","80.05139"
"130.22000","172.52364","79.02535"
"130.35000","172.39328","78.03689"
"130.48000","172.26346","77.02743"
"130.61000","172.13365","76.02876"
"130.74000","172.00327","75.03461"
"130.87000","171.87349","74.02026"
"131.00000","171.74371","73.04672"
"131.13000","171.61339","72.01865"
"131.26000","171.48341","71.04455"
"131.39000","171.35361","70.03741"
"131.52000","171.22357","69.03703"
"131.65000","171.09337","68.03572"
"131.78000","170.96353","67.02323"
"131.91000","170.83362","66.03354"
"132.04000","170.70328","65.00197"
"132.17000","170.57352","64.01088"
"132.30000","170.44371","62.97966"
"132.43000","170.31339","61.98227"
"132.56000","170.18347","60.95041"
"132.69000","170.05368","59.94674"
"132.82000","169.92343","58.93520"
"132.95000","169.79338","57.90940"
"133.08000","169.66360","56.90475"
"133.21000","169.53363","55.85592"
"133.34000","169.40331","54.85771"
"133.47000","169.27351","53.81033"
"133.60000","169.14369","52.80696"
"133.73000","169.01326","51.75887"
"133.86000","168.88347","50.73518"
"133.99000","168.75365","49.69820"
"134.12000","168.62343","48.64130"
"134.25000","168.49358","47.60351"
"134.38000","168.36362","46.54062"
"134.51000","168.23351","45.51670"
"134.64000","168.10341","44.44570"
"134.77000","167.97354","43.40681"
"134.90000","167.84354","42.33666"
"135.03000","167.71329","41.27555"
"135.16000","167.58357","40.22866"
"135.29000","167.45372","39.14302"
"135.42000","167.32330","38.09047"
"135.55000","167.19347","37.00548"
"135.68000","167.06372","35.94987"
"135.81000","166.93340","34.85164"
"135.94000","166.80350","33.77399"
"136.07000","166.67368","32.68133"
"136.20000","166.54346","31.58715"
"136.33000","166.41331","30.50012"
"136.46000","166.28357","29.38054"
"136.59000","166.15358","28.28653"
"136.72000","166.02336","27.16089"
"136.85000","165.89355","26.05166"
"136.98000","165.76363","24.91687"
"137.11000","165.63327","23.78232"
"137.24000","165.50346","22.65707"
"137.37000","165.37366","21.52822"
"137.50000","165.24344","20.40453"
"137.63000","165.11348","19.25874"
"137.76000","164.98363","18.11444"
"137.89000","164.85356","16.92967"
"138.02000","164.72334","15.74827"
"138.15000","164.59355","14.54407"
"138.28000","164.46361","13.32222"
"138.41000","164.33327","12.08190"
"138.54000","164.20351","10.84106"
"138.67000","164.07367","9.60054"
"138.80000","163.94330","8.33599"
"138.93000","163.81357","7.08175"
"139.06000","163.68373","5.80819"
"139.19000","163.55344","4.52326"
"139.32000","163.42342","3.22578"
"139.45000","163.29359","1.93097"
"139.58000","163.16348","0.62500"
"139.71000","163.03336","-0.71665"
"139.84000","162.90359","-2.04451"
"139.97000","162.77364","-3.40487"
"140.10000","162.64333","-4.78328"
"140.20600","162.53761","-5.91075"
"140.33600","162.61403","-4.59576"
"140.46600","162.74622","-2.82742"
"140.59600","162.87624","-1.16866"
"140.72600","163.00612","0.43046"
"140.85600","163.13641","1.99961"
"140.98600","163.26631","3.53857"
"141.11600","163.39601","5.02533"
"141.24600","163.52637","6.51877"
"141.37600","163.65636","7.97998"
"141.50600","163.78603","9.43582"
"141.63600","163.91621","10.86906"
"141.76600","164.04639","12.28247"
"141.89600","164.17612","13.69191"
"142.02600","164.30609","15.05257"
"142.15600","164.43636","16.42239"
"142.28600","164.56627","17.76169"
"142.41600","164.69606","19.09162"
"142.54600","164.82637","20.41669"
"142.67600","164.95639","21.72705"
"142.80600","165.08600","23.02553"
"142.93600","165.21626","24.31134"
"143.06600","165.34637","25.59717"
"143.19600","165.47606","26.86568"
"143.32600","165.60620","28.12391"
"143.45600","165.73634","29.36304"
"143.58600","165.86613","30.59478"
"143.71600","165.99612","31.81010"
"143.84600","166.12636","33.02291"
"143.97600","166.25633","34.21459"
"144.10600","166.38603","35.39461"
"144.23600","166.51640","36.57692"
"144.36600","166.64639","37.74250"
"144.49600","166.77600","38.89902"
"144.62600","166.90631","40.03698"
"144.75600","167.03641","41.17847"
"144.88600","167.16603","42.30946"
"145.01600","167.29619","43.43884"
"145.14600","167.42642","44.55398"
"145.27600","167.55612","45.65903"
"145.40600","167.68608","46.76308"
"145.53600","167.81642","47.86002"
"145.66600","167.94632","48.96304"
"145.79600","168.07605","50.04767"
"145.92600","168.20638","51.15150"
"146.05600","168.33646","52.24481"
"146.18600","168.46608","53.31767"
"146.31600","168.59619","54.39796"
"146.44600","168.72629","55.49085"
"146.57600","168.85611","56.57074"
"146.70600","168.98624","57.65350"
"146.83600","169.11639","58.73042"
"146.96600","169.24622","59.79486"
"147.09600","169.37610","60.85360"
"147.22600","169.50645","61.90743"
"147.35600","169.63635","62.96062"
"147.48600","169.76602","64.00481"
"147.61600","169.89639","65.05066"
"147.74600","170.02637","66.09351"
"147.87600","170.15602","67.11847"
"148.00600","170.28629","68.14426"
"148.13600","170.41638","69.17287"
"148.26600","170.54599","70.18506"
"148.39600","170.67618","71.20342"
"148.52600","170.80640","72.21664"
"148.65600","170.93620","73.22305"
"148.78600","171.06607","74.22387"
"148.91600","171.19638","75.22339"
"149.04600","171.32640","76.21722"
"149.17600","171.45602","77.21438"
"149.30600","171.58643","78.21436"
"149.43600","171.71642","79.19788"
"149.56600","171.84599","80.18232"
"149.69600","171.97620","81.16360"
"149.82600","172.10640","82.15099"
"149.95600","172.23616","83.12877"
"150.08600","172.36620","84.10638"
"150.21600","172.49643","85.08427"
"150.34600","172.62627","86.05059"
"150.47600","172.75607","87.01716"
"150.60600","172.88635","87.98520"
"150.73600","173.01637","88.95103"
"150.86600","173.14609","89.90939"
"150.99600","173.27634","90.86600"
"151.12600","173.40636","91.81662"
"151.25600","173.53609","92.76143"
"151.38600","173.66621","93.70561"
"151.51600","173.79639","94.65089"
"151.64600","173.92612","95.59541"
"151.77600","174.05611","96.53987"
"151.90600","174.18639","97.48383"
"152.03600","174.31630","98.41653"
"152.16600","174.44609","99.35181"
"152.29600","174.57635","100.28546"
"152.42600","174.70642","101.21498"
"152.55600","174.83595","102.15217"
"152.68600","174.96634","103.08363"
"152.81600","175.09644","104.01065"
"152.94600","175.22603","104.93321"
"153.07600","175.35628","105.86326"
"153.20600","175.48639","106.78812"
"153.33600","175.61612","107.70797"
"153.46600","175.74608","108.62020"
"153.59600","175.87634","109.54665"
"153.72600","176.00639","110.46898"
"153.85600","176.13609","111.37392"
"153.98600","176.26630","112.29070"
"154.11600","176.39632","113.19942"
"154.24600","176.52606","114.11945"
"154.37600","176.65633","115.03955"
"154.50600","176.78638","115.95618"
"154.63600","176.91606","116.86112"
"154.76600","177.04613","117.76741"
"154.89600","177.17644","118.67984"
"155.02600","177.30618","119.58116"
"155.15600","177.43611","120.49403"
"155.28600","177.56638","121.40489"
"155.41600","177.69633","122.30863"
"155.54600","177.82607","123.20128"
"155.67600","177.95642","124.10689"
"155.80600","178.08641","125.00997"
"155.93600","178.21597","125.90776"
"156.06600","178.34634","126.80776"
"156.19600","178.47636","127.70995"
"156.32600","178.60600","128.60739"
"156.45600","178.73613","129.49765"
"156.58600","178.86644","130.39476"
"156.71600","178.99623","131.28761"
"156.84600","179.12607","132.18495"
"156.97600","179.25641","133.08142"
"157.10600","179.38631","133.97121"
"157.23600","179.51604","134.85719"
"157.36600","179.64632","135.74750"
"157.49600","179.77640","136.63399"
"157.62600","179.90605","137.52010"
"157.73200","180.01237","138.22893"
"157.86200","179.93460","137.32483"
"157.99200","179.80354","136.10225"
"158.12200","179.67308","134.93413"
"158.25200","179.54305","133.80408"
"158.38200","179.41325","132.69652"
"158.51200","179.28314","131.60002"
"158.64200","179.15297","130.52327"
"158.77200","179.02325","129.45309"
"158.90200","178.89336","128.38828"
"159.03200","178.76294","127.32506"
"159.16200","178.63322","126.27794"
"159.29200","178.50328","125.23383"
"159.42200","178.37296","124.19051"
"159.55200","178.24313","123.15734"
"159.68200","178.11333","122.12714"
"159.81200","177.98314","121.09494"
"159.94200","177.85309","120.06968"
"160.07200","177.72327","119.04525"
"160.20200","177.59320","118.03053"
"160.33200","177.46288","117.01684"
"160.46200","177.33319","115.99747"
"160.59200","177.20338","114.98140"
"160.72200","177.07292","113.97124"
"160.85200","176.94315","112.96066"
"160.98200","176.81339","111.95490"
"161.11200","176.68295","110.94703"
"161.24200","176.55307","109.94018"
"161.37200","176.42332","108.94566"
"161.50200","176.29324","107.93995"
"161.63200","176.16310","106.92931"
"161.76200","176.03317","105.93108"
"161.89200","175.90323","104.93698"
"162.02200","175.77296","103.93274"
"162.15200","175.64313","102.93454"
"162.28200","175.51328","101.92646"
"162.41200","175.38289","100.92019"
"162.54200","175.25313","99.91026"
"162.67200","175.12332","98.91325"
"162.80200","174.99303","97.90922"
"162.93200","174.86310","96.90611"
"163.06200","174.73332","95.91949"
"163.19200","174.60318","94.91266"
"163.32200","174.47301","93.90657"
"163.45200","174.34322","92.90532"
"163.58200","174.21324","91.90923"
"163.71200","174.08295","90.90987"
"163.84200","173.95309","89.91801"
"163.97200","173.82333","88.91660"
"164.10200","173.69299","87.91724"
"164.23200","173.56323","86.91799"
"164.36200","173.43332","85.92023"
"164.49200","173.30307","84.91621"
"164.62200","173.17303","83.91685"
"164.75200","173.04320","82.91894"
"164.88200","172.91316","81.91975"
"165.01200","172.78299","80.92432"
"165.14200","172.65318","79.92133"
"165.27200","172.52330","78.91702"
"165.40200","172.39290","77.91553"
"165.53200","172.26312","76.91577"
"165.66200","172.13333","75.90846"
"165.79200","172.00294","74.90936"
"165.92200","171.87312","73.91026"
"166.05200","171.74332","72.91276"
"166.18200","171.61305","71.91444"
"166.31200","171.48303","70.91589"
"166.44200","171.35327","69.92097"
"166.57200","171.22324","68.91603"
"166.70200","171.09300","67.91232"
"166.83200","170.96313","66.90907"
"166.96200","170.83325","65.90674"
"167.09200","170.70290","64.89021"
"167.22200","170.57317","63.87711"
"167.35200","170.44334","62.86432"
"167.48200","170.31305","61.84743"
"167.61200","170.18309","60.83477"
"167.74200","170.05334","59.82427"
"167.87200","169.92307","58.81150"
"168.00200","169.79301","57.79420"
"168.13200","169.66328","56.77211"
"168.26200","169.53329","55.74679"
"168.39200","169.40291","54.71925"
"168.52200","169.27316","53.69818"
"168.65200","169.14336","52.66932"
"168.78200","169.01289","51.63873"
"168.91200","168.88310","50.60854"
"169.04200","168.75333","49.56728"
"169.17200","168.62309","48.52273"
"169.30200","168.49321","47.47004"
"169.43200","168.36328","46.42697"
"169.56200","168.23308","45.38018"
"169.69200","168.10304","44.33214"
"169.82200","167.97321","43.27993"
"169.95200","167.84319","42.22470"
"170.08200","167.71289","41.16287"
"170.21200","167.58321","40.09955"
"170.34200","167.45337","39.03310"
"170.47200","167.32294","37.95682"
"170.60200","167.19308","36.88712"
"170.73200","167.06340","35.82017"
"170.86200","166.93303","34.73745"
"170.99200","166.80315","33.64693"
"171.12200","166.67329","32.56034"
"171.25200","166.54311","31.46197"
"171.38200","166.41293","30.36503"
"171.51200","166.28317","29.26679"
"171.64200","166.15326","28.15870"
"171.77200","166.02298","27.05055"
"171.90200","165.89323","25.92210"
"172.03200","165.76331","24.80353"
"172.16200","165.63293","23.66329"
"172.29200","165.50308","22.53737"
"172.42200","165.37328","21.41759"
"172.55200","165.24309","20.28410"
"172.68200","165.11311","19.15070"
"172.81200","164.98329","17.99585"
"172.94200","164.85318","16.82583"
"173.07200","164.72296","15.63828"
"173.20200","164.59319","14.44117"
"173.33200","164.46327","13.22014"
"173.46200","164.33290","11.98240"
"173.59200","164.20314","10.74112"
"173.72200","164.07336","9.48829"
"173.85200","163.94295","8.23245"
"173.98200","163.81316","6.96890"
"174.11200","163.68338","5.69878"
"174.24200","163.55309","4.41115"
"174.37200","163.42305","3.11637"
"174.50200","163.29326","1.81979"
"174.63200","163.16316","0.50596"
"174.76200","163.03297","-0.82616"
"174.89200","162.90321","-2.16701"
"175.02200","162.77328","-3.51625"
"175.15200","162.64297","-4.89365"
"175.24600","162.54927","-5.89255"