File: data/instron/1104/5mms.is_tcyclic_RawData/Specimen_RawData_1.csv
Time,Extension,Load
(s),(mm),(N)
"0.00000","162.43481","0.02818"
"0.03000","162.44850","0.51272"
"0.06000","162.54922","1.84728"
"0.09000","162.69727","3.83484"
"0.12000","162.85518","5.81872"
"0.15000","163.00816","7.69230"
"0.18000","163.15904","9.49625"
"0.21000","163.30951","11.26420"
"0.24000","163.45975","13.00117"
"0.27000","163.60983","14.69844"
"0.30000","163.75984","16.40128"
"0.33000","163.90991","18.07567"
"0.36000","164.05997","19.70895"
"0.39000","164.20995","21.32489"
"0.42000","164.35997","22.92224"
"0.45000","164.51001","24.50813"
"0.48000","164.66003","26.06462"
"0.51000","164.81007","27.62196"
"0.54000","164.95998","29.16386"
"0.57000","165.10991","30.66493"
"0.60000","165.25993","32.17192"
"0.63000","165.40994","33.67105"
"0.66000","165.56001","35.14399"
"0.69000","165.70998","36.60252"
"0.72000","165.85997","38.04632"
"0.75000","166.00995","39.48254"
"0.78000","166.15999","40.90329"
"0.81000","166.31006","42.31572"
"0.84000","166.46007","43.72211"
"0.87000","166.61006","45.10598"
"0.90000","166.76009","46.47877"
"0.93000","166.91003","47.84503"
"0.96000","167.06001","49.21803"
"0.99000","167.20996","50.57661"
"1.02000","167.35999","51.91576"
"1.05000","167.51001","53.25046"
"1.08000","167.66002","54.57074"
"1.11000","167.81009","55.87694"
"1.14000","167.96011","57.18377"
"1.17000","168.11009","58.48632"
"1.20000","168.26004","59.77833"
"1.23000","168.41014","61.06010"
"1.26000","168.56015","62.33682"
"1.29000","168.70993","63.61678"
"1.32000","168.85980","64.89303"
"1.35000","169.00998","66.16766"
"1.38000","169.16010","67.44376"
"1.41000","169.31001","68.72320"
"1.44000","169.46001","69.98528"
"1.47000","169.61003","71.23989"
"1.50000","169.76006","72.49746"
"1.53000","169.91011","73.74626"
"1.56000","170.06010","74.99755"
"1.59000","170.20992","76.25253"
"1.62000","170.35980","77.49744"
"1.65000","170.50992","78.72897"
"1.68000","170.65999","79.95036"
"1.71000","170.81001","81.15828"
"1.74000","170.96004","82.35363"
"1.77000","171.11003","83.54118"
"1.80000","171.26003","84.72198"
"1.83000","171.40996","85.89480"
"1.86000","171.56001","87.06664"
"1.89000","171.71008","88.22402"
"1.92000","171.86000","89.37257"
"1.95000","172.00998","90.51553"
"1.98000","172.16000","91.65550"
"2.01000","172.31003","92.79665"
"2.04000","172.46010","93.93291"
"2.07000","172.61002","95.06073"
"2.10000","172.75998","96.17334"
"2.13000","172.91002","97.29241"
"2.16000","173.06001","98.40659"
"2.19000","173.21010","99.50484"
"2.22000","173.36003","100.57079"
"2.25000","173.50995","101.65749"
"2.28000","173.65999","102.75446"
"2.31000","173.81000","103.84798"
"2.34000","173.95998","104.92885"
"2.37000","174.11002","106.01321"
"2.40000","174.26009","107.08293"
"2.43000","174.41014","108.15240"
"2.46000","174.56010","109.21340"
"2.49000","174.71005","110.27779"
"2.52000","174.85991","111.32487"
"2.55000","175.00993","112.36835"
"2.58000","175.16002","113.41228"
"2.61000","175.30998","114.45522"
"2.64000","175.46001","115.49538"
"2.67000","175.61000","116.53419"
"2.70000","175.75998","117.57668"
"2.73000","175.90999","118.61700"
"2.76000","176.06010","119.64806"
"2.79000","176.21014","120.67191"
"2.82000","176.35994","121.69186"
"2.85000","176.50984","122.70950"
"2.88000","176.66002","123.73091"
"2.91000","176.81012","124.74788"
"2.94000","176.96005","125.77656"
"2.97000","177.10986","126.78703"
"3.00000","177.26006","127.79327"
"3.03000","177.41019","128.79839"
"3.06000","177.56010","129.79227"
"3.09000","177.71004","130.78912"
"3.12000","177.85995","131.78291"
"3.15000","178.00996","132.77202"
"3.18000","178.16006","133.76753"
"3.21000","178.31009","134.76637"
"3.24000","178.46010","135.75087"
"3.27000","178.61002","136.73332"
"3.30000","178.76001","137.71213"
"3.33000","178.91005","138.68607"
"3.36000","179.06003","139.66203"
"3.39000","179.21002","140.63919"
"3.42000","179.36005","141.60931"
"3.45000","179.50995","142.57710"
"3.48000","179.65999","143.54465"
"3.51000","179.81001","144.50470"
"3.54000","179.96002","145.46284"
"3.55000","180.01007","145.77786"
"3.58000","180.13123","145.94316"
"3.61000","180.06784","145.37367"
"3.64000","179.91849","143.86128"
"3.67000","179.75912","142.38705"
"3.70000","179.60641","140.94379"
"3.73000","179.45589","139.55803"
"3.76000","179.30559","138.19315"
"3.79000","179.15535","136.85957"
"3.82000","179.00519","135.56145"
"3.85000","178.85516","134.23738"
"3.88000","178.70512","132.96033"
"3.91000","178.55510","131.69084"
"3.94000","178.40504","130.40610"
"3.97000","178.25500","129.13680"
"4.00000","178.10498","127.87074"
"4.03000","177.95493","126.62444"
"4.06000","177.80507","125.37517"
"4.09000","177.65523","124.13359"
"4.12000","177.50514","122.91694"
"4.15000","177.35509","121.67756"
"4.18000","177.20505","120.43835"
"4.21000","177.05489","119.20541"
"4.24000","176.90489","117.97826"
"4.27000","176.75494","116.74983"
"4.30000","176.60490","115.53045"
"4.33000","176.45488","114.33120"
"4.36000","176.30501","113.11337"
"4.39000","176.15517","111.89144"
"4.42000","176.00510","110.67863"
"4.45000","175.85504","109.46159"
"4.48000","175.70503","108.24333"
"4.51000","175.55501","107.02272"
"4.54000","175.40511","105.81232"
"4.57000","175.25493","104.60788"
"4.60000","175.10493","103.39854"
"4.63000","174.95493","102.19946"
"4.66000","174.80492","100.99345"
"4.69000","174.65503","99.78497"
"4.72000","174.50513","98.57204"
"4.75000","174.35507","97.36638"
"4.78000","174.20505","96.16158"
"4.81000","174.05498","94.96065"
"4.84000","173.90494","93.76605"
"4.87000","173.75494","92.56154"
"4.90000","173.60500","91.36085"
"4.93000","173.45503","90.15067"
"4.96000","173.30504","88.94172"
"4.99000","173.15498","87.74520"
"5.02000","173.00493","86.53563"
"5.05000","172.85495","85.34643"
"5.08000","172.70505","84.15221"
"5.11000","172.55504","82.95665"
"5.14000","172.40511","81.75011"
"5.17000","172.25510","80.53979"
"5.20000","172.10497","79.33897"
"5.23000","171.95497","78.12878"
"5.26000","171.80492","76.93668"
"5.29000","171.65495","75.74922"
"5.32000","171.50499","74.55854"
"5.35000","171.35493","73.36028"
"5.38000","171.20499","72.15131"
"5.41000","171.05504","70.94708"
"5.44000","170.90509","69.73978"
"5.47000","170.75504","68.53058"
"5.50000","170.60503","67.33268"
"5.53000","170.45505","66.13029"
"5.56000","170.30495","64.92323"
"5.59000","170.15491","63.70998"
"5.62000","170.00507","62.48410"
"5.65000","169.85507","61.26973"
"5.68000","169.70505","60.04382"
"5.71000","169.55504","58.82768"
"5.74000","169.40497","57.60776"
"5.77000","169.25497","56.38666"
"5.80000","169.10506","55.16414"
"5.83000","168.95502","53.93093"
"5.86000","168.80489","52.69085"
"5.89000","168.65500","51.43919"
"5.92000","168.50511","50.19022"
"5.95000","168.35506","48.94254"
"5.98000","168.20499","47.69138"
"6.01000","168.05501","46.44268"
"6.04000","167.90501","45.17716"
"6.07000","167.75500","43.90056"
"6.10000","167.60498","42.62510"
"6.13000","167.45506","41.34091"
"6.16000","167.30505","40.05680"
"6.19000","167.15497","38.77044"
"6.22000","167.00504","37.47263"
"6.25000","166.85506","36.17149"
"6.28000","166.70502","34.86054"
"6.31000","166.55499","33.54211"
"6.34000","166.40495","32.21818"
"6.37000","166.25497","30.89427"
"6.40000","166.10500","29.55959"
"6.43000","165.95508","28.21852"
"6.46000","165.80515","26.87748"
"6.49000","165.65509","25.51228"
"6.52000","165.50499","24.14505"
"6.55000","165.35493","22.77258"
"6.58000","165.20490","21.38120"
"6.61000","165.05493","19.98657"
"6.64000","164.90491","18.57385"
"6.67000","164.75502","17.14942"
"6.70000","164.60506","15.71413"
"6.73000","164.45503","14.26713"
"6.76000","164.30499","12.80785"
"6.79000","164.15498","11.33823"
"6.82000","164.00504","9.87018"
"6.85000","163.85503","8.36549"
"6.88000","163.70497","6.85151"
"6.91000","163.55501","5.30327"
"6.94000","163.40504","3.74706"
"6.97000","163.25505","2.16144"
"7.00000","163.10500","0.57600"
"7.03000","162.95502","-1.03384"
"7.06000","162.80508","-2.65930"
"7.09000","162.65504","-4.30210"
"7.11200","162.54501","-5.52950"
"7.12400","162.48520","-6.15659"
"7.15400","162.41512","-6.20102"
"7.18400","162.52122","-4.66090"
"7.21400","162.67891","-2.44429"
"7.24400","162.83682","-0.29315"
"7.27400","162.98860","1.68153"
"7.30400","163.13908","3.59966"
"7.33400","163.28943","5.44717"
"7.36400","163.43965","7.31186"
"7.39400","163.58968","9.07488"
"7.42400","163.73970","10.85533"
"7.45400","163.88979","12.62189"
"7.48400","164.03984","14.31917"
"7.51400","164.18988","16.00971"
"7.54400","164.33990","17.67319"
"7.57400","164.48991","19.31798"
"7.60400","164.63991","20.93098"
"7.63400","164.78987","22.52143"
"7.66400","164.93983","24.12439"
"7.69400","165.08986","25.67723"
"7.72400","165.23979","27.22890"
"7.75400","165.38974","28.76587"
"7.78400","165.53986","30.28437"
"7.81400","165.68982","31.79548"
"7.84400","165.83980","33.26937"
"7.87400","165.98984","34.75167"
"7.90400","166.13988","36.21004"
"7.93400","166.28990","37.63368"
"7.96400","166.43996","39.07369"
"7.99400","166.58994","40.48724"
"8.02400","166.73993","41.88663"
"8.05400","166.88989","43.26646"
"8.08400","167.03992","44.65004"
"8.11400","167.18985","46.01778"
"8.14400","167.33986","47.35387"
"8.17400","167.48987","48.68723"
"8.20400","167.63989","50.01426"
"8.23400","167.78993","51.34185"
"8.26400","167.93996","52.66894"
"8.29400","168.08998","53.98331"
"8.32400","168.23991","55.30312"
"8.35400","168.38997","56.60263"
"8.38400","168.54001","57.90135"
"8.41400","168.68980","59.19486"
"8.44400","168.83966","60.48433"
"8.47400","168.98984","61.77023"
"8.50400","169.13995","63.05266"
"8.53400","169.28989","64.32103"
"8.56400","169.43990","65.58990"
"8.59400","169.58992","66.84387"
"8.62400","169.73993","68.10255"
"8.65400","169.88994","69.34889"
"8.68400","170.03993","70.58946"
"8.71400","170.18983","71.82217"
"8.74400","170.33972","73.04691"
"8.77400","170.48982","74.27502"
"8.80400","170.63988","75.48964"
"8.83400","170.78989","76.70222"
"8.86400","170.93990","77.91132"
"8.89400","171.08987","79.10369"
"8.92400","171.23991","80.29002"
"8.95400","171.38988","81.47547"
"8.98400","171.53986","82.66015"
"9.01400","171.68996","83.84501"
"9.04400","171.83989","85.01994"
"9.07400","171.98985","86.19402"
"9.10400","172.13985","87.35511"
"9.13400","172.28984","88.52370"
"9.16400","172.43991","89.68343"
"9.19400","172.58994","90.83752"
"9.22400","172.73991","91.98997"
"9.25400","172.88992","93.13470"
"9.28400","173.03990","94.28400"
"9.31400","173.18996","95.42566"
"9.34400","173.33990","96.56210"
"9.37400","173.48984","97.69962"
"9.40400","173.63982","98.82468"
"9.43400","173.78983","99.94684"
"9.46400","173.93983","101.07648"
"9.49400","174.08987","102.19469"
"9.52400","174.23991","103.29535"
"9.55400","174.38998","104.38442"
"9.58400","174.53996","105.48182"
"9.61400","174.68994","106.58111"
"9.64400","174.83983","107.66592"
"9.67400","174.98982","108.76037"
"9.70400","175.13985","109.85996"
"9.73400","175.28986","110.96183"
"9.76400","175.43987","112.05663"
"9.79400","175.58987","113.14599"
"9.82400","175.73987","114.23540"
"9.85400","175.88985","115.31841"
"9.88400","176.03998","116.39725"
"9.91400","176.19005","117.47681"
"9.94400","176.33986","118.54811"
"9.97400","176.48972","119.62976"
"10.00400","176.63983","120.71574"
"10.03400","176.78995","121.79308"
"10.06400","176.93993","122.87312"
"10.09400","177.08984","123.94059"
"10.12400","177.23991","125.00230"
"10.15400","177.38997","126.06621"
"10.18400","177.53990","127.12680"
"10.21400","177.68991","128.19069"
"10.24400","177.83987","129.25069"
"10.27400","177.98984","130.30167"
"10.30400","178.13994","131.35327"
"10.33400","178.28995","132.40308"
"10.36400","178.43993","133.45061"
"10.39400","178.58987","134.49492"
"10.42400","178.73987","135.53902"
"10.45400","178.88991","136.58463"
"10.48400","179.03992","137.62440"
"10.51400","179.18991","138.65941"
"10.54400","179.33992","139.68842"
"10.57400","179.48985","140.71797"
"10.60400","179.63983","141.74429"
"10.63400","179.78987","142.76671"
"10.66400","179.93987","143.79700"
"10.67800","180.00990","144.27269"
"10.69900","180.10974","144.66179"
"10.72900","180.11047","144.29321"
"10.75900","179.97632","143.00868"
"10.78900","179.81625","141.54286"
"10.81900","179.66162","140.04968"
"10.84900","179.51077","138.67757"
"10.87900","179.36046","137.32602"
"10.90900","179.21022","136.02032"
"10.93900","179.06000","134.69125"
"10.96900","178.90994","133.38345"
"10.99900","178.75996","132.11586"
"11.02900","178.60992","130.82062"
"11.05900","178.45988","129.54247"
"11.08900","178.30981","128.28998"
"11.11900","178.15974","127.04357"
"11.14900","178.00972","125.79721"
"11.17900","177.85982","124.53699"
"11.20900","177.71002","123.32405"
"11.23900","177.55997","122.08715"
"11.26900","177.40984","120.84348"
"11.29900","177.25983","119.63088"
"11.32900","177.10971","118.39851"
"11.35900","176.95967","117.17094"
"11.38900","176.80971","115.96208"
"11.41900","176.65971","114.74622"
"11.44900","176.50966","113.53559"
"11.47900","176.35974","112.30969"
"11.50900","176.20993","111.10121"
"11.53900","176.05995","109.89847"
"11.56900","175.90982","108.68906"
"11.59900","175.75984","107.48560"
"11.62900","175.60982","106.27515"
"11.65900","175.45984","105.07044"
"11.68900","175.30974","103.85443"
"11.71900","175.15973","102.64668"
"11.74900","175.00970","101.45296"
"11.77900","174.85968","100.25420"
"11.80900","174.70979","99.05737"
"11.83900","174.55992","97.85709"
"11.86900","174.40988","96.65697"
"11.89900","174.25987","95.45270"
"11.92900","174.10985","94.24811"
"11.95900","173.95976","93.05345"
"11.98900","173.80969","91.85192"
"12.01900","173.65973","90.65074"
"12.04900","173.50981","89.45644"
"12.07900","173.35986","88.25426"
"12.10900","173.20982","87.05296"
"12.13900","173.05972","85.85231"
"12.16900","172.90971","84.65754"
"12.19900","172.75983","83.46391"
"12.22900","172.60985","82.26861"
"12.25900","172.45988","81.08035"
"12.28900","172.30989","79.89453"
"12.31900","172.15977","78.70409"
"12.34900","172.00977","77.51638"
"12.37900","171.85983","76.32326"
"12.40900","171.70976","75.13135"
"12.43900","171.55974","73.94283"
"12.46900","171.40970","72.75399"
"12.49900","171.25972","71.55846"
"12.52900","171.10983","70.35423"
"12.55900","170.95988","69.14800"
"12.58900","170.80986","67.95042"
"12.61900","170.65979","66.74590"
"12.64900","170.50981","65.53682"
"12.67900","170.35980","64.33012"
"12.70900","170.20976","63.12153"
"12.73900","170.05980","61.91227"
"12.76900","169.90982","60.70036"
"12.79900","169.75981","59.48650"
"12.82900","169.60988","58.25992"
"12.85900","169.45982","57.03381"
"12.88900","169.30975","55.81271"
"12.91900","169.15979","54.59886"
"12.94900","169.00984","53.36929"
"12.97900","168.85974","52.13712"
"13.00900","168.70973","50.89579"
"13.03900","168.55989","49.65247"
"13.06900","168.40991","48.40109"
"13.09900","168.25977","47.14722"
"13.12900","168.10982","45.89886"
"13.15900","167.95979","44.64521"
"13.18900","167.80978","43.37901"
"13.21900","167.65973","42.10991"
"13.24900","167.50981","40.83514"
"13.27900","167.35989","39.55612"
"13.30900","167.20981","38.26815"
"13.33900","167.05977","36.98195"
"13.36900","166.90985","35.69225"
"13.39900","166.75983","34.38152"
"13.42900","166.60982","33.07769"
"13.45900","166.45981","31.76121"
"13.48900","166.30977","30.43833"
"13.51900","166.15976","29.11710"
"13.54900","166.00981","27.77551"
"13.57900","165.85997","26.44459"
"13.60900","165.70995","25.08715"
"13.63900","165.55984","23.72653"
"13.66900","165.40974","22.35850"
"13.69900","165.25961","20.97885"
"13.72900","165.10973","19.57399"
"13.75900","164.95978","18.17892"
"13.78900","164.80975","16.76543"
"13.81900","164.65981","15.34203"
"13.84900","164.50983","13.89677"
"13.87900","164.35982","12.45312"
"13.90900","164.20978","10.99310"
"13.93900","164.05978","9.52293"
"13.96900","163.90979","8.04645"
"13.99900","163.75977","6.53334"
"14.02900","163.60980","4.99648"
"14.05900","163.45982","3.43821"
"14.08900","163.30983","1.87636"
"14.11900","163.15982","0.29813"
"14.14900","163.00983","-1.30421"
"14.17900","162.85988","-2.91864"
"14.20900","162.70987","-4.55894"
"14.23900","162.55984","-6.23206"
"14.24300","162.53986","-6.45581"
"14.27300","162.41850","-7.13556"
"14.30300","162.48050","-6.14019"
"14.33300","162.62949","-3.95004"
"14.36300","162.78973","-1.80584"
"14.39300","162.94287","0.23002"
"14.42300","163.09351","2.16476"
"14.45300","163.24393","4.04560"
"14.48300","163.39421","5.89276"
"14.51300","163.54433","7.67687"
"14.54300","163.69434","9.48685"
"14.57300","163.84430","11.23116"
"14.60300","163.99437","12.93851"
"14.63300","164.14444","14.65264"
"14.66300","164.29448","16.31628"
"14.69300","164.44449","17.96410"
"14.72300","164.59447","19.58703"
"14.75300","164.74445","21.20650"
"14.78300","164.89450","22.79630"
"14.81300","165.04446","24.35033"
"14.84300","165.19441","25.91486"
"14.87300","165.34430","27.45565"
"14.90300","165.49442","28.97414"
"14.93300","165.64445","30.49143"
"14.96300","165.79440","31.97622"
"14.99300","165.94443","33.46065"
"15.02300","166.09447","34.91589"
"15.05300","166.24443","36.35622"
"15.08300","166.39452","37.79892"
"15.11300","166.54457","39.20116"
"15.14300","166.69455","40.60448"
"15.17300","166.84450","42.00402"
"15.20300","166.99446","43.38291"
"15.23300","167.14445","44.74472"
"15.26300","167.29446","46.07965"
"15.29300","167.44452","47.41928"
"15.32300","167.59448","48.72887"
"15.35300","167.74451","50.03265"
"15.38300","167.89456","51.35751"
"15.41300","168.04459","52.67865"
"15.44300","168.19452","53.99846"
"15.47300","168.34451","55.31210"
"15.50300","168.49460","56.61642"
"15.53300","168.64449","57.91101"
"15.56300","168.79431","59.18947"
"15.59300","168.94437","60.47868"
"15.62300","169.09451","61.76159"
"15.65300","169.24446","63.03313"
"15.68300","169.39447","64.30483"
"15.71300","169.54453","65.56252"
"15.74300","169.69453","66.81764"
"15.77300","169.84451","68.05470"
"15.80300","169.99452","69.29700"
"15.83300","170.14450","70.53059"
"15.86300","170.29434","71.75781"
"15.89300","170.44437","72.98885"
"15.92300","170.59444","74.21315"
"15.95300","170.74446","75.42774"
"15.98300","170.89449","76.62529"
"16.01300","171.04449","77.81617"
"16.04300","171.19447","79.00333"
"16.07300","171.34447","80.18777"
"16.10300","171.49440","81.38105"
"16.13300","171.64453","82.57022"
"16.16300","171.79456","83.74788"
"16.19300","171.94449","84.92622"
"16.22300","172.09444","86.08578"
"16.25300","172.24440","87.24851"
"16.28300","172.39450","88.40620"
"16.31300","172.54454","89.56174"
"16.34300","172.69447","90.73055"
"16.37300","172.84447","91.90108"
"16.40300","172.99446","93.07275"
"16.43300","173.14453","94.17490"
"16.46300","173.29456","95.31860"
"16.49300","173.44444","96.45428"
"16.52300","173.59442","97.57092"
"16.55300","173.74443","98.71539"
"16.58300","173.89445","99.84826"
"16.61300","174.04448","100.98659"
"16.64300","174.19450","102.07578"
"16.67300","174.34457","103.16722"
"16.70300","174.49458","104.27543"
"16.73300","174.64455","105.36895"
"16.76300","174.79446","106.46335"
"16.79300","174.94438","107.56314"
"16.82300","175.09444","108.68070"
"16.85300","175.24443","109.78336"
"16.88300","175.39442","110.87180"
"16.91300","175.54446","111.97565"
"16.94300","175.69446","113.05233"
"16.97300","175.84442","114.13306"
"17.00300","175.99448","115.23331"
"17.03300","176.14459","116.32181"
"17.06300","176.29456","117.40940"
"17.09300","176.44434","118.49123"
"17.12300","176.59435","119.57259"
"17.15300","176.74451","120.65005"
"17.18300","176.89453","121.72342"
"17.21300","177.04449","122.79813"
"17.24300","177.19450","123.87595"
"17.27300","177.34453","124.95127"
"17.30300","177.49451","126.01865"
"17.33300","177.64449","127.09428"
"17.36300","177.79449","128.15462"
"17.39300","177.94444","129.20251"
"17.42300","178.09450","130.26523"
"17.45300","178.24451","131.32294"
"17.48300","178.39453","132.38110"
"17.51300","178.54451","133.44804"
"17.54300","178.69450","134.50409"
"17.57300","178.84451","135.55370"
"17.60300","178.99448","136.60121"
"17.63300","179.14444","137.64452"
"17.66300","179.29453","138.68552"
"17.69300","179.44447","139.72681"
"17.72300","179.59442","140.76752"
"17.75300","179.74446","141.81288"
"17.78300","179.89447","142.85779"
"17.80500","180.00450","143.61037"
"17.81700","180.06433","143.98141"
"17.84700","180.13414","143.83221"
"17.87700","180.02634","142.91689"
"17.90700","179.86906","141.40860"
"17.93700","179.71202","139.90314"
"17.96700","179.56056","138.53435"
"17.99700","179.41020","137.18216"
"18.02700","179.25992","135.85728"
"18.05700","179.10966","134.51788"
"18.08700","178.95958","133.23862"
"18.11700","178.80962","131.94049"
"18.14700","178.65959","130.63303"
"18.17700","178.50954","129.38324"
"18.20700","178.35944","128.12825"
"18.23700","178.20938","126.87494"
"18.26700","178.05936","125.62151"
"18.29700","177.90942","124.38067"
"18.32700","177.75958","123.15422"
"18.35700","177.60962","121.89338"
"18.38700","177.45949","120.67390"
"18.41700","177.30951","119.45766"
"18.44700","177.15941","118.22815"
"18.47700","177.00928","117.01337"
"18.50700","176.85930","115.79259"
"18.53700","176.70935","114.57920"
"18.56700","176.55933","113.35452"
"18.59700","176.40932","112.13368"
"18.62700","176.25952","110.94003"
"18.65700","176.10962","109.73283"
"18.68700","175.95944","108.53084"
"18.71700","175.80949","107.33202"
"18.74700","175.65950","106.12808"
"18.77700","175.50941","104.90839"
"18.80700","175.35934","103.68729"
"18.83700","175.20932","102.48856"
"18.86700","175.05940","101.29221"
"18.89700","174.90930","100.09818"
"18.92700","174.75934","98.90720"
"18.95700","174.60950","97.70444"
"18.98700","174.45953","96.49860"
"19.01700","174.30952","95.29176"
"19.04700","174.15950","94.08871"
"19.07700","174.00945","92.89590"
"19.10700","173.85936","91.69871"
"19.13700","173.70937","90.50597"
"19.16700","173.55945","89.31525"
"19.19700","173.40950","88.11330"
"19.22700","173.25946","86.90691"
"19.25700","173.10938","85.70400"
"19.28700","172.95932","84.51436"
"19.31700","172.80943","83.31768"
"19.34700","172.65950","82.12881"
"19.37700","172.50949","80.94778"
"19.40700","172.35953","79.76157"
"19.43700","172.20946","78.56693"
"19.46700","172.05949","77.37232"
"19.49700","171.90935","76.17558"
"19.52700","171.75932","74.98516"
"19.55700","171.60938","73.80447"
"19.58700","171.45938","72.62425"
"19.61700","171.30936","71.43163"
"19.64700","171.15945","70.23057"
"19.67700","171.00948","69.02222"
"19.70700","170.85950","67.82088"
"19.73700","170.70944","66.61390"
"19.76700","170.55945","65.40642"
"19.79700","170.40945","64.20949"
"19.82700","170.25940","63.00714"
"19.85700","170.10942","61.79627"
"19.88700","169.95944","60.58719"
"19.91700","169.80945","59.37443"
"19.94700","169.65948","58.14956"
"19.97700","169.50946","56.92400"
"20.00700","169.35938","55.70505"
"20.03700","169.20940","54.48514"
"20.06700","169.05948","53.26283"
"20.09700","168.90942","52.02967"
"20.12700","168.75934","50.79968"
"20.15700","168.60945","49.55066"
"20.18700","168.45956","48.29588"
"20.21700","168.30945","47.04890"
"20.24700","168.15944","45.80015"
"20.27700","168.00945","44.54585"
"20.30700","167.85942","43.28776"
"20.33700","167.70938","42.02252"
"20.36700","167.55942","40.74371"
"20.39700","167.40952","39.46537"
"20.42700","167.25948","38.19026"
"20.45700","167.10938","36.90213"
"20.48700","166.95946","35.60860"
"20.51700","166.80952","34.31193"
"20.54700","166.65945","33.01263"
"20.57700","166.50940","31.69730"
"20.60700","166.35936","30.38341"
"20.63700","166.20932","29.05922"
"20.66700","166.05940","27.73072"
"20.69700","165.90958","26.39081"
"20.72700","165.75957","25.05264"
"20.75700","165.60947","23.70259"
"20.78700","165.45941","22.33482"
"20.81700","165.30940","20.95983"
"20.84700","165.15933","19.56959"
"20.87700","165.00937","18.16821"
"20.90700","164.85934","16.76516"
"20.93700","164.70941","15.34854"
"20.96700","164.55946","13.92403"
"20.99700","164.40947","12.48958"
"21.02700","164.25945","11.03872"
"21.05700","164.10941","9.57518"
"21.08700","163.95941","8.09176"
"21.11700","163.80942","6.57737"
"21.14700","163.65947","5.04696"
"21.17700","163.50946","3.49929"
"21.20700","163.35944","1.94193"
"21.23700","163.20946","0.36894"
"21.26700","163.05945","-1.22070"
"21.29700","162.90948","-2.82814"
"21.32700","162.75951","-4.46918"
"21.35700","162.60945","-6.13289"
"21.37000","162.54448","-6.86337"
"21.39100","162.44456","-7.66765"
"21.42100","162.44301","-7.14505"
"21.45100","162.57603","-5.17929"
"21.48100","162.73677","-3.00182"
"21.51100","162.89201","-0.87554"
"21.54100","163.04303","1.05905"
"21.57100","163.19345","2.96937"
"21.60100","163.34380","4.79559"
"21.63100","163.49396","6.62201"
"21.66100","163.64397","8.42861"
"21.69100","163.79395","10.16023"
"21.72100","163.94403","11.91366"
"21.75100","164.09410","13.62704"
"21.78100","164.24411","15.29614"
"21.81100","164.39412","16.94900"
"21.84100","164.54413","18.57656"
"21.87100","164.69415","20.20916"
"21.90100","164.84418","21.78247"
"21.93100","164.99411","23.36540"
"21.96100","165.14406","24.93786"
"21.99100","165.29398","26.47288"
"22.02100","165.44402","28.00635"
"22.05100","165.59412","29.51131"
"22.08100","165.74413","31.00875"
"22.11100","165.89409","32.48106"
"22.14100","166.04408","33.94295"
"22.17100","166.19412","35.40992"
"22.20100","166.34418","36.83780"
"22.23100","166.49420","38.25927"
"22.26100","166.64413","39.66988"
"22.29100","166.79414","41.05440"
"22.32100","166.94414","42.43353"
"22.35100","167.09410","43.79090"
"22.38100","167.24413","45.15302"
"22.41100","167.39415","46.48656"
"22.44100","167.54413","47.79415"
"22.47100","167.69415","49.11346"
"22.50100","167.84421","50.41888"
"22.53100","167.99422","51.72737"
"22.56100","168.14417","53.04697"
"22.59100","168.29413","54.36188"
"22.62100","168.44423","55.67281"
"22.65100","168.59422","56.96039"
"22.68100","168.74400","58.25430"
"22.71100","168.89392","59.54993"
"22.74100","169.04413","60.82368"
"22.77100","169.19421","62.09374"
"22.80100","169.34415","63.36552"
"22.83100","169.49417","64.63273"
"22.86100","169.64417","65.88296"
"22.89100","169.79417","67.12957"
"22.92100","169.94418","68.37752"
"22.95100","170.09421","69.60184"
"22.98100","170.24406","70.83249"
"23.01100","170.39397","72.06432"
"23.04100","170.54404","73.28236"
"23.07100","170.69409","74.50293"
"23.10100","170.84415","75.70670"
"23.13100","170.99417","76.90675"
"23.16100","171.14413","78.09654"
"23.19100","171.29413","79.27811"
"23.22100","171.44406","80.47153"
"23.25100","171.59419","81.65239"
"23.28100","171.74422","82.83316"
"23.31100","171.89409","84.00945"
"23.34100","172.04407","85.18062"
"23.37100","172.19409","86.35062"
"23.40100","172.34413","87.51004"
"23.43100","172.49419","88.67775"
"23.46100","172.64413","89.82921"
"23.49100","172.79413","90.97890"
"23.52100","172.94412","92.13857"
"23.55100","173.09416","93.28649"
"23.58100","173.24425","94.42828"
"23.61100","173.39413","95.56460"
"23.64100","173.54407","96.69451"
"23.67100","173.69408","97.83220"
"23.70100","173.84410","98.95950"
"23.73100","173.99411","100.07646"
"23.76100","174.14413","101.19280"
"23.79100","174.29419","102.29548"
"23.82100","174.44423","103.39745"
"23.85100","174.59422","104.49132"
"23.88100","174.74417","105.59541"
"23.91100","174.89401","106.70406"
"23.94100","175.04408","107.80788"
"23.97100","175.19412","108.91383"
"24.00100","175.34412","110.01025"
"24.03100","175.49413","111.11533"
"24.06100","175.64409","112.20789"
"24.09100","175.79408","113.29686"
"24.12100","175.94412","114.38808"
"24.15100","176.09427","115.47459"
"24.18100","176.24426","116.55991"
"24.21100","176.39403","117.64725"
"24.24100","176.54395","118.73019"
"24.27100","176.69412","119.81760"
"24.30100","176.84422","120.90372"
"24.33100","176.99414","121.98365"
"24.36100","177.14410","123.05744"
"24.39100","177.29416","124.12854"
"24.42100","177.44418","125.19951"
"24.45100","177.59416","126.27135"
"24.48100","177.74419","127.33722"
"24.51100","177.89410","128.40771"
"24.54100","178.04411","129.47160"
"24.57100","178.19418","130.53851"
"24.60100","178.34418","131.59480"
"24.63100","178.49419","132.65324"
"24.66100","178.64412","133.71272"
"24.69100","178.79411","134.76750"
"24.72100","178.94417","135.82320"
"24.75100","179.09413","136.88120"
"24.78100","179.24414","137.93028"
"24.81100","179.39413","138.97293"
"24.84100","179.54407","140.01559"
"24.87100","179.69412","141.05800"
"24.90100","179.84416","142.09993"
"24.93100","179.99413","143.14172"
"24.93500","180.01413","143.27869"
"24.96500","180.13525","143.50415"
"24.99500","180.07204","142.98532"
"25.02500","179.92261","141.50473"
"25.05500","179.76318","140.03984"
"25.08500","179.61044","138.60979"
"25.11500","179.45990","137.23822"
"25.14500","179.30959","135.89795"
"25.17500","179.15938","134.58177"
"25.20500","179.00920","133.30211"
"25.23500","178.85919","131.97812"
"25.26500","178.70918","130.70314"
"25.29500","178.55913","129.44237"
"25.32500","178.40904","128.16092"
"25.35500","178.25900","126.90276"
"25.38500","178.10896","125.65589"
"25.41500","177.95895","124.42827"
"25.44500","177.80908","123.17941"
"25.47500","177.65923","121.93839"
"25.50500","177.50914","120.72939"
"25.53500","177.35910","119.48779"
"25.56500","177.20908","118.25996"
"25.59500","177.05896","117.04173"
"25.62500","176.90884","115.82339"
"25.65500","176.75891","114.61140"
"25.68500","176.60890","113.39063"
"25.71500","176.45886","112.19579"
"25.74500","176.30899","110.97930"
"25.77500","176.15918","109.76299"
"25.80500","176.00911","108.56577"
"25.83500","175.85909","107.36336"
"25.86500","175.70906","106.16400"
"25.89500","175.55901","104.94984"
"25.92500","175.40900","103.74110"
"25.95500","175.25890","102.54102"
"25.98500","175.10892","101.32816"
"26.01500","174.95889","100.12971"
"26.04500","174.80891","98.93809"
"26.07500","174.65904","97.73337"
"26.10500","174.50914","96.53716"
"26.13500","174.35910","95.33856"
"26.16500","174.20908","94.14253"
"26.19500","174.05902","92.93948"
"26.22500","173.90897","91.74019"
"26.25500","173.75897","90.54771"
"26.28500","173.60904","89.35162"
"26.31500","173.45909","88.15273"
"26.34500","173.30907","86.96238"
"26.37500","173.15900","85.76933"
"26.40500","173.00893","84.57040"
"26.43500","172.85896","83.37703"
"26.46500","172.70908","82.18897"
"26.49500","172.55907","80.99197"
"26.52500","172.40910","79.79992"
"26.55500","172.25906","78.60977"
"26.58500","172.10896","77.42072"
"26.61500","171.95895","76.22755"
"26.64500","171.80896","75.04344"
"26.67500","171.65900","73.85540"
"26.70500","171.50903","72.66988"
"26.73500","171.35895","71.47485"
"26.76500","171.20898","70.27708"
"26.79500","171.05902","69.08070"
"26.82500","170.90909","67.87974"
"26.85500","170.75908","66.67593"
"26.88500","170.60902","65.46996"
"26.91500","170.45914","64.26637"
"26.94500","170.30905","63.06129"
"26.97500","170.15891","61.84974"
"27.00500","170.00900","60.65071"
"27.03500","169.85904","59.44144"
"27.06500","169.70903","58.22169"
"27.09500","169.55907","57.00163"
"27.12500","169.40901","55.77739"
"27.15500","169.25897","54.55400"
"27.18500","169.10902","53.32493"
"27.21500","168.95903","52.09539"
"27.24500","168.80891","50.86629"
"27.27500","168.65900","49.62493"
"27.30500","168.50916","48.37514"
"27.33500","168.35904","47.12878"
"27.36500","168.20897","45.87539"
"27.39500","168.05902","44.62215"
"27.42500","167.90901","43.35845"
"27.45500","167.75900","42.09684"
"27.48500","167.60895","40.83026"
"27.51500","167.45906","39.55865"
"27.54500","167.30910","38.27855"
"27.57500","167.15901","36.99573"
"27.60500","167.00903","35.70349"
"27.63500","166.85907","34.40591"
"27.66500","166.70901","33.10477"
"27.69500","166.55901","31.80262"
"27.72500","166.40898","30.49231"
"27.75500","166.25897","29.17656"
"27.78500","166.10899","27.85556"
"27.81500","165.95911","26.52034"
"27.84500","165.80916","25.17872"
"27.87500","165.65910","23.82132"
"27.90500","165.50900","22.45809"
"27.93500","165.35889","21.09403"
"27.96500","165.20889","19.71610"
"27.99500","165.05899","18.32514"
"28.02500","164.90897","16.92881"
"28.05500","164.75903","15.53096"
"28.08500","164.60909","14.11168"
"28.11500","164.45905","12.67818"
"28.14500","164.30901","11.23094"
"28.17500","164.15898","9.76858"
"28.20500","164.00902","8.28225"
"28.23500","163.85901","6.78603"
"28.26500","163.70898","5.25991"
"28.29500","163.55902","3.71600"
"28.32500","163.40906","2.15995"
"28.35500","163.25905","0.58690"
"28.38500","163.10902","-1.00004"
"28.41500","162.95905","-2.59454"
"28.44500","162.80908","-4.21886"
"28.47500","162.65907","-5.87680"
"28.49700","162.54906","-7.11149"
"28.50900","162.48924","-7.74112"
"28.53900","162.41905","-7.77674"
"28.56900","162.52509","-6.25065"
"28.59900","162.68274","-4.02354"
"28.62900","162.84064","-1.85583"
"28.65900","162.99243","0.11323"
"28.68900","163.14293","2.02989"
"28.71900","163.29329","3.87593"
"28.74900","163.44347","5.73267"
"28.77900","163.59358","7.49423"
"28.80900","163.74358","9.26471"
"28.83900","163.89360","11.03480"
"28.86900","164.04370","12.73215"
"28.89900","164.19371","14.42607"
"28.92900","164.34370","16.08730"
"28.95900","164.49373","17.73265"
"28.98900","164.64374","19.34578"
"29.01900","164.79376","20.93073"
"29.04900","164.94374","22.53735"
"29.07900","165.09369","24.08725"
"29.10900","165.24364","25.63181"
"29.13900","165.39363","27.17387"
"29.16900","165.54370","28.69005"
"29.19900","165.69370","30.18851"
"29.22900","165.84364","31.65826"
"29.25900","165.99367","33.13689"
"29.28900","166.14371","34.59605"
"29.31900","166.29373","36.02085"
"29.34900","166.44379","37.46285"
"29.37900","166.59377","38.86709"
"29.40900","166.74376","40.25858"
"29.43900","166.89375","41.63608"
"29.46900","167.04376","43.00497"
"29.49900","167.19368","44.36561"
"29.52900","167.34367","45.69505"
"29.55900","167.49373","47.01960"
"29.58900","167.64375","48.33971"
"29.61900","167.79379","49.63615"
"29.64900","167.94382","50.94728"
"29.67900","168.09380","52.26070"
"29.70900","168.24373","53.58242"
"29.73900","168.39380","54.88803"
"29.76900","168.54382","56.18479"
"29.79900","168.69363","57.47757"
"29.82900","168.84352","58.76023"
"29.85900","168.99367","60.04271"
"29.88900","169.14380","61.31927"
"29.91900","169.29373","62.59073"
"29.94900","169.44371","63.85955"
"29.97900","169.59375","65.11078"
"30.00900","169.74377","66.36811"
"30.03900","169.89377","67.60991"
"30.06900","170.04376","68.84220"
"30.09900","170.19366","70.07725"
"30.12900","170.34363","71.30386"
"30.15900","170.49367","72.52390"
"30.18900","170.64371","73.74039"
"30.21900","170.79373","74.95419"
"30.24900","170.94374","76.15878"
"30.27900","171.09373","77.34498"
"30.30900","171.24374","78.53146"
"30.33900","171.39372","79.71316"
"30.36900","171.54373","80.89947"
"30.39900","171.69380","82.08353"
"30.42900","171.84372","83.25425"
"30.45900","171.99368","84.43216"
"30.48900","172.14369","85.59934"
"30.51900","172.29367","86.76426"
"30.54900","172.44376","87.93082"
"30.57900","172.59375","89.08926"
"30.60900","172.74374","90.24339"
"30.63900","172.89378","91.39720"
"30.66900","173.04376","92.54729"
"30.69900","173.19380","93.69415"
"30.72900","173.34377","94.83138"
"30.75900","173.49368","95.96796"
"30.78900","173.64368","97.10025"
"30.81900","173.79370","98.22551"
"30.84900","173.94370","99.35287"
"30.87900","174.09370","100.46243"
"30.90900","174.24373","101.57751"
"30.93900","174.39380","102.68089"
"30.96900","174.54379","103.78603"
"30.99900","174.69379","104.89606"
"31.02900","174.84367","105.99818"
"31.05900","174.99370","107.10223"
"31.08900","175.14375","108.20741"
"31.11900","175.29367","109.30950"
"31.14900","175.44368","110.41290"
"31.17900","175.59373","111.50458"
"31.20900","175.74370","112.59695"
"31.23900","175.89368","113.69246"
"31.26900","176.04378","114.77966"
"31.29900","176.19388","115.86737"
"31.32900","176.34370","116.94859"
"31.35900","176.49358","118.03883"
"31.38900","176.64366","119.12865"
"31.41900","176.79376","120.21218"
"31.44900","176.94376","121.29861"
"31.47900","177.09369","122.37112"
"31.50900","177.24376","123.44090"
"31.53900","177.39380","124.51773"
"31.56900","177.54373","125.58833"
"31.59900","177.69376","126.65838"
"31.62900","177.84375","127.72992"
"31.65900","177.99371","128.79669"
"31.68900","178.14378","129.86307"
"31.71900","178.29376","130.92616"
"31.74900","178.44377","131.98959"
"31.77900","178.59373","133.04762"
"31.80900","178.74373","134.10500"
"31.83900","178.89374","135.16122"
"31.86900","179.04376","136.22200"
"31.89900","179.19376","137.27867"
"31.92900","179.34380","138.32777"
"31.95900","179.49371","139.36948"
"31.98900","179.64368","140.41760"
"32.01900","179.79373","141.46262"
"32.04900","179.94371","142.51118"
"32.06200","180.00874","142.96103"
"32.08300","180.10858","143.35626"
"32.11300","180.10938","143.01559"
"32.14300","179.97533","141.73877"
"32.17300","179.81522","140.27853"
"32.20300","179.66052","138.78679"
"32.23300","179.50970","137.42296"
"32.26300","179.35941","136.07487"
"32.29300","179.20915","134.76651"
"32.32300","179.05896","133.44478"
"32.35300","178.90887","132.13271"
"32.38300","178.75888","130.87498"
"32.41300","178.60884","129.58243"
"32.44300","178.45885","128.31393"
"32.47300","178.30875","127.06366"
"32.50300","178.15866","125.80731"
"32.53300","178.00862","124.56337"
"32.56300","177.85873","123.30938"
"32.59300","177.70894","122.09825"
"32.62300","177.55887","120.86489"
"32.65300","177.40877","119.62282"
"32.68300","177.25877","118.41050"
"32.71300","177.10864","117.18352"
"32.74300","176.95859","115.95927"
"32.77300","176.80864","114.73945"
"32.80300","176.65862","113.52827"
"32.83300","176.50858","112.32936"
"32.86300","176.35864","111.10021"
"32.89300","176.20885","109.90065"
"32.92300","176.05885","108.70543"
"32.95300","175.90874","107.49874"
"32.98300","175.75874","106.29466"
"33.01300","175.60875","105.08933"
"33.04300","175.45877","103.88538"
"33.07300","175.30865","102.67299"
"33.10300","175.15858","101.46491"
"33.13300","175.00858","100.27539"
"33.16300","174.85861","99.07212"
"33.19300","174.70871","97.87373"
"33.22300","174.55884","96.67653"
"33.25300","174.40881","95.47819"
"33.28300","174.25877","94.27676"
"33.31300","174.10875","93.07075"
"33.34300","173.95869","91.88223"
"33.37300","173.80865","90.68636"
"33.40300","173.65869","89.48479"
"33.43300","173.50876","88.29387"
"33.46300","173.35878","87.10063"
"33.49300","173.20874","85.89828"
"33.52300","173.05864","84.70110"
"33.55300","172.90862","83.51350"
"33.58300","172.75874","82.32476"
"33.61300","172.60878","81.13195"
"33.64300","172.45882","79.93715"
"33.67300","172.30885","78.74848"
"33.70300","172.15866","77.55486"
"33.73300","172.00862","76.36086"
"33.76300","171.85866","75.17500"
"33.79300","171.70869","73.99092"
"33.82300","171.55870","72.80813"
"33.85300","171.40866","71.62080"
"33.88300","171.25865","70.42493"
"33.91300","171.10876","69.22755"
"33.94300","170.95883","68.02316"
"33.97300","170.80879","66.82271"
"34.00300","170.65869","65.61942"
"34.03300","170.50876","64.41465"
"34.06300","170.35878","63.21251"
"34.09300","170.20885","62.01074"
"34.12300","170.05873","60.80184"
"34.15300","169.90866","59.59079"
"34.18300","169.75870","58.37113"
"34.21300","169.60875","57.15426"
"34.24300","169.45871","55.93158"
"34.27300","169.30865","54.70962"
"34.30300","169.15869","53.48940"
"34.33300","169.00877","52.26599"
"34.36300","168.85869","51.03147"
"34.39300","168.70865","49.78893"
"34.42300","168.55879","48.54339"
"34.45300","168.40880","47.29255"
"34.48300","168.25868","46.04317"
"34.51300","168.10872","44.79048"
"34.54300","167.95872","43.52866"
"34.57300","167.80873","42.26728"
"34.60300","167.65868","41.00434"
"34.63300","167.50873","39.73190"
"34.66300","167.35878","38.45626"
"34.69300","167.20871","37.17535"
"34.72300","167.05870","35.89502"
"34.75300","166.90878","34.60175"
"34.78300","166.75876","33.30366"
"34.81300","166.60873","31.99954"
"34.84300","166.45871","30.69018"
"34.87300","166.30865","29.37499"
"34.90300","166.15862","28.05339"
"34.93300","166.00871","26.72694"
"34.96300","165.85889","25.39203"
"34.99300","165.70886","24.04156"
"35.02300","165.55875","22.68397"
"35.05300","165.40866","21.32052"
"35.08300","165.25862","19.94726"
"35.11300","165.10867","18.56799"
"35.14300","164.95866","17.18219"
"35.17300","164.80869","15.78434"
"35.20300","164.65874","14.37012"
"35.23300","164.50876","12.94094"
"35.26300","164.35876","11.49931"
"35.29300","164.20872","10.03388"
"35.32300","164.05870","8.54749"
"35.35300","163.90869","7.04793"
"35.38300","163.75870","5.53707"
"35.41300","163.60870","4.00133"
"35.44300","163.45876","2.44861"
"35.47300","163.30878","0.88165"
"35.50300","163.15874","-0.69811"
"35.53300","163.00871","-2.29582"
"35.56300","162.85880","-3.91003"
"35.59300","162.70880","-5.55370"
"35.62300","162.55878","-7.22532"
"35.62500","162.54878","-7.33854"