File: data/instron/2021/1104/3mms_1.is_tcyclic_RawData/Specimen_RawData_1.csv
Time,Extension,Load
(s),(mm),(N)
"0.00000","162.47990","-1.84994"
"0.05000","162.52275","-1.10186"
"0.10000","162.66658","0.79887"
"0.15000","162.82259","2.77323"
"0.20000","162.97362","4.61025"
"0.25000","163.12389","6.37949"
"0.30000","163.27391","8.14674"
"0.35000","163.42397","9.85382"
"0.40000","163.57402","11.53899"
"0.45000","163.72400","13.20490"
"0.50000","163.87399","14.86279"
"0.55000","164.02402","16.50527"
"0.60000","164.17395","18.08304"
"0.65000","164.32404","19.64885"
"0.70000","164.47412","21.18651"
"0.75000","164.62408","22.73573"
"0.80000","164.77402","24.25978"
"0.85000","164.92392","25.76375"
"0.90000","165.07396","27.23813"
"0.95000","165.22395","28.70903"
"1.00000","165.37401","30.19395"
"1.05000","165.52402","31.63914"
"1.10000","165.67392","33.04351"
"1.15000","165.82397","34.43386"
"1.20000","165.97400","35.82288"
"1.25000","166.12408","37.21187"
"1.30000","166.27400","38.56771"
"1.35000","166.42400","39.88646"
"1.40000","166.57407","41.21107"
"1.45000","166.72414","42.54670"
"1.50000","166.87408","43.86839"
"1.55000","167.02402","45.17810"
"1.60000","167.17386","46.47692"
"1.65000","167.32401","47.77844"
"1.70000","167.47412","49.08273"
"1.75000","167.62408","50.38163"
"1.80000","167.77399","51.66090"
"1.85000","167.92398","52.93319"
"1.90000","168.07410","54.21021"
"1.95000","168.22401","55.49939"
"2.00000","168.37413","56.76763"
"2.05000","168.52408","58.02070"
"2.10000","168.67381","59.27439"
"2.15000","168.82388","60.52738"
"2.20000","168.97409","61.78630"
"2.25000","169.12413","63.01627"
"2.30000","169.27396","64.24014"
"2.35000","169.42397","65.46098"
"2.40000","169.57410","66.67700"
"2.45000","169.72411","67.88592"
"2.50000","169.87408","69.08651"
"2.55000","170.02402","70.27728"
"2.60000","170.17392","71.46175"
"2.65000","170.32385","72.65491"
"2.70000","170.47406","73.83221"
"2.75000","170.62407","74.99916"
"2.80000","170.77399","76.16875"
"2.85000","170.92397","77.33370"
"2.90000","171.07404","78.49445"
"2.95000","171.22412","79.63705"
"3.00000","171.37404","80.78644"
"3.05000","171.52396","81.93398"
"3.10000","171.67398","83.08821"
"3.15000","171.82402","84.22577"
"3.20000","171.97406","85.35349"
"3.25000","172.12402","86.48423"
"3.30000","172.27396","87.61726"
"3.35000","172.42401","88.75220"
"3.40000","172.57404","89.87044"
"3.45000","172.72409","90.97231"
"3.50000","172.87405","92.07984"
"3.55000","173.02400","93.18908"
"3.60000","173.17404","94.29971"
"3.65000","173.32401","95.39196"
"3.70000","173.47403","96.48663"
"3.75000","173.62401","97.58572"
"3.80000","173.77402","98.68827"
"3.85000","173.92395","99.78607"
"3.90000","174.07401","100.86774"
"3.95000","174.22412","101.95340"
"4.00000","174.37411","103.03769"
"4.05000","174.52405","104.12341"
"4.10000","174.67398","105.20158"
"4.15000","174.82391","106.27125"
"4.20000","174.97408","107.34663"
"4.25000","175.12402","108.42533"
"4.30000","175.27396","109.49976"
"4.35000","175.42397","110.56731"
"4.40000","175.57402","111.62890"
"4.45000","175.72411","112.69650"
"4.50000","175.87402","113.77180"
"4.55000","176.02409","114.83829"
"4.60000","176.17409","115.87794"
"4.65000","176.32390","116.92508"
"4.70000","176.47394","117.98679"
"4.75000","176.62404","119.05599"
"4.80000","176.77405","120.10983"
"4.85000","176.92395","121.15424"
"4.90000","177.07394","122.20802"
"4.95000","177.22417","123.26418"
"5.00000","177.37413","124.30987"
"5.05000","177.52396","125.35941"
"5.10000","177.67403","126.40137"
"5.15000","177.82404","127.44524"
"5.20000","177.97400","128.49585"
"5.25000","178.12408","129.53908"
"5.30000","178.27400","130.57712"
"5.35000","178.42400","131.61942"
"5.40000","178.57399","132.66089"
"5.45000","178.72408","133.69763"
"5.50000","178.87411","134.72768"
"5.55000","179.02399","135.75566"
"5.60000","179.17397","136.79530"
"5.65000","179.32407","137.82242"
"5.70000","179.47408","138.85432"
"5.75000","179.62405","139.87323"
"5.80000","179.77397","140.89613"
"5.85000","179.92393","141.91829"
"5.87800","180.00810","142.48325"
"5.92800","180.06750","142.49580"
"5.97800","179.92358","141.11516"
"6.02800","179.76720","139.60753"
"6.07800","179.61623","138.21748"
"6.12800","179.46576","136.86603"
"6.17800","179.31561","135.54243"
"6.22800","179.16565","134.25090"
"6.27800","179.01570","132.96095"
"6.32800","178.86569","131.68359"
"6.37800","178.71558","130.41634"
"6.42800","178.56552","129.15990"
"6.47800","178.41556","127.90406"
"6.52800","178.26562","126.66335"
"6.57800","178.11552","125.43474"
"6.62800","177.96548","124.20532"
"6.67800","177.81561","122.98368"
"6.72800","177.66579","121.76410"
"6.77800","177.51564","120.54870"
"6.82800","177.36560","119.34094"
"6.87800","177.21555","118.12599"
"6.92800","177.06538","116.91379"
"6.97800","176.91551","115.70605"
"7.02800","176.76564","114.51060"
"7.07800","176.61552","113.31879"
"7.12800","176.46544","112.12222"
"7.17800","176.31557","110.92380"
"7.22800","176.16574","109.73038"
"7.27800","176.01566","108.53784"
"7.32800","175.86559","107.35654"
"7.37800","175.71553","106.16538"
"7.42800","175.56555","104.97078"
"7.47800","175.41553","103.78037"
"7.52800","175.26555","102.59154"
"7.57800","175.11557","101.40652"
"7.62800","174.96541","100.21116"
"7.67800","174.81544","99.02634"
"7.72800","174.66570","97.84000"
"7.77800","174.51572","96.64861"
"7.82800","174.36560","95.45985"
"7.87800","174.21558","94.27448"
"7.92800","174.06551","93.09445"
"7.97800","173.91553","91.90816"
"8.02800","173.76561","90.72726"
"8.07800","173.61560","89.54227"
"8.12800","173.46558","88.35561"
"8.17800","173.31555","87.17274"
"8.22800","173.16551","85.99253"
"8.27800","173.01553","84.81223"
"8.32800","172.86563","83.63065"
"8.37800","172.71558","82.44968"
"8.42800","172.56555","81.26678"
"8.47800","172.41566","80.08731"
"8.52800","172.26566","78.89897"
"8.57800","172.11551","77.71004"
"8.62800","171.96545","76.52969"
"8.67800","171.81552","75.34795"
"8.72800","171.66557","74.16217"
"8.77800","171.51562","72.98531"
"8.82800","171.36552","71.80266"
"8.87800","171.21556","70.61734"
"8.92800","171.06557","69.43970"
"8.97800","170.91562","68.25747"
"9.02800","170.76564","67.06773"
"9.07800","170.61560","65.87434"
"9.12800","170.46553","64.67965"
"9.17800","170.31546","63.48808"
"9.22800","170.16557","62.28338"
"9.27800","170.01576","61.08180"
"9.32800","169.86559","59.88641"
"9.37800","169.71555","58.68973"
"9.42800","169.56555","57.48491"
"9.47800","169.41548","56.27553"
"9.52800","169.26558","55.06240"
"9.57800","169.11568","53.85714"
"9.62800","168.96550","52.64112"
"9.67800","168.81543","51.41647"
"9.72800","168.66560","50.19017"
"9.77800","168.51576","48.95310"
"9.82800","168.36559","47.71983"
"9.87800","168.21550","46.48966"
"9.92800","168.06549","45.24866"
"9.97800","167.91559","44.00922"
"10.02800","167.76562","42.76538"
"10.07800","167.61557","41.52644"
"10.12800","167.46561","40.27491"
"10.17800","167.31549","39.01398"
"10.22800","167.16551","37.75307"
"10.27800","167.01572","36.48595"
"10.32800","166.86566","35.21117"
"10.37800","166.71547","33.92577"
"10.42800","166.56551","32.64011"
"10.47800","166.41557","31.35155"
"10.52800","166.26561","30.05995"
"10.57800","166.11555","28.75564"
"10.62800","165.96558","27.45142"
"10.67800","165.81561","26.13234"
"10.72800","165.66563","24.80415"
"10.77800","165.51559","23.48388"
"10.82800","165.36572","22.16388"
"10.87800","165.21541","20.83858"
"10.92800","165.06535","19.50286"
"10.97800","164.91551","18.13919"
"11.02800","164.76570","16.75725"
"11.07800","164.61565","15.34277"
"11.12800","164.46552","13.89775"
"11.17800","164.31551","12.44172"
"11.22800","164.16560","10.97194"
"11.27800","164.01566","9.48867"
"11.32800","163.86560","8.00693"
"11.37800","163.71550","6.50594"
"11.42800","163.56551","4.99709"
"11.47800","163.41559","3.46564"
"11.52800","163.26566","1.92467"
"11.57800","163.11559","0.35901"
"11.62800","162.96553","-1.20898"
"11.67800","162.81555","-2.81170"
"11.72800","162.66556","-4.45227"
"11.76800","162.54558","-5.78668"
"11.80900","162.46979","-6.16104"
"11.85900","162.59360","-4.34648"
"11.90900","162.75250","-2.17614"
"11.95900","162.90369","-0.17302"
"12.00900","163.05409","1.73858"
"12.05900","163.20436","3.58357"
"12.10900","163.35451","5.39019"
"12.15900","163.50452","7.16127"
"12.20900","163.65434","8.89992"
"12.25900","163.80421","10.62471"
"12.30900","163.95438","12.32668"
"12.35900","164.10448","13.99706"
"12.40900","164.25450","15.62589"
"12.45900","164.40440","17.23330"
"12.50900","164.55432","18.82299"
"12.55900","164.70442","20.39400"
"12.60900","164.85451","21.95206"
"12.65900","165.00444","23.48751"
"12.70900","165.15431","25.00974"
"12.75900","165.30424","26.52008"
"12.80900","165.45436","28.02423"
"12.85900","165.60449","29.49706"
"12.90900","165.75449","30.94679"
"12.95900","165.90433","32.38264"
"13.00900","166.05434","33.79584"
"13.05900","166.20438","35.19793"
"13.10900","166.35451","36.58779"
"13.15900","166.50452","37.95901"
"13.20900","166.65440","39.31053"
"13.25900","166.80437","40.64965"
"13.30900","166.95442","41.99072"
"13.35900","167.10443","43.32503"
"13.40900","167.25441","44.65030"
"13.45900","167.40442","45.96424"
"13.50900","167.55432","47.27139"
"13.55900","167.70441","48.57637"
"13.60900","167.85457","49.87392"
"13.65900","168.00455","51.16464"
"13.70900","168.15433","52.46075"
"13.75900","168.30429","53.74996"
"13.80900","168.45451","55.03316"
"13.85900","168.60448","56.30497"
"13.90900","168.75430","57.58035"
"13.95900","168.90430","58.84992"
"14.00900","169.05435","60.11922"
"14.05900","169.20445","61.36984"
"14.10900","169.35446","62.61679"
"14.15900","169.50452","63.85606"
"14.20900","169.65443","65.08768"
"14.25900","169.80434","66.31252"
"14.30900","169.95448","67.52924"
"14.35900","170.10455","68.73974"
"14.40900","170.25426","69.94660"
"14.45900","170.40430","71.14885"
"14.50900","170.55434","72.35036"
"14.55900","170.70444","73.53552"
"14.60900","170.85451","74.71989"
"14.65900","171.00449","75.89693"
"14.70900","171.15436","77.06480"
"14.75900","171.30435","78.23096"
"14.80900","171.45433","79.40083"
"14.85900","171.60452","80.57339"
"14.90900","171.75450","81.73163"
"14.95900","171.90440","82.89225"
"15.00900","172.05431","84.04208"
"15.05900","172.20435","85.19193"
"15.10900","172.35452","86.34136"
"15.15900","172.50453","87.48983"
"15.20900","172.65436","88.62787"
"15.25900","172.80435","89.75886"
"15.30900","172.95441","90.88088"
"15.35900","173.10449","92.00240"
"15.40900","173.25450","93.12090"
"15.45900","173.40437","94.23179"
"15.50900","173.55431","95.35044"
"15.55900","173.70438","96.46194"
"15.60900","173.85446","97.58180"
"15.65900","174.00447","98.68722"
"15.70900","174.15442","99.79371"
"15.75900","174.30441","100.88956"
"15.80900","174.45447","101.98229"
"15.85900","174.60452","103.08511"
"15.90900","174.75443","104.17511"
"15.95900","174.90430","105.27766"
"16.00900","175.05432","106.36252"
"16.05900","175.20436","107.44876"
"16.10900","175.35442","108.53645"
"16.15900","175.50450","109.62363"
"16.20900","175.65439","110.70586"
"16.25900","175.80429","111.78252"
"16.30900","175.95438","112.86277"
"16.35900","176.10461","113.93925"
"16.40900","176.25452","115.00366"
"16.45900","176.40422","116.07385"
"16.50900","176.55424","117.14787"
"16.55900","176.70444","118.22235"
"16.60900","176.85451","119.29549"
"16.65900","177.00444","120.36084"
"16.70900","177.15439","121.42484"
"16.75900","177.30440","122.49128"
"16.80900","177.45442","123.54767"
"16.85900","177.60449","124.61552"
"16.90900","177.75453","125.67222"
"16.95900","177.90431","126.73342"
"17.00900","178.05431","127.79134"
"17.05900","178.20444","128.85025"
"17.10900","178.35454","129.90335"
"17.15900","178.50449","130.95949"
"17.20900","178.65437","132.01434"
"17.25900","178.80437","133.06299"
"17.30900","178.95441","134.10379"
"17.35900","179.10443","135.15895"
"17.40900","179.25450","136.20044"
"17.45900","179.40437","137.24702"
"17.50900","179.55431","138.28946"
"17.55900","179.70441","139.33159"
"17.60900","179.85449","140.36732"
"17.65800","180.00150","141.38216"
"17.69000","180.08031","141.57495"
"17.74000","179.98792","140.68901"
"17.79000","179.82764","139.16063"
"17.84000","179.67580","137.75049"
"17.89000","179.52533","136.40865"
"17.94000","179.37518","135.07788"
"17.99000","179.22505","133.76668"
"18.04000","179.07497","132.48004"
"18.09000","178.92493","131.21754"
"18.14000","178.77501","129.94859"
"18.19000","178.62508","128.68987"
"18.24000","178.47502","127.43646"
"18.29000","178.32494","126.19450"
"18.34000","178.17484","124.96735"
"18.39000","178.02486","123.74152"
"18.44000","177.87505","122.51827"
"18.49000","177.72527","121.30468"
"18.54000","177.57504","120.09270"
"18.59000","177.42488","118.88517"
"18.64000","177.27496","117.67285"
"18.69000","177.12495","116.46766"
"18.74000","176.97493","115.26115"
"18.79000","176.82497","114.06882"
"18.84000","176.67484","112.88210"
"18.89000","176.52487","111.68925"
"18.94000","176.37503","110.49577"
"18.99000","176.22519","109.30199"
"19.04000","176.07504","108.11414"
"19.09000","175.92488","106.93455"
"19.14000","175.77495","105.74535"
"19.19000","175.62505","104.55703"
"19.24000","175.47504","103.36974"
"19.29000","175.32483","102.17775"
"19.34000","175.17487","100.99551"
"19.39000","175.02489","99.81225"
"19.44000","174.87498","98.62280"
"19.49000","174.72504","97.43870"
"19.54000","174.57503","96.25179"
"19.59000","174.42493","95.07149"
"19.64000","174.27498","93.88618"
"19.69000","174.12505","92.70532"
"19.74000","173.97498","91.52549"
"19.79000","173.82492","90.34624"
"19.84000","173.67488","89.16554"
"19.89000","173.52501","87.98616"
"19.94000","173.37508","86.80299"
"19.99000","173.22501","85.62019"
"20.04000","173.07487","84.44282"
"20.09000","172.92488","83.26599"
"20.14000","172.77498","82.08351"
"20.19000","172.62509","80.90240"
"20.24000","172.47508","79.72271"
"20.29000","172.32497","78.54356"
"20.34000","172.17482","77.36394"
"20.39000","172.02492","76.17944"
"20.44000","171.87503","74.99773"
"20.49000","171.72501","73.82200"
"20.54000","171.57492","72.64451"
"20.59000","171.42487","71.47231"
"20.64000","171.27492","70.29633"
"20.69000","171.12506","69.10705"
"20.74000","170.97508","67.93143"
"20.79000","170.82501","66.74892"
"20.84000","170.67488","65.55611"
"20.89000","170.52492","64.36194"
"20.94000","170.37497","63.16618"
"20.99000","170.22499","61.97397"
"21.04000","170.07504","60.77756"
"21.09000","169.92491","59.58512"
"21.14000","169.77493","58.39135"
"21.19000","169.62508","57.18848"
"21.24000","169.47502","55.98396"
"21.29000","169.32489","54.77918"
"21.34000","169.17494","53.57010"
"21.39000","169.02502","52.36480"
"21.44000","168.87497","51.14536"
"21.49000","168.72501","49.92337"
"21.54000","168.57504","48.69465"
"21.59000","168.42494","47.46453"
"21.64000","168.27487","46.23471"
"21.69000","168.12502","45.00002"
"21.74000","167.97502","43.76143"
"21.79000","167.82492","42.51674"
"21.84000","167.67484","41.27187"
"21.89000","167.52499","40.02977"
"21.94000","167.37512","38.77624"
"21.99000","167.22498","37.52049"
"22.04000","167.07492","36.25883"
"22.09000","166.92497","34.98980"
"22.14000","166.77498","33.71308"
"22.19000","166.62503","32.43003"
"22.24000","166.47501","31.14716"
"22.29000","166.32489","29.85860"
"22.34000","166.17490","28.56449"
"22.39000","166.02496","27.25938"
"22.44000","165.87515","25.94599"
"22.49000","165.72508","24.62529"
"22.54000","165.57489","23.30325"
"22.59000","165.42482","21.98654"
"22.64000","165.27489","20.67256"
"22.69000","165.12502","19.34227"
"22.74000","164.97501","17.98445"
"22.79000","164.82495","16.60446"
"22.84000","164.67491","15.19633"
"22.89000","164.52499","13.77397"
"22.94000","164.37505","12.31679"
"22.99000","164.22501","10.85545"
"23.04000","164.07492","9.38171"
"23.09000","163.92488","7.90492"
"23.14000","163.77496","6.41583"
"23.19000","163.62503","4.91036"
"23.24000","163.47505","3.38727"
"23.29000","163.32495","1.86098"
"23.34000","163.17491","0.31304"
"23.39000","163.02495","-1.26006"
"23.44000","162.87511","-2.84040"
"23.49000","162.72505","-4.46066"
"23.54000","162.57497","-6.11333"
"23.57100","162.48509","-6.93253"
"23.62100","162.53088","-5.92413"
"23.67100","162.68964","-3.68361"
"23.72100","162.84270","-1.63258"
"23.77100","162.99335","0.30590"
"23.82100","163.14363","2.17330"
"23.87100","163.29364","4.00047"
"23.92100","163.44362","5.79036"
"23.97100","163.59361","7.54860"
"24.02100","163.74361","9.26831"
"24.07100","163.89371","10.97768"
"24.12100","164.04369","12.66494"
"24.17100","164.19365","14.32100"
"24.22100","164.34364","15.93875"
"24.27100","164.49371","17.53620"
"24.32100","164.64375","19.11604"
"24.37100","164.79369","20.68163"
"24.42100","164.94359","22.22887"
"24.47100","165.09358","23.76151"
"24.52100","165.24359","25.27948"
"24.57100","165.39368","26.78589"
"24.62100","165.54375","28.27100"
"24.67100","165.69354","29.73417"
"24.72100","165.84358","31.17950"
"24.77100","165.99368","32.60795"
"24.82100","166.14375","34.01868"
"24.87100","166.29370","35.41641"
"24.92100","166.44368","36.80490"
"24.97100","166.59366","38.16949"
"25.02100","166.74373","39.51358"
"25.07100","166.89377","40.85060"
"25.12100","167.04370","42.19112"
"25.17100","167.19351","43.52568"
"25.22100","167.34363","44.84505"
"25.27100","167.49371","46.15210"
"25.32100","167.64375","47.45094"
"25.37100","167.79370","48.75215"
"25.42100","167.94365","50.05150"
"25.47100","168.09366","51.34099"
"25.52100","168.24367","52.63330"
"25.57100","168.39386","53.91429"
"25.62100","168.54373","55.18746"
"25.67100","168.69345","56.46311"
"25.72100","168.84346","57.73322"
"25.77100","168.99373","59.00417"
"25.82100","169.14383","60.26106"
"25.87100","169.29364","61.51387"
"25.92100","169.44360","62.75906"
"25.97100","169.59367","63.99296"
"26.02100","169.74374","65.22131"
"26.07100","169.89378","66.43981"
"26.12100","170.04373","67.66620"
"26.17100","170.19354","68.87666"
"26.22100","170.34348","70.07646"
"26.27100","170.49371","71.27672"
"26.32100","170.64375","72.47419"
"26.37100","170.79366","73.66682"
"26.42100","170.94360","74.85110"
"26.47100","171.09366","76.02216"
"26.52100","171.24373","77.19056"
"26.57100","171.39372","78.36276"
"26.62100","171.54369","79.53295"
"26.67100","171.69365","80.70091"
"26.72100","171.84363","81.85812"
"26.77100","171.99368","83.01029"
"26.82100","172.14369","84.17023"
"26.87100","172.29367","85.32066"
"26.92100","172.44366","86.47088"
"26.97100","172.59361","87.60970"
"27.02100","172.74373","88.74511"
"27.07100","172.89374","89.88368"
"27.12100","173.04372","91.01335"
"27.17100","173.19371","92.13770"
"27.22100","173.34361","93.24775"
"27.27100","173.49365","94.36431"
"27.32100","173.64369","95.48875"
"27.37100","173.79370","96.59890"
"27.42100","173.94360","97.71439"
"27.47100","174.09363","98.82129"
"27.52100","174.24374","99.92705"
"27.57100","174.39381","101.02654"
"27.62100","174.54373","102.12246"
"27.67100","174.69363","103.21861"
"27.72100","174.84351","104.31870"
"27.77100","174.99368","105.41347"
"27.82100","175.14374","106.49956"
"27.87100","175.29362","107.58566"
"27.92100","175.44359","108.67343"
"27.97100","175.59364","109.76177"
"28.02100","175.74374","110.83836"
"28.07100","175.89368","111.93123"
"28.12100","176.04381","113.01040"
"28.17100","176.19373","114.08112"
"28.22100","176.34351","115.15115"
"28.27100","176.49359","116.22878"
"28.32100","176.64377","117.29962"
"28.37100","176.79373","118.37521"
"28.42100","176.94360","119.44883"
"28.47100","177.09357","120.51971"
"28.52100","177.24377","121.58729"
"28.57100","177.39380","122.64801"
"28.62100","177.54366","123.71171"
"28.67100","177.69363","124.77331"
"28.72100","177.84363","125.83792"
"28.77100","177.99370","126.90103"
"28.82100","178.14377","127.96180"
"28.87100","178.29370","129.02007"
"28.92100","178.44357","130.07880"
"28.97100","178.59361","131.12994"
"29.02100","178.74376","132.18210"
"29.07100","178.89377","133.22897"
"29.12100","179.04364","134.28902"
"29.17100","179.19363","135.33812"
"29.22100","179.34363","136.38800"
"29.27100","179.49370","137.42967"
"29.32100","179.64377","138.47034"
"29.37100","179.79369","139.51390"
"29.42100","179.94360","140.55803"
"29.45200","180.03668","141.17688"
"29.50200","180.04251","140.81882"
"29.55200","179.88855","139.35422"
"29.60200","179.73499","137.88106"
"29.65200","179.58447","136.50726"
"29.70200","179.43419","135.17496"
"29.75200","179.28398","133.87341"
"29.80200","179.13396","132.58156"
"29.85200","178.98407","131.29912"
"29.90200","178.83412","130.02432"
"29.95200","178.68401","128.76527"
"30.00200","178.53392","127.51373"
"30.05200","178.38388","126.28249"
"30.10200","178.23399","125.03815"
"30.15200","178.08398","123.80645"
"30.20200","177.93398","122.59086"
"30.25200","177.78412","121.37730"
"30.30200","177.63408","120.16407"
"30.35200","177.48399","118.95271"
"30.40200","177.33408","117.74092"
"30.45200","177.18401","116.53309"
"30.50200","177.03378","115.33195"
"30.55200","176.88391","114.13637"
"30.60200","176.73401","112.94193"
"30.65200","176.58394","111.75092"
"30.70200","176.43396","110.56479"
"30.75200","176.28401","109.37371"
"30.80200","176.13408","108.18057"
"30.85200","175.98402","106.99548"
"30.90200","175.83408","105.81092"
"30.95200","175.68401","104.62460"
"31.00200","175.53391","103.44041"
"31.05200","175.38385","102.24803"
"31.10200","175.23402","101.06160"
"31.15200","175.08395","99.87571"
"31.20200","174.93388","98.69351"
"31.25200","174.78387","97.51102"
"31.30200","174.63402","96.32618"
"31.35200","174.48409","95.13793"
"31.40200","174.33408","93.95737"
"31.45200","174.18404","92.77518"
"31.50200","174.03389","91.59451"
"31.55200","173.88387","90.41956"
"31.60200","173.73398","89.24103"
"31.65200","173.58408","88.06150"
"31.70200","173.43405","86.88047"
"31.75200","173.28395","85.70116"
"31.80200","173.13383","84.51852"
"31.85200","172.98393","83.33743"
"31.90200","172.83409","82.16617"
"31.95200","172.68407","80.98856"
"32.00200","172.53395","79.80676"
"32.05200","172.38394","78.62308"
"32.10200","172.23399","77.44625"
"32.15200","172.08400","76.26210"
"32.20200","171.93396","75.08380"
"32.25200","171.78392","73.90553"
"32.30200","171.63390","72.73058"
"32.35200","171.48399","71.55323"
"32.40200","171.33397","70.37955"
"32.45200","171.18405","69.19211"
"32.50200","171.03400","68.01312"
"32.55200","170.88396","66.82954"
"32.60200","170.73399","65.64660"
"32.65200","170.58408","64.45628"
"32.70200","170.43407","63.26103"
"32.75200","170.28386","62.06942"
"32.80200","170.13391","60.87259"
"32.85200","169.98402","59.68205"
"32.90200","169.83403","58.48313"
"32.95200","169.68402","57.28757"
"33.00200","169.53400","56.08159"
"33.05200","169.38383","54.87675"
"33.10200","169.23398","53.67387"
"33.15200","169.08417","52.46742"
"33.20200","168.93396","51.25470"
"33.25200","168.78384","50.03284"
"33.30200","168.63399","48.81058"
"33.35200","168.48410","47.57673"
"33.40200","168.33400","46.34509"
"33.45200","168.18398","45.11767"
"33.50200","168.03392","43.87933"
"33.55200","167.88391","42.64140"
"33.60200","167.73396","41.39407"
"33.65200","167.58406","40.14881"
"33.70200","167.43407","38.89332"
"33.75200","167.28387","37.64058"
"33.80200","167.13385","36.37884"
"33.85200","166.98412","35.11721"
"33.90200","166.83409","33.84341"
"33.95200","166.68399","32.56344"
"34.00200","166.53389","31.28529"
"34.05200","166.38387","29.99395"
"34.10200","166.23401","28.70461"
"34.15200","166.08405","27.40078"
"34.20200","165.93408","26.09700"
"34.25200","165.78400","24.78060"
"34.30200","165.63393","23.46199"
"34.35200","165.48393","22.14869"
"34.40200","165.33403","20.82681"
"34.45200","165.18390","19.51095"
"34.50200","165.03389","18.15858"
"34.55200","164.88390","16.78738"
"34.60200","164.73407","15.38828"
"34.65200","164.58411","13.97217"
"34.70200","164.43401","12.53493"
"34.75200","164.28391","11.07566"
"34.80200","164.13393","9.60712"
"34.85200","163.98404","8.12895"
"34.90200","163.83400","6.64513"
"34.95200","163.68398","5.15037"
"35.00200","163.53395","3.64211"
"35.05200","163.38391","2.11071"
"35.10200","163.23404","0.56535"
"35.15200","163.08406","-0.98895"
"35.20200","162.93404","-2.56349"
"35.25200","162.78398","-4.16923"
"35.30200","162.63397","-5.80565"
"35.33300","162.54106","-6.83210"
"35.38300","162.48157","-6.98624"
"35.43300","162.62447","-4.92725"
"35.48300","162.78136","-2.78114"
"35.53300","162.93219","-0.79988"
"35.58300","163.08247","1.09681"
"35.63300","163.23262","2.94441"
"35.68300","163.38278","4.73021"
"35.73300","163.53282","6.49525"
"35.78300","163.68271","8.24033"
"35.83300","163.83261","9.96041"
"35.88300","163.98262","11.65800"
"35.93300","164.13272","13.31687"
"35.98300","164.28282","14.95138"
"36.03300","164.43282","16.55408"
"36.08300","164.58269","18.14654"
"36.13300","164.73267","19.71725"
"36.18300","164.88277","21.26273"
"36.23300","165.03279","22.80149"
"36.28300","165.18266","24.32792"
"36.33300","165.33260","25.84067"
"36.38300","165.48268","27.33653"
"36.43300","165.63271","28.80838"
"36.48300","165.78279","30.25839"
"36.53300","165.93269","31.69766"
"36.58300","166.08270","33.11847"
"36.63300","166.23268","34.52343"
"36.68300","166.38278","35.90947"
"36.73300","166.53284","37.28939"
"36.78300","166.68279","38.64766"
"36.83300","166.83270","39.98750"
"36.88300","166.98268","41.32484"
"36.93300","167.13268","42.66006"
"36.98300","167.28281","43.98760"
"37.03300","167.43275","45.30172"
"37.08300","167.58267","46.60485"
"37.13300","167.73268","47.90184"
"37.18300","167.88278","49.19163"
"37.23300","168.03287","50.48371"
"37.28300","168.18269","51.77646"
"37.33300","168.33272","53.06664"
"37.38300","168.48280","54.33934"
"37.43300","168.63264","55.60718"
"37.48300","168.78261","56.88503"
"37.53300","168.93274","58.15941"
"37.58300","169.08273","59.41828"
"37.63300","169.23270","60.67480"
"37.68300","169.38275","61.92234"
"37.73300","169.53287","63.16165"
"37.78300","169.68279","64.39442"
"37.83300","169.83266","65.61868"
"37.88300","169.98270","66.83933"
"37.93300","170.13278","68.05447"
"37.98300","170.28268","69.26498"
"38.03300","170.43268","70.46752"
"38.08300","170.58267","71.66732"
"38.13300","170.73267","72.86212"
"38.18300","170.88275","74.04759"
"38.23300","171.03284","75.22735"
"38.28300","171.18277","76.38879"
"38.33300","171.33267","77.56023"
"38.38300","171.48262","78.73768"
"38.43300","171.63280","79.90694"
"38.48300","171.78282","81.06569"
"38.53300","171.93279","82.22851"
"38.58300","172.08263","83.37514"
"38.63300","172.23260","84.53402"
"38.68300","172.38278","85.68310"
"38.73300","172.53284","86.83546"
"38.78300","172.68277","87.97094"
"38.83300","172.83269","89.10992"
"38.88300","172.98267","90.24010"
"38.93300","173.13278","91.36674"
"38.98300","173.28284","92.48615"
"39.03300","173.43274","93.60181"
"39.08300","173.58263","94.72348"
"39.13300","173.73267","95.83935"
"39.18300","173.88271","96.95160"
"39.23300","174.03279","98.06910"
"39.28300","174.18280","99.17666"
"39.33300","174.33270","100.28453"
"39.38300","174.48274","101.37669"
"39.43300","174.63278","102.47569"
"39.48300","174.78273","103.57428"
"39.53300","174.93271","104.67085"
"39.58300","175.08267","105.75739"
"39.63300","175.23260","106.84859"
"39.68300","175.38272","107.93642"
"39.73300","175.53285","109.02200"
"39.78300","175.68274","110.10981"
"39.83300","175.83261","111.19387"
"39.88300","175.98271","112.28167"
"39.93300","176.13287","113.35460"
"39.98300","176.28276","114.42520"
"40.03300","176.43263","115.50060"
"40.08300","176.58263","116.57726"
"40.13300","176.73270","117.65282"
"40.18300","176.88275","118.72807"
"40.23300","177.03279","119.79940"
"40.28300","177.18280","120.86765"
"40.33300","177.33270","121.93718"
"40.38300","177.48268","122.99846"
"40.43300","177.63278","124.06240"
"40.48300","177.78284","125.12809"
"40.53300","177.93271","126.19442"
"40.58300","178.08269","127.25481"
"40.63300","178.23267","128.31898"
"40.68300","178.38280","129.37239"
"40.73300","178.53281","130.43257"
"40.78300","178.68272","131.48866"
"40.83300","178.83273","132.54132"
"40.88300","178.98270","133.58995"
"40.93300","179.13271","134.64291"
"40.98300","179.28284","135.69588"
"41.03300","179.43277","136.74321"
"41.08300","179.58267","137.79031"
"41.13300","179.73265","138.83173"
"41.18300","179.88275","139.87317"
"41.22400","180.00580","140.72728"
"41.26500","180.08144","140.87563"
"41.31500","179.95706","139.70708"
"41.36500","179.79828","138.20378"
"41.41500","179.64700","136.82138"
"41.46500","179.49652","135.46056"
"41.51500","179.34644","134.13947"
"41.56500","179.19638","132.84679"
"41.61500","179.04637","131.56773"
"41.66500","178.89629","130.30176"
"41.71500","178.74626","129.03386"
"41.76500","178.59630","127.77177"
"41.81500","178.44635","126.52652"
"41.86500","178.29631","125.29832"
"41.91500","178.14616","124.06364"
"41.96500","177.99615","122.84260"
"42.01500","177.84634","121.62147"
"42.06500","177.69655","120.40737"
"42.11500","177.54639","119.20239"
"42.16500","177.39626","117.99807"
"42.21500","177.24623","116.78687"
"42.26500","177.09616","115.57991"
"42.31500","176.94626","114.37968"
"42.36500","176.79634","113.18410"
"42.41500","176.64615","111.99874"
"42.46500","176.49612","110.80301"
"42.51500","176.34633","109.61897"
"42.56500","176.19650","108.42297"
"42.61500","176.04637","107.23634"
"42.66500","175.89624","106.05469"
"42.71500","175.74623","104.86932"
"42.76500","175.59628","103.68032"
"42.81500","175.44632","102.49541"
"42.86500","175.29623","101.31047"
"42.91500","175.14624","100.12414"
"42.96500","174.99615","98.93765"
"43.01500","174.84622","97.76111"
"43.06500","174.69638","96.57360"
"43.11500","174.54642","95.38457"
"43.16500","174.39627","94.20192"
"43.21500","174.24622","93.02192"
"43.26500","174.09628","91.84238"
"43.31500","173.94632","90.66103"
"43.36500","173.79628","89.48785"
"43.41500","173.64626","88.30425"
"43.46500","173.49628","87.12914"
"43.51500","173.34633","85.94377"
"43.56500","173.19630","84.76707"
"43.61500","173.04623","83.58521"
"43.66500","172.89626","82.40804"
"43.71500","172.74631","81.23257"
"43.76500","172.59630","80.05695"
"43.81500","172.44640","78.87284"
"43.86500","172.29634","77.69450"
"43.91500","172.14616","76.51167"
"43.96500","171.99620","75.33343"
"44.01500","171.84628","74.14961"
"44.06500","171.69632","72.97088"
"44.11500","171.54630","71.79375"
"44.16500","171.39621","70.62293"
"44.21500","171.24619","69.44422"
"44.26500","171.09634","68.26537"
"44.31500","170.94643","67.08249"
"44.36500","170.79636","65.89030"
"44.41500","170.64622","64.71100"
"44.46500","170.49623","63.51987"
"44.51500","170.34622","62.32631"
"44.56500","170.19638","61.12573"
"44.61500","170.04636","59.93853"
"44.66500","169.89621","58.74912"
"44.71500","169.74620","57.55316"
"44.76500","169.59636","56.34403"
"44.81500","169.44629","55.13880"
"44.86500","169.29623","53.93435"
"44.91500","169.14630","52.72767"
"44.96500","168.99623","51.51047"
"45.01500","168.84624","50.29465"
"45.06500","168.69638","49.07653"
"45.11500","168.54639","47.84924"
"45.16500","168.39626","46.61286"
"45.21500","168.24614","45.38682"
"45.26500","168.09625","44.14994"
"45.31500","167.94635","42.91547"
"45.36500","167.79628","41.67224"
"45.41500","167.64618","40.42700"
"45.46500","167.49628","39.17665"
"45.51500","167.34634","37.92273"
"45.56500","167.19633","36.67093"
"45.61500","167.04633","35.40779"
"45.66500","166.89629","34.14020"
"45.71500","166.74622","32.85662"
"45.76500","166.59628","31.57416"
"45.81500","166.44635","30.28975"
"45.86500","166.29626","29.00626"
"45.91500","166.14627","27.70819"
"45.96500","165.99626","26.40393"
"46.01500","165.84639","25.09175"
"46.06500","165.69637","23.77295"
"46.11500","165.54628","22.45691"
"46.16500","165.39613","21.14494"
"46.21500","165.24615","19.82674"
"46.26500","165.09625","18.48627"
"46.31500","164.94633","17.12749"
"46.36500","164.79639","15.73542"
"46.41500","164.64626","14.32545"
"46.46500","164.49623","12.90011"
"46.51500","164.34633","11.44561"
"46.56500","164.19633","9.97854"
"46.61500","164.04631","8.51039"
"46.66500","163.89619","7.03014"
"46.71500","163.74622","5.54163"
"46.76500","163.59630","4.03555"
"46.81500","163.44638","2.51248"
"46.86500","163.29633","0.97802"
"46.91500","163.14624","-0.57326"
"46.96500","162.99623","-2.14017"
"47.01500","162.84634","-3.72815"
"47.06500","162.69638","-5.34546"
"47.11400","162.54932","-6.96863"
"47.14600","162.47023","-7.46006"
"47.19600","162.56233","-6.02194"
"47.24600","162.72232","-3.80330"
"47.29600","162.87419","-1.78746"
"47.34600","163.02467","0.12311"
"47.39600","163.17503","1.98840"
"47.44600","163.32510","3.81318"
"47.49600","163.47502","5.58209"
"47.54600","163.62492","7.32695"
"47.59600","163.77484","9.05481"
"47.64600","163.92506","10.75760"
"47.69600","164.07510","12.43555"
"47.74600","164.22502","14.09017"
"47.79600","164.37497","15.70088"
"47.84600","164.52499","17.28996"
"47.89600","164.67511","18.86545"
"47.94600","164.82510","20.42836"
"47.99600","164.97501","21.97164"
"48.04600","165.12488","23.49895"
"48.09600","165.27489","25.01216"
"48.14600","165.42505","26.52110"
"48.19600","165.57513","28.00190"
"48.24600","165.72495","29.46479"
"48.29600","165.87491","30.90732"
"48.34600","166.02493","32.33296"
"48.39600","166.17508","33.74622"
"48.44600","166.32515","35.14323"
"48.49600","166.47507","36.52329"
"48.54600","166.62497","37.89250"
"48.59600","166.77499","39.23973"
"48.64600","166.92503","40.57408"
"48.69600","167.07513","41.91467"
"48.74600","167.22501","43.24671"
"48.79600","167.37494","44.56327"
"48.84600","167.52496","45.86961"
"48.89600","167.67513","47.16254"
"48.94600","167.82516","48.46045"
"48.99600","167.97504","49.75237"
"49.04600","168.12497","51.04487"
"49.09600","168.27493","52.33538"
"49.14600","168.42520","53.60993"
"49.19600","168.57512","54.88325"
"49.24600","168.72482","56.15681"
"49.29600","168.87485","57.43718"
"49.34600","169.02504","58.70512"
"49.39600","169.17514","59.95929"
"49.44600","169.32504","61.21245"
"49.49600","169.47504","62.45840"
"49.54600","169.62500","63.69474"
"49.59600","169.77501","64.92201"
"49.64600","169.92511","66.14949"
"49.69600","170.07513","67.36360"
"49.74600","170.22490","68.57771"
"49.79600","170.37488","69.78525"
"49.84600","170.52495","70.98404"
"49.89600","170.67506","72.17706"
"49.94600","170.82509","73.36990"
"49.99600","170.97501","74.55220"
"50.04600","171.12498","75.72554"
"50.09600","171.27501","76.89294"
"50.14600","171.42503","78.06382"
"50.19600","171.57518","79.23510"
"50.24600","171.72505","80.39822"
"50.29600","171.87497","81.56224"
"50.34600","172.02495","82.71985"
"50.39600","172.17505","83.87050"
"50.44600","172.32509","85.02828"
"50.49600","172.47508","86.17890"
"50.54600","172.62494","87.32227"
"50.59600","172.77496","88.45824"
"50.64600","172.92506","89.58949"
"50.69600","173.07513","90.72364"
"50.74600","173.22508","91.84676"
"50.79600","173.37495","92.96304"
"50.84600","173.52495","94.07957"
"50.89600","173.67505","95.19784"
"50.94600","173.82509","96.31374"
"50.99600","173.97499","97.43516"
"51.04600","174.12497","98.54116"
"51.09600","174.27504","99.65337"
"51.14600","174.42514","100.74656"
"51.19600","174.57515","101.84566"
"51.24600","174.72502","102.94282"
"51.29600","174.87485","104.04173"
"51.34600","175.02498","105.14146"
"51.39600","175.17505","106.22699"
"51.44600","175.32503","107.31531"
"51.49600","175.47504","108.39967"
"51.54600","175.62494","109.48887"
"51.59600","175.77496","110.57390"
"51.64600","175.92503","111.65832"
"51.69600","176.07523","112.73753"
"51.74600","176.22508","113.81046"
"51.79600","176.37483","114.88791"
"51.84600","176.52487","115.96179"
"51.89600","176.67511","117.03725"
"51.94600","176.82515","118.11538"
"51.99600","176.97502","119.19375"
"52.04600","177.12491","120.26063"
"52.09600","177.27504","121.32706"
"52.14600","177.42509","122.39441"
"52.19600","177.57510","123.45932"
"52.24600","177.72507","124.52798"
"52.29600","177.87492","125.59367"
"52.34600","178.02499","126.65289"
"52.39600","178.17513","127.70796"
"52.44600","178.32512","128.77545"
"52.49600","178.47504","129.83563"
"52.54600","178.62488","130.89145"
"52.59600","178.77496","131.94394"
"52.64600","178.92514","132.99390"
"52.69600","179.07509","134.05064"
"52.74600","179.22505","135.10765"
"52.79600","179.37498","136.15259"
"52.84600","179.52496","137.19766"
"52.89600","179.67508","138.24370"
"52.94600","179.82510","139.29079"
"52.99600","179.97502","140.33408"
"53.02700","180.06499","140.78798"
"53.07700","180.01895","140.14748"
"53.12700","179.85939","138.62068"
"53.17700","179.70662","137.18974"
"53.22700","179.55608","135.82913"
"53.27700","179.40584","134.49573"
"53.32700","179.25563","133.19157"
"53.37700","179.10553","131.90140"
"53.42700","178.95558","130.62103"
"53.47700","178.80573","129.36096"
"53.52700","178.65565","128.11131"
"53.57700","178.50558","126.85837"
"53.62700","178.35547","125.60829"
"53.67700","178.20547","124.37964"
"53.72700","178.05554","123.15270"
"53.77700","177.90567","121.93266"
"53.82700","177.75578","120.72179"
"53.87700","177.60562","119.50763"
"53.92700","177.45551","118.29343"
"53.97700","177.30565","117.09007"
"54.02700","177.15561","115.88490"
"54.07700","177.00554","114.68108"
"54.12700","176.85545","113.48743"
"54.17700","176.70546","112.29163"
"54.22700","176.55553","111.10176"
"54.27700","176.40562","109.90950"
"54.32700","176.25569","108.72356"
"54.37700","176.10564","107.53163"
"54.42700","175.95552","106.34757"
"54.47700","175.80565","105.16109"
"54.52700","175.65569","103.97697"
"54.57700","175.50560","102.78864"
"54.62700","175.35539","101.59814"
"54.67700","175.20546","100.41062"
"54.72700","175.05557","99.22594"
"54.77700","174.90558","98.04615"
"54.82700","174.75554","96.86423"
"54.87700","174.60559","95.67683"
"54.92700","174.45558","94.48743"
"54.97700","174.30562","93.31001"
"55.02700","174.15567","92.13103"
"55.07700","174.00554","90.95234"
"55.12700","173.85544","89.77277"
"55.17700","173.70554","88.59013"
"55.22700","173.55568","87.41031"
"55.27700","173.40567","86.23574"
"55.32700","173.25557","85.05515"
"55.37700","173.10544","83.86861"
"55.42700","172.95549","82.69451"
"55.47700","172.80568","81.52196"
"55.52700","172.65569","80.34259"
"55.57700","172.50560","79.16615"
"55.62700","172.35555","77.98492"
"55.67700","172.20549","76.79853"
"55.72700","172.05560","75.62427"
"55.77700","171.90562","74.44200"
"55.82700","171.75555","73.26228"
"55.87700","171.60545","72.08686"
"55.92700","171.45554","70.91220"
"55.97700","171.30557","69.73684"
"56.02700","171.15569","68.55733"
"56.07700","171.00565","67.37341"
"56.12700","170.85555","66.18799"
"56.17700","170.70547","65.00095"
"56.22700","170.55568","63.81281"
"56.27700","170.40576","62.61912"
"56.32700","170.25545","61.42578"
"56.37700","170.10551","60.23640"
"56.42700","169.95552","59.04127"
"56.47700","169.80560","57.84676"
"56.52700","169.65570","56.64856"
"56.57700","169.50563","55.44417"
"56.62700","169.35544","54.23465"
"56.67700","169.20555","53.02668"
"56.72700","169.05571","51.82096"
"56.77700","168.90559","50.60463"
"56.82700","168.75552","49.38270"
"56.87700","168.60558","48.15910"
"56.92700","168.45561","46.92830"
"56.97700","168.30554","45.69717"
"57.02700","168.15561","44.46886"
"57.07700","168.00558","43.22890"
"57.12700","167.85551","41.98972"
"57.17700","167.70547","40.74445"
"57.22700","167.55566","39.49834"
"57.27700","167.40573","38.24649"
"57.32700","167.25552","36.99335"
"57.37700","167.10545","35.73746"
"57.42700","166.95563","34.46950"
"57.47700","166.80566","33.19264"
"57.52700","166.65564","31.90900"
"57.57700","166.50554","30.62441"
"57.62700","166.35545","29.34020"
"57.67700","166.20554","28.04171"
"57.72700","166.05566","26.74290"
"57.77700","165.90573","25.43252"
"57.82700","165.75565","24.12309"
"57.87700","165.60547","22.80254"
"57.92700","165.45549","21.48867"
"57.97700","165.30554","20.17359"
"58.02700","165.15559","18.84583"
"58.07700","165.00555","17.49092"
"58.12700","164.85548","16.10542"
"58.17700","164.70558","14.70584"
"58.22700","164.55568","13.28887"
"58.27700","164.40565","11.83906"
"58.32700","164.25554","10.37869"
"58.37700","164.10548","8.91681"
"58.42700","163.95557","7.43986"
"58.47700","163.80562","5.95719"
"58.52700","163.65561","4.45961"
"58.57700","163.50563","2.94721"
"58.62700","163.35550","1.41008"
"58.67700","163.20554","-0.12753"
"58.72700","163.05566","-1.68676"
"58.77700","162.90569","-3.26395"
"58.82700","162.75563","-4.87498"
"58.87700","162.60553","-6.51329"
"58.89600","162.54860","-7.14255"