File: 5mms_1.is_tcyclic_RawData/Specimen_RawData_1.csv
Time,Extension,Load
(s),(mm),(N)
"0.00000","162.43622","-2.20598"
"0.03000","162.45003","-1.71263"
"0.06000","162.55124","-0.37483"
"0.09000","162.69933","1.60197"
"0.12000","162.85712","3.57629"
"0.15000","163.01003","5.44974"
"0.18000","163.16086","7.25214"
"0.21000","163.31133","9.01678"
"0.24000","163.46156","10.75213"
"0.27000","163.61159","12.46311"
"0.30000","163.76167","14.16525"
"0.33000","163.91177","15.83213"
"0.36000","164.06183","17.46914"
"0.39000","164.21181","19.08337"
"0.42000","164.36183","20.67875"
"0.45000","164.51183","22.25640"
"0.48000","164.66185","23.80261"
"0.51000","164.81190","25.35314"
"0.54000","164.96184","26.89798"
"0.57000","165.11179","28.39227"
"0.60000","165.26172","29.89691"
"0.63000","165.41173","31.38418"
"0.66000","165.56186","32.84367"
"0.69000","165.71182","34.28965"
"0.72000","165.86174","35.72354"
"0.75000","166.01176","37.14029"
"0.78000","166.16183","38.53944"
"0.81000","166.31184","39.92345"
"0.84000","166.46188","41.29627"
"0.87000","166.61185","42.64272"
"0.90000","166.76187","43.96790"
"0.93000","166.91188","45.28756"
"0.96000","167.06187","46.61406"
"0.99000","167.21178","47.92456"
"1.02000","167.36183","49.22906"
"1.05000","167.51187","50.54325"
"1.08000","167.66185","51.85194"
"1.11000","167.81189","53.15726"
"1.14000","167.96193","54.45557"
"1.17000","168.11189","55.75166"
"1.20000","168.26183","57.04031"
"1.23000","168.41193","58.31653"
"1.26000","168.56195","59.59180"
"1.29000","168.71172","60.86262"
"1.32000","168.86162","62.12318"
"1.35000","169.01176","63.37729"
"1.38000","169.16190","64.63710"
"1.41000","169.31184","65.88391"
"1.44000","169.46184","67.12193"
"1.47000","169.61186","68.35275"
"1.50000","169.76189","69.57770"
"1.53000","169.91191","70.78877"
"1.56000","170.06194","71.99689"
"1.59000","170.21173","73.20110"
"1.62000","170.36166","74.39748"
"1.65000","170.51176","75.59189"
"1.68000","170.66183","76.78352"
"1.71000","170.81186","77.96724"
"1.74000","170.96187","79.14083"
"1.77000","171.11183","80.30176"
"1.80000","171.26184","81.46085"
"1.83000","171.41182","82.62644"
"1.86000","171.56187","83.78587"
"1.89000","171.71191","84.93926"
"1.92000","171.86183","86.09490"
"1.95000","172.01180","87.24446"
"1.98000","172.16182","88.38205"
"2.01000","172.31183","89.52550"
"2.04000","172.46188","90.65886"
"2.07000","172.61185","91.79622"
"2.10000","172.76184","92.92410"
"2.13000","172.91187","94.05518"
"2.16000","173.06186","95.18302"
"2.19000","173.21190","96.30513"
"2.22000","173.36185","97.41611"
"2.25000","173.51180","98.51062"
"2.28000","173.66179","99.60664"
"2.31000","173.81180","100.69128"
"2.34000","173.96182","101.78770"
"2.37000","174.11185","102.89966"
"2.40000","174.26187","103.99644"
"2.43000","174.41193","105.08717"
"2.46000","174.56190","106.17156"
"2.49000","174.71188","107.25907"
"2.52000","174.86174","108.34830"
"2.55000","175.01178","109.43286"
"2.58000","175.16183","110.51975"
"2.61000","175.31180","111.60230"
"2.64000","175.46184","112.67979"
"2.67000","175.61182","113.75761"
"2.70000","175.76181","114.83287"
"2.73000","175.91183","115.90489"
"2.76000","176.06195","116.97831"
"2.79000","176.21199","118.04765"
"2.82000","176.36179","119.11024"
"2.85000","176.51164","120.17426"
"2.88000","176.66177","121.24138"
"2.91000","176.81189","122.30936"
"2.94000","176.96184","123.36918"
"2.97000","177.11179","124.43098"
"3.00000","177.26189","125.48396"
"3.03000","177.41191","126.54443"
"3.06000","177.56187","127.60189"
"3.09000","177.71191","128.65848"
"3.12000","177.86183","129.70717"
"3.15000","178.01180","130.75635"
"3.18000","178.16190","131.80310"
"3.21000","178.31189","132.85037"
"3.24000","178.46188","133.89255"
"3.27000","178.61183","134.93752"
"3.30000","178.76180","135.97665"
"3.33000","178.91187","137.01646"
"3.36000","179.06186","138.05696"
"3.39000","179.21185","139.08946"
"3.42000","179.36186","140.12744"
"3.45000","179.51178","141.16177"
"3.48000","179.66182","142.18900"
"3.51000","179.81186","143.21994"
"3.54000","179.96184","144.25049"
"3.55000","180.01186","144.59077"
"3.58000","180.13300","144.79970"
"3.61000","180.06978","144.26268"
"3.64000","179.92039","142.77417"
"3.67000","179.76096","141.30090"
"3.70000","179.60822","139.86848"
"3.73000","179.45767","138.49301"
"3.76000","179.30736","137.14131"
"3.79000","179.15714","135.81427"
"3.82000","179.00697","134.53061"
"3.85000","178.85696","133.20042"
"3.88000","178.70692","131.91978"
"3.91000","178.55687","130.65440"
"3.94000","178.40681","129.36511"
"3.97000","178.25674","128.10629"
"4.00000","178.10672","126.84370"
"4.03000","177.95668","125.61073"
"4.06000","177.80682","124.35705"
"4.09000","177.65701","123.11908"
"4.12000","177.50693","121.89849"
"4.15000","177.35687","120.65299"
"4.18000","177.20683","119.42595"
"4.21000","177.05675","118.20181"
"4.24000","176.90663","116.97531"
"4.27000","176.75670","115.75567"
"4.30000","176.60667","114.52914"
"4.33000","176.45662","113.31918"
"4.36000","176.30672","112.10308"
"4.39000","176.15691","110.88037"
"4.42000","176.00687","109.68086"
"4.45000","175.85680","108.47083"
"4.48000","175.70680","107.26224"
"4.51000","175.55681","106.05277"
"4.54000","175.40683","104.84270"
"4.57000","175.25668","103.63250"
"4.60000","175.10669","102.41811"
"4.63000","174.95667","101.21697"
"4.66000","174.80669","100.02073"
"4.69000","174.65683","98.81370"
"4.72000","174.50690","97.60849"
"4.75000","174.35686","96.39861"
"4.78000","174.20683","95.20171"
"4.81000","174.05678","93.99395"
"4.84000","173.90672","92.79569"
"4.87000","173.75671","91.59535"
"4.90000","173.60677","90.39863"
"4.93000","173.45683","89.19478"
"4.96000","173.30682","87.99596"
"4.99000","173.15674","86.79701"
"5.02000","173.00670","85.59554"
"5.05000","172.85675","84.39420"
"5.08000","172.70685","83.20147"
"5.11000","172.55685","82.00465"
"5.14000","172.40691","80.80650"
"5.17000","172.25685","79.60793"
"5.20000","172.10675","78.41270"
"5.23000","171.95679","77.21958"
"5.26000","171.80672","76.02345"
"5.29000","171.65671","74.83702"
"5.32000","171.50676","73.65379"
"5.35000","171.35669","72.45878"
"5.38000","171.20676","71.26394"
"5.41000","171.05681","70.06375"
"5.44000","170.90685","68.85760"
"5.47000","170.75684","67.64803"
"5.50000","170.60681","66.44477"
"5.53000","170.45685","65.23302"
"5.56000","170.30675","64.02277"
"5.59000","170.15674","62.81377"
"5.62000","170.00687","61.59863"
"5.65000","169.85680","60.39142"
"5.68000","169.70679","59.16972"
"5.71000","169.55681","57.94333"
"5.74000","169.40675","56.72080"
"5.77000","169.25673","55.49099"
"5.80000","169.10681","54.26650"
"5.83000","168.95680","53.04055"
"5.86000","168.80673","51.80240"
"5.89000","168.65685","50.55296"
"5.92000","168.50688","49.30227"
"5.95000","168.35678","48.05770"
"5.98000","168.20671","46.80050"
"6.01000","168.05675","45.53920"
"6.04000","167.90677","44.27725"
"6.07000","167.75676","43.01277"
"6.10000","167.60672","41.74126"
"6.13000","167.45680","40.46099"
"6.16000","167.30682","39.18452"
"6.19000","167.15675","37.89574"
"6.22000","167.00679","36.60632"
"6.25000","166.85687","35.31177"
"6.28000","166.70683","34.00837"
"6.31000","166.55679","32.70559"
"6.34000","166.40677","31.39288"
"6.37000","166.25674","30.07481"
"6.40000","166.10677","28.75165"
"6.43000","165.95685","27.42226"
"6.46000","165.80693","26.07914"
"6.49000","165.65688","24.73178"
"6.52000","165.50677","23.36880"
"6.55000","165.35663","21.99803"
"6.58000","165.20663","20.62216"
"6.61000","165.05672","19.23557"
"6.64000","164.90669","17.84619"
"6.67000","164.75677","16.44888"
"6.70000","164.60686","15.03307"
"6.73000","164.45683","13.59033"
"6.76000","164.30679","12.14462"
"6.79000","164.15675","10.66697"
"6.82000","164.00679","9.17536"
"6.85000","163.85680","7.66907"
"6.88000","163.70679","6.15058"
"6.91000","163.55678","4.60605"
"6.94000","163.40678","3.04439"
"6.97000","163.25681","1.46585"
"7.00000","163.10677","-0.12267"
"7.03000","162.95680","-1.72292"
"7.06000","162.80688","-3.35862"
"7.09000","162.65683","-5.02070"
"7.11200","162.54681","-6.26055"
"7.12400","162.48698","-6.88889"
"7.15400","162.41687","-6.93387"
"7.18400","162.52299","-5.40554"
"7.21400","162.68065","-3.17841"
"7.24400","162.83849","-1.01605"
"7.27400","162.99030","0.95160"
"7.30400","163.14079","2.87276"
"7.33400","163.29111","4.71978"
"7.36400","163.44135","6.56985"
"7.39400","163.59143","8.32844"
"7.42400","163.74138","10.09331"
"7.45400","163.89142","11.86118"
"7.48400","164.04155","13.55072"
"7.51400","164.19156","15.24282"
"7.54400","164.34157","16.89775"
"7.57400","164.49158","18.53533"
"7.60400","164.64157","20.14628"
"7.63400","164.79161","21.72873"
"7.66400","164.94156","23.32742"
"7.69400","165.09152","24.86977"
"7.72400","165.24147","26.41083"
"7.75400","165.39143","27.95811"
"7.78400","165.54155","29.46763"
"7.81400","165.69153","30.96497"
"7.84400","165.84148","32.43046"
"7.87400","165.99150","33.90370"
"7.90400","166.14154","35.34761"
"7.93400","166.29156","36.76465"
"7.96400","166.44162","38.19337"
"7.99400","166.59161","39.58863"
"8.02400","166.74162","40.97317"
"8.05400","166.89160","42.33536"
"8.08400","167.04163","43.69401"
"8.11400","167.19154","45.04207"
"8.14400","167.34155","46.36382"
"8.17400","167.49159","47.68859"
"8.20400","167.64159","49.00955"
"8.23400","167.79160","50.31414"
"8.26400","167.94165","51.63528"
"8.29400","168.09164","52.95071"
"8.32400","168.24158","54.26777"
"8.35400","168.39165","55.56700"
"8.38400","168.54169","56.85854"
"8.41400","168.69148","58.14892"
"8.44400","168.84134","59.42598"
"8.47400","168.99149","60.71217"
"8.50400","169.14168","61.99246"
"8.53400","169.29160","63.26172"
"8.56400","169.44154","64.52067"
"8.59400","169.59158","65.77104"
"8.62400","169.74164","67.01908"
"8.65400","169.89162","68.25728"
"8.68400","170.04163","69.48498"
"8.71400","170.19151","70.72268"
"8.74400","170.34142","71.94049"
"8.77400","170.49152","73.15517"
"8.80400","170.64156","74.36662"
"8.83400","170.79156","75.57368"
"8.86400","170.94159","76.77107"
"8.89400","171.09158","77.95621"
"8.92400","171.24158","79.14220"
"8.95400","171.39157","80.32183"
"8.98400","171.54155","81.50610"
"9.01400","171.69164","82.68183"
"9.04400","171.84160","83.85307"
"9.07400","171.99155","85.01891"
"9.10400","172.14154","86.17832"
"9.13400","172.29153","87.34669"
"9.16400","172.44162","88.51028"
"9.19400","172.59160","89.66187"
"9.22400","172.74159","90.81366"
"9.25400","172.89162","91.96297"
"9.28400","173.04158","93.11121"
"9.31400","173.19165","94.25146"
"9.34400","173.34161","95.38400"
"9.37400","173.49153","96.51939"
"9.40400","173.64151","97.64008"
"9.43400","173.79155","98.75703"
"9.46400","173.94157","99.87398"
"9.49400","174.09158","100.98290"
"9.52400","174.24158","102.09872"
"9.55400","174.39165","103.20998"
"9.58400","174.54164","104.31821"
"9.61400","174.69162","105.42159"
"9.64400","174.84151","106.52278"
"9.67400","174.99152","107.63033"
"9.70400","175.14156","108.73425"
"9.73400","175.29150","109.82899"
"9.76400","175.44156","110.92496"
"9.79400","175.59157","112.01428"
"9.82400","175.74155","113.10495"
"9.85400","175.89154","114.19517"
"9.88400","176.04163","115.28225"
"9.91400","176.19170","116.37231"
"9.94400","176.34154","117.44621"
"9.97400","176.49139","118.53049"
"10.00400","176.64151","119.61800"
"10.03400","176.79163","120.69950"
"10.06400","176.94159","121.78044"
"10.09400","177.09155","122.85208"
"10.12400","177.24161","123.92657"
"10.15400","177.39165","124.99551"
"10.18400","177.54161","126.06998"
"10.21400","177.69160","127.14333"
"10.24400","177.84155","128.20911"
"10.27400","177.99155","129.27415"
"10.30400","178.14160","130.33397"
"10.33400","178.29163","131.39732"
"10.36400","178.44164","132.46185"
"10.39400","178.59158","133.51505"
"10.42400","178.74156","134.56906"
"10.45400","178.89162","135.62306"
"10.48400","179.04158","136.67857"
"10.51400","179.19156","137.73245"
"10.54400","179.34158","138.77977"
"10.57400","179.49153","139.82584"
"10.60400","179.64154","140.87279"
"10.63400","179.79155","141.91745"
"10.66400","179.94154","142.96219"
"10.67700","180.00659","143.40878"
"10.69800","180.10643","143.80286"
"10.72800","180.10721","143.46278"
"10.75800","179.97316","142.18971"
"10.78800","179.81306","140.72620"
"10.81800","179.65837","139.23891"
"10.84800","179.50754","137.87419"
"10.87800","179.35721","136.52017"
"10.90800","179.20695","135.21542"
"10.93800","179.05676","133.88814"
"10.96800","178.90669","132.57274"
"10.99800","178.75670","131.31438"
"11.02800","178.60666","130.02396"
"11.05800","178.45662","128.75041"
"11.08800","178.30656","127.50033"
"11.11800","178.15651","126.25117"
"11.14800","178.00645","125.00661"
"11.17800","177.85657","123.74799"
"11.20800","177.70674","122.53322"
"11.23800","177.55669","121.29695"
"11.26800","177.40662","120.05685"
"11.29800","177.25659","118.84503"
"11.32800","177.10649","117.61556"
"11.35800","176.95644","116.38761"
"11.38800","176.80646","115.17106"
"11.41800","176.65643","113.95764"
"11.44800","176.50641","112.74999"
"11.47800","176.35648","111.52516"
"11.50800","176.20668","110.32576"
"11.53800","176.05667","109.12421"
"11.56800","175.90656","107.91554"
"11.59800","175.75658","106.71329"
"11.62800","175.60657","105.50826"
"11.65800","175.45656","104.29974"
"11.68800","175.30646","103.08779"
"11.71800","175.15645","101.88107"
"11.74800","175.00648","100.68535"
"11.77800","174.85648","99.48492"
"11.80800","174.70656","98.28948"
"11.83800","174.55666","97.08675"
"11.86800","174.40662","95.88464"
"11.89800","174.25665","94.68053"
"11.92800","174.10660","93.47938"
"11.95800","173.95651","92.28618"
"11.98800","173.80646","91.09453"
"12.01800","173.65648","89.89573"
"12.04800","173.50656","88.69965"
"12.07800","173.35663","87.49841"
"12.10800","173.20657","86.30129"
"12.13800","173.05646","85.10355"
"12.16800","172.90648","83.91431"
"12.19800","172.75658","82.72030"
"12.22800","172.60661","81.52893"
"12.25800","172.45667","80.34032"
"12.28800","172.30663","79.14466"
"12.31800","172.15649","77.94891"
"12.34800","172.00655","76.75561"
"12.37800","171.85649","75.57478"
"12.40800","171.70651","74.38447"
"12.43800","171.55653","73.20507"
"12.46800","171.40648","72.01763"
"12.49800","171.25648","70.82156"
"12.52800","171.10658","69.62135"
"12.55800","170.95662","68.41531"
"12.58800","170.80659","67.21239"
"12.61800","170.65654","66.01530"
"12.64800","170.50658","64.81128"
"12.67800","170.35657","63.60203"
"12.70800","170.20659","62.39178"
"12.73800","170.05650","61.18748"
"12.76800","169.90654","59.97825"
"12.79800","169.75656","58.76252"
"12.82800","169.60660","57.54257"
"12.85800","169.45657","56.32829"
"12.88800","169.30649","55.10210"
"12.91800","169.15654","53.87711"
"12.94800","169.00659","52.65233"
"12.97800","168.85649","51.41354"
"13.00800","168.70648","50.17089"
"13.03800","168.55663","48.92783"
"13.06800","168.40662","47.68102"
"13.09800","168.25650","46.42995"
"13.12800","168.10655","45.17405"
"13.15800","167.95656","43.91516"
"13.18800","167.80653","42.65252"
"13.21800","167.65648","41.38750"
"13.24800","167.50655","40.11619"
"13.27800","167.35663","38.84803"
"13.30800","167.20654","37.56876"
"13.33800","167.05652","36.27937"
"13.36800","166.90660","34.98999"
"13.39800","166.75661","33.69513"
"13.42800","166.60658","32.38939"
"13.45800","166.45657","31.08521"
"13.48800","166.30650","29.77612"
"13.51800","166.15648","28.45781"
"13.54800","166.00656","27.13397"
"13.57800","165.85670","25.79517"
"13.60800","165.70668","24.44699"
"13.63800","165.55656","23.09339"
"13.66800","165.40642","21.72985"
"13.69800","165.25638","20.35631"
"13.72800","165.10648","18.98753"
"13.75800","164.95650","17.59695"
"13.78800","164.80650","16.20749"
"13.81800","164.65656","14.80439"
"13.84800","164.50659","13.36996"
"13.87800","164.35661","11.91836"
"13.90800","164.20659","10.44649"
"13.93800","164.05653","8.95754"
"13.96800","163.90649","7.45250"
"13.99800","163.75652","5.93536"
"14.02800","163.60658","4.40268"
"14.05800","163.45662","2.85984"
"14.08800","163.30656","1.28906"
"14.11800","163.15654","-0.29502"
"14.14800","163.00655","-1.88981"
"14.17800","162.85663","-3.51587"
"14.20800","162.70663","-5.17050"
"14.23800","162.55659","-6.84330"
"14.24200","162.53661","-7.06935"
"14.27200","162.41530","-7.76252"
"14.30200","162.47731","-6.77237"
"14.33200","162.62639","-4.57781"
"14.36200","162.78661","-2.41785"
"14.39200","162.93973","-0.38065"
"14.42200","163.09035","1.55627"
"14.45200","163.24074","3.43747"
"14.48200","163.39105","5.27651"
"14.51200","163.54117","7.05265"
"14.54200","163.69116","8.86004"
"14.57200","163.84117","10.59820"
"14.60200","163.99124","12.30756"
"14.63200","164.14127","14.01491"
"14.66200","164.29131","15.68172"
"14.69200","164.44135","17.33118"
"14.72200","164.59134","18.93250"
"14.75200","164.74135","20.54669"
"14.78200","164.89133","22.13308"
"14.81200","165.04129","23.67882"
"14.84200","165.19125","25.24851"
"14.87200","165.34116","26.77824"
"14.90200","165.49123","28.30094"
"14.93200","165.64131","29.80274"
"14.96200","165.79126","31.28219"
"14.99200","165.94124","32.76879"
"15.02200","166.09126","34.20208"
"15.05200","166.24127","35.64424"
"15.08200","166.39136","37.07798"
"15.11200","166.54140","38.47049"
"15.14200","166.69141","39.85873"
"15.17200","166.84135","41.24068"
"15.20200","166.99135","42.60416"
"15.23200","167.14131","43.96158"
"15.26200","167.29131","45.28993"
"15.29200","167.44133","46.62597"
"15.32200","167.59129","47.93644"
"15.35200","167.74132","49.24393"
"15.38200","167.89140","50.55434"
"15.41200","168.04143","51.87469"
"15.44200","168.19135","53.18941"
"15.47200","168.34135","54.49050"
"15.50200","168.49141","55.79926"
"15.53200","168.64130","57.08055"
"15.56200","168.79115","58.36892"
"15.59200","168.94118","59.65602"
"15.62200","169.09135","60.93092"
"15.65200","169.24132","62.20374"
"15.68200","169.39131","63.47008"
"15.71200","169.54137","64.72190"
"15.74200","169.69138","65.97789"
"15.77200","169.84134","67.21741"
"15.80200","169.99135","68.45345"
"15.83200","170.14136","69.68719"
"15.86200","170.29121","70.90882"
"15.89200","170.44121","72.13461"
"15.92200","170.59126","73.34726"
"15.95200","170.74129","74.55534"
"15.98200","170.89133","75.75894"
"16.01200","171.04135","76.94808"
"16.04200","171.19131","78.13039"
"16.07200","171.34129","79.31635"
"16.10200","171.49124","80.50514"
"16.13200","171.64136","81.68580"
"16.16200","171.79138","82.86126"
"16.19200","171.94131","84.03086"
"16.22200","172.09126","85.19363"
"16.25200","172.24124","86.36124"
"16.28200","172.39133","87.52535"
"16.31200","172.54138","88.67953"
"16.34200","172.69133","89.84137"
"16.37200","172.84132","90.99020"
"16.40200","172.99130","92.14616"
"16.43200","173.14137","93.28914"
"16.46200","173.29141","94.42403"
"16.49200","173.44131","95.56161"
"16.52200","173.59128","96.69116"
"16.55200","173.74124","97.80972"
"16.58200","173.89127","98.93160"
"16.61200","174.04131","100.04471"
"16.64200","174.19131","101.16319"
"16.67200","174.34137","102.27141"
"16.70200","174.49141","103.38808"
"16.73200","174.64139","104.50043"
"16.76200","174.79134","105.60363"
"16.79200","174.94124","106.70930"
"16.82200","175.09129","107.80869"
"16.85200","175.24130","108.91194"
"16.88200","175.39127","110.01374"
"16.91200","175.54131","111.10943"
"16.94200","175.69130","112.20525"
"16.97200","175.84128","113.29437"
"17.00200","175.99133","114.38766"
"17.03200","176.14145","115.47451"
"17.06200","176.29140","116.55334"
"17.09200","176.44118","117.64274"
"17.12200","176.59117","118.73387"
"17.15200","176.74133","119.81858"
"17.18200","176.89137","120.89704"
"17.21200","177.04132","121.97841"
"17.24200","177.19133","123.05508"
"17.27200","177.34135","124.12716"
"17.30200","177.49132","125.20146"
"17.33200","177.64130","126.27512"
"17.36200","177.79137","127.35062"
"17.39200","177.94131","128.41689"
"17.42200","178.09134","129.48497"
"17.45200","178.24135","130.55037"
"17.48200","178.39136","131.61163"
"17.51200","178.54135","132.67451"
"17.54200","178.69133","133.73140"
"17.57200","178.84134","134.78632"
"17.60200","178.99130","135.84453"
"17.63200","179.14128","136.90105"
"17.66200","179.29135","137.95580"
"17.69200","179.44130","139.01071"
"17.72200","179.59126","140.05237"
"17.75200","179.74132","141.10344"
"17.78200","179.89133","142.15462"
"17.80400","180.00133","142.92201"
"17.81600","180.06116","143.29536"
"17.84600","180.13095","143.17000"
"17.87600","180.02338","142.26569"
"17.90600","179.86601","140.76604"
"17.93600","179.70886","139.25682"
"17.96600","179.55740","137.87875"
"17.99600","179.40703","136.52765"
"18.02600","179.25671","135.20650"
"18.05600","179.10645","133.86650"
"18.08600","178.95634","132.59738"
"18.11600","178.80640","131.30321"
"18.14600","178.65637","130.00046"
"18.17600","178.50630","128.74609"
"18.20600","178.35620","127.48048"
"18.23600","178.20616","126.22574"
"18.26600","178.05615","124.97343"
"18.29600","177.90619","123.73693"
"18.32600","177.75635","122.52080"
"18.35600","177.60638","121.26504"
"18.38600","177.45627","120.04543"
"18.41600","177.30629","118.82144"
"18.44600","177.15623","117.58398"
"18.47600","177.00610","116.36550"
"18.50600","176.85606","115.15108"
"18.53600","176.70612","113.94042"
"18.56600","176.55611","112.72335"
"18.59600","176.40610","111.50819"
"18.62600","176.25626","110.31306"
"18.65600","176.10635","109.09814"
"18.68600","175.95622","107.88925"
"18.71600","175.80624","106.69382"
"18.74600","175.65625","105.49161"
"18.77600","175.50626","104.28522"
"18.80600","175.35616","103.07252"
"18.83600","175.20613","101.86950"
"18.86600","175.05614","100.66628"
"18.89600","174.90610","99.46131"
"18.92600","174.75615","98.27737"
"18.95600","174.60628","97.07497"
"18.98600","174.45630","95.87325"
"19.01600","174.30629","94.66916"
"19.04600","174.15628","93.47238"
"19.07600","174.00621","92.27788"
"19.10600","173.85614","91.08067"
"19.13600","173.70613","89.88148"
"19.16600","173.55623","88.69464"
"19.19600","173.40628","87.49409"
"19.22600","173.25624","86.29160"
"19.25600","173.10612","85.09687"
"19.28600","172.95612","83.90589"
"19.31600","172.80621","82.70876"
"19.34600","172.65630","81.51856"
"19.37600","172.50627","80.32927"
"19.40600","172.35629","79.13757"
"19.43600","172.20621","77.94622"
"19.46600","172.05617","76.75334"
"19.49600","171.90617","75.56224"
"19.52600","171.75616","74.38040"
"19.55600","171.60616","73.19237"
"19.58600","171.45616","72.01292"
"19.61600","171.30615","70.81771"
"19.64600","171.15623","69.61481"
"19.67600","171.00626","68.42075"
"19.70600","170.85628","67.21655"
"19.73600","170.70622","66.01332"
"19.76600","170.55624","64.80858"
"19.79600","170.40623","63.60768"
"19.82600","170.25618","62.40059"
"19.85600","170.10622","61.19590"
"19.88600","169.95622","59.99075"
"19.91600","169.80621","58.78006"
"19.94600","169.65627","57.56306"
"19.97600","169.50626","56.34064"
"20.00600","169.35616","55.12199"
"20.03600","169.20616","53.89710"
"20.06600","169.05626","52.67080"
"20.09600","168.90622","51.44090"
"20.12600","168.75610","50.20752"
"20.15600","168.60620","48.96017"
"20.18600","168.45633","47.70871"
"20.21600","168.30621","46.45877"
"20.24600","168.15622","45.20838"
"20.27600","168.00621","43.95147"
"20.30600","167.85622","42.69159"
"20.33600","167.70616","41.42762"
"20.36600","167.55618","40.16315"
"20.39600","167.40628","38.89218"
"20.42600","167.25623","37.61326"
"20.45600","167.10612","36.33623"
"20.48600","166.95624","35.04317"
"20.51600","166.80627","33.74762"
"20.54600","166.65625","32.45350"
"20.57600","166.50623","31.15290"
"20.60600","166.35617","29.84618"
"20.63600","166.20616","28.52445"
"20.66600","166.05621","27.20308"
"20.69600","165.90633","25.86850"
"20.72600","165.75633","24.53216"
"20.75600","165.60623","23.18517"
"20.78600","165.45613","21.82128"
"20.81600","165.30608","20.46166"
"20.84600","165.15622","19.09417"
"20.87600","165.00613","17.71332"
"20.90600","164.85608","16.32015"
"20.93600","164.70621","14.91578"
"20.96600","164.55627","13.48987"
"20.99600","164.40627","12.04593"
"21.02600","164.25621","10.57964"
"21.05600","164.10619","9.09247"
"21.08600","163.95618","7.59403"
"21.11600","163.80618","6.07937"
"21.14600","163.65620","4.54679"
"21.17600","163.50624","3.00878"
"21.20600","163.35623","1.45817"
"21.23600","163.20622","-0.12176"
"21.26600","163.05621","-1.71374"
"21.29600","162.90630","-3.32851"
"21.32600","162.75629","-4.97661"
"21.35600","162.60623","-6.64564"
"21.36900","162.54128","-7.38002"
"21.39000","162.44139","-8.17937"
"21.42000","162.43980","-7.66070"
"21.45000","162.57288","-5.69809"
"21.48000","162.73369","-3.51651"
"21.51000","162.88890","-1.39003"
"21.54000","163.03993","0.55342"
"21.57000","163.19038","2.46134"
"21.60000","163.34071","4.29059"
"21.63000","163.49091","6.11411"
"21.66000","163.64091","7.91510"
"21.69000","163.79083","9.64110"
"21.72000","163.94093","11.39216"
"21.75000","164.09103","13.09800"
"21.78000","164.24106","14.77096"
"21.81000","164.39107","16.42060"
"21.84000","164.54106","18.04037"
"21.87000","164.69109","19.67307"
"21.90000","164.84111","21.24221"
"21.93000","164.99106","22.81487"
"21.96000","165.14101","24.38334"
"21.99000","165.29092","25.90870"
"22.02000","165.44095","27.44050"
"22.05000","165.59106","28.94686"
"22.08000","165.74104","30.44383"
"22.11000","165.89096","31.91702"
"22.14000","166.04097","33.36575"
"22.17000","166.19099","34.82365"
"22.20000","166.34108","36.24217"
"22.23000","166.49113","37.65279"
"22.26000","166.64111","39.05053"
"22.29000","166.79109","40.42965"
"22.32000","166.94109","41.79864"
"22.35000","167.09109","43.14723"
"22.38000","167.24103","44.49891"
"22.41000","167.39104","45.83545"
"22.44000","167.54105","47.14696"
"22.47000","167.69107","48.46381"
"22.50000","167.84114","49.76652"
"22.53000","167.99117","51.07613"
"22.56000","168.14110","52.39355"
"22.59000","168.29106","53.70274"
"22.62000","168.44115","55.00965"
"22.65000","168.59116","56.29195"
"22.68000","168.74095","57.58053"
"22.71000","168.89087","58.87101"
"22.74000","169.04106","60.14915"
"22.77000","169.19112","61.42699"
"22.80000","169.34106","62.69160"
"22.83000","169.49109","63.95777"
"22.86000","169.64108","65.20509"
"22.89000","169.79109","66.44563"
"22.92000","169.94110","67.69074"
"22.95000","170.09113","68.92165"
"22.98000","170.24101","70.15273"
"23.01000","170.39091","71.37617"
"23.04000","170.54097","72.59015"
"23.07000","170.69104","73.80374"
"23.10000","170.84106","75.00716"
"23.13000","170.99109","76.20409"
"23.16000","171.14108","77.39319"
"23.19000","171.29105","78.57570"
"23.22000","171.44102","79.76165"
"23.25000","171.59113","80.94630"
"23.28000","171.74115","82.12823"
"23.31000","171.89105","83.29366"
"23.34000","172.04102","84.46389"
"23.37000","172.19098","85.62929"
"23.40000","172.34105","86.79338"
"23.43000","172.49113","87.96194"
"23.46000","172.64105","89.11809"
"23.49000","172.79108","90.26679"
"23.52000","172.94109","91.42213"
"23.55000","173.09108","92.56273"
"23.58000","173.24117","93.70407"
"23.61000","173.39108","94.84419"
"23.64000","173.54097","95.97852"
"23.67000","173.69099","97.10973"
"23.70000","173.84102","98.22616"
"23.73000","173.99106","99.34099"
"23.76000","174.14108","100.46247"
"23.79000","174.29108","101.57565"
"23.82000","174.44113","102.68470"
"23.85000","174.59116","103.79294"
"23.88000","174.74110","104.90672"
"23.91000","174.89093","106.01569"
"23.94000","175.04103","107.11966"
"23.97000","175.19106","108.22398"
"24.00000","175.34102","109.31925"
"24.03000","175.49106","110.42287"
"24.06000","175.64104","111.51244"
"24.09000","175.79100","112.60768"
"24.12000","175.94102","113.70699"
"24.15000","176.09119","114.79469"
"24.18000","176.24120","115.88142"
"24.21000","176.39098","116.96835"
"24.24000","176.54089","118.05276"
"24.27000","176.69104","119.13704"
"24.30000","176.84114","120.22112"
"24.33000","176.99109","121.30863"
"24.36000","177.14104","122.39124"
"24.39000","177.29109","123.46159"
"24.42000","177.44112","124.54139"
"24.45000","177.59109","125.60849"
"24.48000","177.74112","126.68526"
"24.51000","177.89105","127.75937"
"24.54000","178.04103","128.83101"
"24.57000","178.19112","129.90079"
"24.60000","178.34113","130.96031"
"24.63000","178.49110","132.02826"
"24.66000","178.64102","133.08759"
"24.69000","178.79102","134.14255"
"24.72000","178.94113","135.20078"
"24.75000","179.09109","136.25790"
"24.78000","179.24110","137.31860"
"24.81000","179.39108","138.37289"
"24.84000","179.54100","139.42230"
"24.87000","179.69104","140.47466"
"24.90000","179.84105","141.52258"
"24.93000","179.99107","142.57121"
"24.93400","180.01108","142.70967"
"24.96400","180.13223","142.94420"
"24.99400","180.06895","142.42535"
"25.02400","179.91963","140.94965"
"25.05400","179.76018","139.49281"
"25.08400","179.60742","138.07077"
"25.11400","179.45688","136.69881"
"25.14400","179.30655","135.35130"
"25.17400","179.15631","134.03627"
"25.20400","179.00620","132.75395"
"25.23400","178.85620","131.43332"
"25.26400","178.70618","130.15834"
"25.29400","178.55608","128.90007"
"25.32400","178.40601","127.62365"
"25.35400","178.25600","126.36388"
"25.38400","178.10596","125.11985"
"25.41400","177.95595","123.89039"
"25.44400","177.80606","122.63949"
"25.47400","177.65620","121.40330"
"25.50400","177.50610","120.19579"
"25.53400","177.35606","118.95427"
"25.56400","177.20602","117.72887"
"25.59400","177.05588","116.50696"
"25.62400","176.90587","115.28666"
"25.65400","176.75594","114.07364"
"25.68400","176.60590","112.85180"
"25.71400","176.45586","111.65481"
"25.74400","176.30598","110.44350"
"25.77400","176.15614","109.22736"
"25.80400","176.00609","108.03140"
"25.83400","175.85603","106.83601"
"25.86400","175.70601","105.62818"
"25.89400","175.55597","104.41590"
"25.92400","175.40596","103.21538"
"25.95400","175.25591","102.00826"
"25.98400","175.10593","100.80060"
"26.01400","174.95587","99.60130"
"26.04400","174.80588","98.41058"
"26.07400","174.65602","97.21065"
"26.10400","174.50613","96.00846"
"26.13400","174.35609","94.80867"
"26.16400","174.20609","93.61604"
"26.19400","174.05602","92.41389"
"26.22400","173.90593","91.22054"
"26.25400","173.75594","90.02840"
"26.28400","173.60600","88.82681"
"26.31400","173.45602","87.62873"
"26.34400","173.30603","86.43528"
"26.37400","173.15594","85.24011"
"26.40400","173.00587","84.04336"
"26.43400","172.85594","82.84834"
"26.46400","172.70605","81.65999"
"26.49400","172.55606","80.46861"
"26.52400","172.40611","79.28018"
"26.55400","172.25603","78.08277"
"26.58400","172.10594","76.89206"
"26.61400","171.95593","75.70226"
"26.64400","171.80595","74.51461"
"26.67400","171.65596","73.33315"
"26.70400","171.50598","72.14812"
"26.73400","171.35591","70.96104"
"26.76400","171.20596","69.75897"
"26.79400","171.05602","68.56023"
"26.82400","170.90610","67.36141"
"26.85400","170.75604","66.15675"
"26.88400","170.60602","64.95530"
"26.91400","170.45605","63.75383"
"26.94400","170.30609","62.55331"
"26.97400","170.15598","61.34251"
"27.00400","170.00601","60.13643"
"27.03400","169.85600","58.92612"
"27.06400","169.70602","57.70870"
"27.09400","169.55603","56.48835"
"27.12400","169.40596","55.26696"
"27.15400","169.25595","54.04274"
"27.18400","169.10605","52.82157"
"27.21400","168.95601","51.59596"
"27.24400","168.80588","50.35938"
"27.27400","168.65598","49.11238"
"27.30400","168.50610","47.86460"
"27.33400","168.35605","46.61900"
"27.36400","168.20598","45.36962"
"27.39400","168.05598","44.11934"
"27.42400","167.90601","42.86005"
"27.45400","167.75598","41.59012"
"27.48400","167.60596","40.32772"
"27.51400","167.45604","39.06349"
"27.54400","167.30603","37.79244"
"27.57400","167.15594","36.51580"
"27.60400","167.00601","35.22931"
"27.63400","166.85606","33.93787"
"27.66400","166.70602","32.64573"
"27.69400","166.55600","31.34269"
"27.72400","166.40598","30.03169"
"27.75400","166.25595","28.71791"
"27.78400","166.10597","27.40562"
"27.81400","165.95607","26.07508"
"27.84400","165.80612","24.74085"
"27.87400","165.65607","23.38846"
"27.90400","165.50597","22.03396"
"27.93400","165.35590","20.67657"
"27.96400","165.20589","19.31547"
"27.99400","165.05592","17.94696"
"28.02400","164.90591","16.55525"
"28.05400","164.75600","15.15591"
"28.08400","164.60605","13.74262"
"28.11400","164.45604","12.29771"
"28.14400","164.30602","10.82954"
"28.17400","164.15599","9.34920"
"28.20400","164.00601","7.85347"
"28.23400","163.85599","6.35315"
"28.26400","163.70598","4.82943"
"28.29400","163.55602","3.28345"
"28.32400","163.40602","1.73466"
"28.35400","163.25601","0.16538"
"28.38400","163.10600","-1.42629"
"28.41400","162.95602","-3.02697"
"28.44400","162.80605","-4.66249"
"28.47400","162.65604","-6.31979"
"28.49600","162.54605","-7.55133"
"28.50800","162.48622","-8.18092"
"28.53800","162.41608","-8.21812"
"28.56800","162.52229","-6.69088"
"28.59800","162.67993","-4.46143"
"28.62800","162.83771","-2.29564"
"28.65800","162.98946","-0.32559"
"28.68800","163.13994","1.59065"
"28.71800","163.29033","3.44430"
"28.74800","163.44055","5.29815"
"28.77800","163.59061","7.05553"
"28.80800","163.74055","8.81774"
"28.83800","163.89059","10.58607"
"28.86800","164.04070","12.27885"
"28.89800","164.19075","13.96791"
"28.92800","164.34076","15.62939"
"28.95800","164.49075","17.26853"
"28.98800","164.64078","18.88044"
"29.01800","164.79079","20.45793"
"29.04800","164.94075","22.06156"
"29.07800","165.09071","23.60983"
"29.10800","165.24066","25.14572"
"29.13800","165.39064","26.68913"
"29.16800","165.54074","28.20313"
"29.19800","165.69072","29.70292"
"29.22800","165.84065","31.16987"
"29.25800","165.99068","32.63863"
"29.28800","166.14072","34.09533"
"29.31800","166.29071","35.51441"
"29.34800","166.44078","36.94380"
"29.37800","166.59081","38.34062"
"29.40800","166.74083","39.73030"
"29.43800","166.89081","41.09893"
"29.46800","167.04079","42.45411"
"29.49800","167.19067","43.81460"
"29.52800","167.34073","45.14608"
"29.55800","167.49078","46.46983"
"29.58800","167.64076","47.78751"
"29.61800","167.79082","49.09146"
"29.64800","167.94083","50.39759"
"29.67800","168.09082","51.70880"
"29.70800","168.24075","53.02775"
"29.73800","168.39082","54.32693"
"29.76800","168.54088","55.61823"
"29.79800","168.69067","56.91060"
"29.82800","168.84055","58.19169"
"29.85800","168.99069","59.47846"
"29.88800","169.14081","60.75690"
"29.91800","169.29076","62.03049"
"29.94800","169.44075","63.29721"
"29.97800","169.59081","64.53550"
"30.00800","169.74081","65.79063"
"30.03800","169.89079","67.03342"
"30.06800","170.04080","68.26353"
"30.09800","170.19073","69.49995"
"30.12800","170.34064","70.72149"
"30.15800","170.49068","71.93957"
"30.18800","170.64073","73.15891"
"30.21800","170.79076","74.36678"
"30.24800","170.94077","75.56633"
"30.27800","171.09076","76.75034"
"30.30800","171.24077","77.93278"
"30.33800","171.39075","79.12186"
"30.36800","171.54074","80.31262"
"30.39800","171.69083","81.49499"
"30.42800","171.84077","82.66560"
"30.45800","171.99074","83.83782"
"30.48800","172.14072","85.00369"
"30.51800","172.29070","86.16654"
"30.54800","172.44080","87.33470"
"30.57800","172.59079","88.49113"
"30.60800","172.74075","89.64740"
"30.63800","172.89079","90.79900"
"30.66800","173.04077","91.94709"
"30.69800","173.19083","93.09116"
"30.72800","173.34079","94.22585"
"30.75800","173.49071","95.36314"
"30.78800","173.64070","96.49201"
"30.81800","173.79071","97.61005"
"30.84800","173.94069","98.73507"
"30.87800","174.09073","99.85146"
"30.90800","174.24077","100.96674"
"30.93800","174.39085","102.08113"
"30.96800","174.54083","103.19187"
"30.99800","174.69083","104.30688"
"31.02800","174.84070","105.41451"
"31.05800","174.99069","106.51773"
"31.08800","175.14076","107.63039"
"31.11800","175.29074","108.72914"
"31.14800","175.44073","109.82364"
"31.17800","175.59074","110.91966"
"31.20800","175.74074","112.01308"
"31.23800","175.89070","113.11058"
"31.26800","176.04080","114.20236"
"31.29800","176.19090","115.29350"
"31.32800","176.34073","116.37630"
"31.35800","176.49059","117.46965"
"31.38800","176.64070","118.55585"
"31.41800","176.79080","119.64013"
"31.44800","176.94078","120.72709"
"31.47800","177.09073","121.80405"
"31.50800","177.24075","122.88525"
"31.53800","177.39081","123.96140"
"31.56800","177.54079","125.03940"
"31.59800","177.69078","126.11541"
"31.62800","177.84079","127.18707"
"31.65800","177.99077","128.25935"
"31.68800","178.14084","129.32433"
"31.71800","178.29082","130.39845"
"31.74800","178.44078","131.46410"
"31.77800","178.59074","132.52361"
"31.80800","178.74074","133.58365"
"31.83800","178.89078","134.64255"
"31.86800","179.04079","135.70107"
"31.89800","179.19078","136.76305"
"31.92800","179.34077","137.82132"
"31.95800","179.49072","138.87175"
"31.98800","179.64073","139.92369"
"32.01800","179.79074","140.97055"
"32.04800","179.94075","142.02335"
"32.06100","180.00578","142.47112"
"32.08200","180.10559","142.87801"
"32.11200","180.10635","142.54121"
"32.14200","179.97227","141.26953"
"32.17200","179.81223","139.81535"
"32.20200","179.65755","138.33015"
"32.23200","179.50670","136.96292"
"32.26200","179.35640","135.61406"
"32.29200","179.20613","134.30774"
"32.32200","179.05592","132.98260"
"32.35200","178.90590","131.67307"
"32.38200","178.75589","130.41440"
"32.41200","178.60583","129.12390"
"32.44200","178.45583","127.85044"
"32.47200","178.30571","126.60326"
"32.50200","178.15564","125.35442"
"32.53200","178.00563","124.10730"
"32.56200","177.85574","122.85115"
"32.59200","177.70595","121.64161"
"32.62200","177.55588","120.40574"
"32.65200","177.40578","119.16703"
"32.68200","177.25580","117.95229"
"32.71200","177.10567","116.72318"
"32.74200","176.95560","115.49877"
"32.77200","176.80566","114.27808"
"32.80200","176.65562","113.06872"
"32.83200","176.50558","111.86736"
"32.86200","176.35567","110.64627"
"32.89200","176.20587","109.44670"
"32.92200","176.05585","108.24835"
"32.95200","175.90575","107.04116"
"32.98200","175.75577","105.84226"
"33.01200","175.60574","104.63145"
"33.04200","175.45573","103.42280"
"33.07200","175.30563","102.21285"
"33.10200","175.15565","101.01430"
"33.13200","175.00566","99.82157"
"33.16200","174.85561","98.61848"
"33.19200","174.70573","97.41956"
"33.22200","174.55585","96.22314"
"33.25200","174.40578","95.02071"
"33.28200","174.25577","93.81970"
"33.31200","174.10577","92.62103"
"33.34200","173.95569","91.43149"
"33.37200","173.80563","90.23391"
"33.40200","173.65565","89.03608"
"33.43200","173.50574","87.84599"
"33.46200","173.35580","86.64642"
"33.49200","173.20575","85.44981"
"33.52200","173.05563","84.25043"
"33.55200","172.90564","83.06554"
"33.58200","172.75577","81.87231"
"33.61200","172.60579","80.68023"
"33.64200","172.45583","79.48981"
"33.67200","172.30582","78.29095"
"33.70200","172.15567","77.09518"
"33.73200","172.00565","75.90665"
"33.76200","171.85567","74.72028"
"33.79200","171.70570","73.53830"
"33.82200","171.55571","72.35702"
"33.85200","171.40565","71.16521"
"33.88200","171.25565","69.97055"
"33.91200","171.10576","68.76978"
"33.94200","170.95584","67.56448"
"33.97200","170.80582","66.36865"
"34.00200","170.65573","65.16872"
"34.03200","170.50575","63.96516"
"34.06200","170.35574","62.76176"
"34.09200","170.20572","61.55633"
"34.12200","170.05574","60.34899"
"34.15200","169.90573","59.14046"
"34.18200","169.75574","57.92649"
"34.21200","169.60580","56.70929"
"34.24200","169.45576","55.48984"
"34.27200","169.30568","54.26539"
"34.30200","169.15570","53.04842"
"34.33200","169.00575","51.82375"
"34.36200","168.85565","50.58346"
"34.39200","168.70564","49.34414"
"34.42200","168.55583","48.09452"
"34.45200","168.40581","46.85021"
"34.48200","168.25568","45.60324"
"34.51200","168.10573","44.35112"
"34.54200","167.95573","43.09368"
"34.57200","167.80574","41.83113"
"34.60200","167.65565","40.56436"
"34.63200","167.50571","39.30275"
"34.66200","167.35579","38.03192"
"34.69200","167.20578","36.75167"
"34.72200","167.05569","35.47572"
"34.75200","166.90576","34.18969"
"34.78200","166.75577","32.89278"
"34.81200","166.60574","31.59434"
"34.84200","166.45573","30.28816"
"34.87200","166.30569","28.98019"
"34.90200","166.15567","27.66894"
"34.93200","166.00577","26.33828"
"34.96200","165.85585","25.00229"
"34.99200","165.70581","23.65954"
"35.02200","165.55571","22.31360"
"35.05200","165.40562","20.95751"
"35.08200","165.25566","19.59701"
"35.11200","165.10565","18.22919"
"35.14200","164.95561","16.84556"
"35.17200","164.80565","15.45326"
"35.20200","164.65572","14.04729"
"35.23200","164.50577","12.60522"
"35.26200","164.35576","11.14186"
"35.29200","164.20573","9.65938"
"35.32200","164.05576","8.17367"
"35.35200","163.90572","6.67041"
"35.38200","163.75569","5.15290"
"35.41200","163.60571","3.62252"
"35.44200","163.45575","2.07462"
"35.47200","163.30577","0.51487"
"35.50200","163.15575","-1.06499"
"35.53200","163.00572","-2.66203"
"35.56200","162.85580","-4.29232"
"35.59200","162.70583","-5.93800"
"35.62200","162.55577","-7.61115"
"35.62400","162.54578","-7.72435"